Workbook

Sheet CAPEX
A1: Cost factors
A2: Equipment erection | B2: fer | C2: 0.3
A3: Piping | B3: fp | C3: 0.8
A4: Instrumentation and control | B4: fi | C4: 0.3
A5: Electrical | B5: fel | C5: 0.2
A6: Civil | B6: fc | C6: 0.3
A7: Structures and buildings | B7: fs | C7: 0.2
A8: Lagging and paint | B8: fl | C8: 0.1
A9: Material factor for 304 SS | B9: fm | C9: 1.3
A12: Equipment | B12: Equipment approximated as | C12: Dimension needed | D12: Value | E12: a | F12: b | G12: n | H12: Purchased Cost (Ce,i,a) | J12: Equipment | K12: Internal diameter (m) | L12: h (m) | M12: External diameter (m) | N12: Area for shell (m2) | O12: Volume | P12: Density (kg/m3) | Q12: Shell mass (kg)
A13: Compressors | J13: HTWGS | K13: 3.048 | L13: 10.668 | M13: =K13+0.0254 -> 3.0734 | N13: =PI()*(M13*M13-K13*K13)/4 -> 0.1221165 | O13: =N13*L13 -> 1.3027388 | P13: 8000 | Q13: =P13*O13 -> 10421.911
A14: K-108 | B14: Centrifugal Compressor | C14: Power, kW | D14: 520.97381 | E14: 580000 | F14: 20000 | G14: 0.6 | H14: =(E14+(F14*(D14^G14)))/1000000 -> 1.4333349 | J14: LTWGS | K14: 3.048 | L14: 10.668 | M14: =K14+0.0254 -> 3.0734 | N14: =PI()*(M14*M14-K14*K14)/4 -> 0.1221165 | O14: =N14*L14 -> 1.3027388 | P14: 8000 | Q14: =P14*O14 -> 10421.911
A15: K-101-5 | B15: Centrifugal Compressor | C15: Power, kW | D15: 1918.8124 | E15: 580000 | F15: 20000 | G15: 0.6 | H15: =(E15+(F15*(D15^G15)))/1000000 -> 2.445733 | J15: BED1 | K15: 2 | L15: 2.13 | M15: =K15+0.0254 -> 2.0254 | N15: =PI()*(M15*M15-K15*K15)/4 -> 0.080303161 | O15: =N15*L15 -> 0.17104573 | P15: 8000 | Q15: =P15*O15 -> 1368.3659
A16: K-101-2 | B16: Centrifugal Compressor | C16: Power, kW | D16: 1918.963 | E16: 580000 | F16: 20000 | G16: 0.6 | H16: =(E16+(F16*(D16^G16)))/1000000 -> 2.4458209 | J16: BED2 | K16: 2 | L16: 3.07 | M16: =K16+0.0254 -> 2.0254 | N16: =PI()*(M16*M16-K16*K16)/4 -> 0.080303161 | O16: =N16*L16 -> 0.2465307 | P16: 8000 | Q16: =P16*O16 -> 1972.2456
A17: K-101-3 | B17: Centrifugal Compressor | C17: Power, kW | D17: 1919.106 | E17: 580000 | F17: 20000 | G17: 0.6 | H17: =(E17+(F17*(D17^G17)))/1000000 -> 2.4459043 | J17: BED3 | K17: 2 | L17: 4.84 | M17: =K17+0.0254 -> 2.0254 | N17: =PI()*(M17*M17-K17*K17)/4 -> 0.080303161 | O17: =N17*L17 -> 0.3886673 | P17: 8000 | Q17: =P17*O17 -> 3109.3384
A18: K-101-4 | B18: Centrifugal Compressor | C18: Power, kW | D18: 1953.1509 | E18: 580000 | F18: 20000 | G18: 0.6 | H18: =(E18+(F18*(D18^G18)))/1000000 -> 2.4656951 | J18: V-502 | K18: 3.9624 | L18: 13.8684 | M18: =K18+0.0254 -> 3.9878 | N18: =PI()*(M18*M18-K18*K18)/4 -> 0.15859944 | O18: =N18*L18 -> 2.1995205 | P18: 8000 | Q18: =P18*O18 -> 17596.164
A19: K-102 | B19: Centrifugal Compressor | C19: Power, kW | D19: 3248.8729 | E19: 580000 | F19: 20000 | G19: 0.6 | H19: =(E19+(F19*(D19^G19)))/1000000 -> 3.1389961 | J19: V-100 | K19: 1.524 | L19: 8.382 | M19: =K19+0.0254 -> 1.5494 | N19: =PI()*(M19*M19-K19*K19)/4 -> 0.061311605 | O19: =N19*L19 -> 0.51391387 | P19: 8000 | Q19: =P19*O19 -> 4111.311
A20: K-103 | B20: Centrifugal Compressor | C20: Power, kW | D20: 8923.6287 | E20: 580000 | F20: 20000 | G20: 0.6 | H20: =(E20+(F20*(D20^G20)))/1000000 -> 5.2719664 | J20: V-101 | K20: 1.524 | L20: 8.382 | M20: =K20+0.0254 -> 1.5494 | N20: =PI()*(M20*M20-K20*K20)/4 -> 0.061311605 | O20: =N20*L20 -> 0.51391387 | P20: 8000 | Q20: =P20*O20 -> 4111.311
A21: K-105 | B21: Centrifugal Compressor | C21: Power, kW | D21: 7774.6049 | E21: 580000 | F21: 20000 | G21: 0.6 | H21: =(E21+(F21*(D21^G21)))/1000000 -> 4.8995349 | J21: V-102 | K21: 1.3716 | L21: 4.8006 | M21: =K21+0.0254 -> 1.397 | N21: =PI()*(M21*M21-K21*K21)/4 -> 0.055231115 | O21: =N21*L21 -> 0.26514249 | P21: 8000 | Q21: =P21*O21 -> 2121.1399
A22: K-402 | B22: Centrifugal Compressor | C22: Power, kW | D22: 2615.689 | E22: 580000 | F22: 20000 | G22: 0.6 | H22: =(E22+(F22*(D22^G22)))/1000000 -> 2.8268892 | J22: V-103 | K22: 3.6576 | L22: 12.8016 | M22: =K22+0.0254 -> 3.683 | N22: =PI()*(M22*M22-K22*K22)/4 -> 0.14643846 | O22: =N22*L22 -> 1.8746466 | P22: 8000 | Q22: =P22*O22 -> 14997.173
A23: K-100 | B23: Centrifugal Compressor | C23: Power, kW | D23: 41.043826 | E23: 580000 | F23: 20000 | G23: 0.6 | H23: =(E23+(F23*(D23^G23)))/1000000 -> 0.76577133 | J23: T-100 | K23: 3.114 | L23: =0.60960000000058*(10) -> 6.096 | M23: =K23+0.0254 -> 3.1394 | N23: =PI()*(M23*M23-K23*K23)/4 -> 0.12474979 | O23: =N23*L23 -> 0.76047469 | P23: 8000 | Q23: =P23*O23 -> 6083.7975
A24: K-101 | B24: Centrifugal Compressor | C24: Power, kW | D24: 3297.1211 | E24: 580000 | F24: 20000 | G24: 0.6 | H24: =(E24+(F24*(D24^G24)))/1000000 -> 3.1617307 | J24: T-101 | K24: 5.1495 | L24: =0.60960000000058*(10) -> 6.096 | M24: =K24+0.0254 -> 5.1749 | N24: =PI()*(M24*M24-K24*K24)/4 -> 0.20596263 | O24: =N24*L24 -> 1.2555482 | P24: 8000 | Q24: =P24*O24 -> 10044.385
A25: K-109 | B25: Centrifugal Compressor | C25: Power, kW | D25: 4754.8911 | E25: 580000 | F25: 20000 | G25: 0.6 | H25: =(E25+(F25*(D25^G25)))/1000000 -> 3.7959874 | J25: ATR | K25: 3.048 | L25: 10.668 | M25: =K25+0.0254 -> 3.0734 | N25: =PI()*(M25*M25-K25*K25)/4 -> 0.1221165 | O25: =N25*L25 -> 1.3027388 | P25: 8000 | Q25: =P25*O25 -> 10421.911
A26: Heat Exchangers
A27: E-128 | B27: U Tube HEX | C27: Area | D27: 623.95738 | E27: 28000 | F27: 54 | G27: 1.2 | H27: =(E27+(F27*(D27^G27)))/1000000 -> 0.15006177
A28: E-129 | B28: U Tube HEX | C28: Area | D28: 85.277032 | E28: 28000 | F28: 54 | G28: 1.2 | H28: =(E28+(F28*(D28^G28)))/1000000 -> 0.039204494
A29: E-130 | B29: U Tube HEX | C29: Area | D29: 56.302091 | E29: 28000 | F29: 54 | G29: 1.2 | H29: =(E29+(F29*(D29^G29)))/1000000 -> 0.034808057
A30: E-131 | B30: U Tube HEX | C30: Area | D30: 162.29127 | E30: 28000 | F30: 54 | G30: 1.2 | H30: =(E30+(F30*(D30^G30)))/1000000 -> 0.052252022
A31: E-132 | B31: U Tube HEX | C31: Area | D31: 2320.2029 | E31: 28000 | F31: 54 | G31: 1.2 | H31: =(E31+(F31*(D31^G31)))/1000000 -> 0.61823494
A32: E-133 | B32: U Tube HEX | C32: Area | D32: 160.80251 | E32: 28000 | F32: 54 | G32: 1.2 | H32: =(E32+(F32*(D32^G32)))/1000000 -> 0.051985299
A33: E-134 | B33: U Tube HEX | C33: Area | D33: 1396.5434 | E33: 28000 | F33: 54 | G33: 1.2 | H33: =(E33+(F33*(D33^G33)))/1000000 -> 0.34896603
A34: E-135 | B34: U Tube HEX | C34: Area | D34: 4119.717 | E34: 28000 | F34: 54 | G34: 1.2 | H34: =(E34+(F34*(D34^G34)))/1000000 -> 1.2035325
A35: E-136 | B35: U Tube HEX | C35: Area | D35: 4.5208054 | E35: 28000 | F35: 54 | G35: 1.2 | H35: =(E35+(F35*(D35^G35)))/1000000 -> 0.028330105
A36: E-137 | B36: U Tube HEX | C36: Area | D36: 687.95728 | E36: 28000 | F36: 54 | G36: 1.2 | H36: =(E36+(F36*(D36^G36)))/1000000 -> 0.16523583
A37: E-138 | B37: U Tube HEX | C37: Area | D37: 1353.3089 | E37: 28000 | F37: 54 | G37: 1.2 | H37: =(E37+(F37*(D37^G37)))/1000000 -> 0.33707942
A38: E-139 | B38: U Tube HEX | C38: Area | D38: 5159.0463 | E38: 28000 | F38: 54 | G38: 1.2 | H38: =(E38+(F38*(D38^G38)))/1000000 -> 1.5678452
... A75: E-102 | B75: U Tube HEX | C75: Area | D75: 60.318579 | E75: 28000 | F75: 54 | G75: 1.2 | H75: =(E75+(F75*(D75^G75)))/1000000 -> 0.035394947
A76: Reactors
A77: SMR | B77: Furnace | C77: Duty, MW | D77: =317324616.548787/3600/1000 -> 88.145727 | E77: 80000 | F77: 109000 | G77: 0.8 | H77: =(E77+(F77*(D77^G77)))/1000000 -> 4.0027218
A78: Methanator | B78: Furnace | C78: Duty, MW | D78: =2900425.6074054/3600/1000 -> 0.80567378 | E78: 80000 | F78: 109000 | G78: 0.8 | H78: =(E78+(F78*(D78^G78)))/1000000 -> 0.17169674
...

Sheet Production Costs
A4: Description | B4: Assumption | C4: M$/year
A5: Labor Costs
A6: Operating labor | B6: 9 shift positions, 9 operators/shift | C6: =50000*9*9/1000000 -> 4.05
A7: Supervision | B7: 25% of operating Labor | C7: =0.25*C6 -> 1.0125
A8: Direct overhead | B8: 45% of labor and supervision | C8: =0.45*(C6+C7) -> 2.278125
C9: =SUM(C6:C8) -> 7.340625
A10: Maintanance Costs
A11: Maintanance | B11: 3% of the installed capital cost | C11: =0.03*CAPEX!B116 -> 8.0920588
C12: =C11 -> 8.0920588
A13: Overhead Expenses
A14: Plant overhead | B14: 65% of labor and maintanace | C14: =0.65*(C6+C7+C8+C11) -> 10.031244
A15: Tax & Insurance | B15: 2% of installed cost and offsites | C15: =0.02*(CAPEX!B116+CAPEX!B117) -> 7.0131176
C16: =SUM(C14:C15) -> 17.044362
A17: Interest
A18: Interest on debit | B18: 6% of working capital | C18: =0.06*CAPEX!B121 -> 4.4182641
C19: =C18 -> 4.4182641
A20: Total fixed production costs | C20: =C9+C12+C16+C19 -> 36.89531

Sheet Catalyst Costs
A2: Unit operation | B2: Catalyst used | C2: Total kg | D2: Year | E2: $/kg | F2: $ | G2: 2019$ | H2: Reference
A3: Hydro-desulfurization | B3: CoMo | C3: 0.31531406 | D3: 2019 | E3: 10 | F3: =C3*E3 -> 3.1531406 | G3: =F3*$B$14/$B$14 -> 3.1531406 | H3: Alibaba
A4: Desulfurization | B4: ZnO | C4: 2.1172244 | D4: 2015 | E4: =1.04*1.2 -> 1.248 | F4: =C4*E4 -> 2.642296 | G4: =F4*$B$14/$B$13 -> 2.882893 | H4: Cora2019 (table S4)
A5: SMR | B5: NiO | C5: 1.6231175 | D5: 2015 | E5: =1.81*1.2 -> 2.172 | F5: =C5*E5 -> 3.5254112 | G5: =F5*$B$14/$B$13 -> 3.8464212 | H5: Cora2019 (table S4)
A6: ATR | B6: NiO | C6: 1.298494 | D6: 2015 | E6: =1.81*1.2 -> 2.172 | F6: =C6*E6 -> 2.820329 | G6: =F6*$B$14/$B$13 -> 3.0771369 | H6: Cora2019 (table S4)
A7: HTWGS | B7: ZnO | C7: 3.9490395 | D7: 2015 | E7: =1.04*1.2 -> 1.248 | F7: =C7*E7 -> 4.9284013 | G7: =F7*$B$14/$B$13 -> 5.377162 | H7: Cora2019 (table S4)
A8: LTWGS | B8: ZnO | C8: 7.9534587 | D8: 2015 | E8: =1.04*1.2 -> 1.248 | F8: =C8*E8 -> 9.9259164 | G8: =F8*$B$14/$B$13 -> 10.829731 | H8: Cora2019 (table S4)
A9: Methanation | B9: NiO | C9: 1.012939 | D9: 2015 | E9: =1.81*1.2 -> 2.172 | F9: =C9*E9 -> 2.2001036 | G9: =F9*$B$14/$B$13 -> 2.4004363 | H9: Cora2019 (table S4)
A10: Ammonia synthesis | B10: Fe2O3 | C10: 3.7328053 | D10: 2015 | E10: =2.23*1.2 -> 2.676 | F10: =C10*E10 -> 9.9889869 | G10: =F10*$B$14/$B$13 -> 10.898544 | H10: Cora2019 (table S4)
A11: Total catalayst cost (M$/year) | G11: =SUM(G3:G10)*8000/1000000 -> 0.33972372
A13: CEPCI 2015 | B13: 556.8
A14: CEPCI 2019 | B14: 607.5

Sheet OPEX
B3: Material | C3: Unit | D3: Quantity | E3: Price ($/unit) | F3: Total cost | G3: 2019 costs | H3: Reference
B4: Raw Material Costs
B5: Natural gas | C5: ton/hr | D5: =29101.8207550049/1000 -> 29.101821 | E5: 315 | F5: =E5*D5 -> 9167.0735 | G5: =F5*C$25/C$24 -> 9233.9532 | H5: 24 USD2018/MWh @ 47.1 MJ/kg | K5: =D5*1000/Summary!$C$23 -> 0.43035039
B6: Water | C6: ton/hr | D6: =55864.8265857697/1000 -> 55.864827 | E6: 0.177 | F6: =E6*D6 -> 9.8880743 | G6: =F6*C$25/C$24 -> 9.9602141 | H6: Turton2018 (Pg. 246) | K6: =D6*1000/Summary!$C$23 -> 0.82611497
B7: Utility Costs
B8: Cooling water | C8: GJ/hr | D8: =550925906.27899/1000000 -> 550.92591 | E8: 0.378 | F8: =E8*D8 -> 208.24999 | G8: =F8*C$25/C$24 -> 209.76931 | H8: Turton2018 (Pg. 246) | K8: =D8*1000/Summary!$C$23 -> 8.1469534 | M8: =K8+K16+K19 -> 18.120095
B9: Electricity | C9: kWh | D9: 63254.431 | E9: 0.0674 | F9: =E9*D9 -> 4263.3487 | G9: =F9*C$25/C$24 -> 4294.4525 | H9: Turton2018 (Pg. 246) | K9: =D9*1000/Summary!$C$23 -> 935.39058
B10: Fired Heat - Natural Gas | C10: GJ/hr | D10: 0 | E10: 6.67 | F10: =E10*D10 -> 0 | G10: =F10*C$25/C$24 -> 0 | H10: 24 USD2018/MWh @ 47.1 MJ/kg
B11: Additional Costs (purge,etc)
B12: CO2 emissions | C12: ton/hr | D12: =79305.0822691293/1000 -> 79.305082 | E12: 30 | F12: =E12*D12 -> 2379.1525 | G12: =F12*C25/C25 -> 2379.1525 | H12: https://markets.businessinsider.com/commodities/co2-european-emission-allowances | K12: =D12*1000/Summary!$C$23 -> 1.1727436 | M12: =K12+K17 -> 1.4371155
B13: Purge gas emissions | C13: ton/hr | D13: =584.815321092863/1000 -> 0.58481532 | E13: 0 | F13: =E13*D13 -> 0 | G13: =F13*C$25/C$24 -> 0 | H13: We are not costing emissions from the purge | K13: =D13*1000/Summary!$C$23 -> 0.0086481015
B14: External Furnace for SMR Heating
B15: Natural gas | C15: ton/hr | D15: =6517/1000 -> 6.517 | E15: 315 | F15: =E15*D15 -> 2052.855 | G15: =F15*C$25/C$24 -> 2067.8319 | H15: 24 USD2018/MWh @ 47.1 MJ/kg | K15: =D15*1000/Summary!$C$23 -> 0.096371753
B16: Cooling water | C16: GJ/hr | D16: =165559324.987747/1000000 -> 165.55932 | E16: 0.378 | F16: =E16*D16 -> 62.581425 | G16: =F16*C$25/C$24 -> 63.037996 | H16: Turton2018 (Pg. 246) | K16: =D16*1000/Summary!$C$23 -> 2.4482496
B17: CO2 emissions | C17: ton/hr | D17: =17877.7663903652/1000 -> 17.877766 | E17: 30 | F17: =E17*D17 -> 536.33299 | G17: =F17 -> 536.33299 | H17: https://markets.businessinsider.com/commodities/co2-european-emission-allowances | K17: =D17*1000/Summary!$C$23 -> 0.2643719
B18: MP and LP Steam Utilization
B19: Cooling water | C19: GJ/hr | D19: =508859926.043997/1000000 -> 508.85993 | E19: 0.378 | F19: =E19*D19 -> 192.34905 | G19: =F19*C$25/C$24 -> 193.75236 | H19: Turton2018 (Pg. 246) | K19: =D19*1000/Summary!$C$23 -> 7.5248923
B20: Catalyst costs | G20: =SUM('Catalyst Costs'!G11) -> 0.33972372 | H20: Refer Catalyst Costs sheet
B21: OPEX | C21: M$/year | G21: =(G5+G6+G8+G9+G10+G12+G13+G15+G16+G17+G19)/1000000*8000+G20 -> 152.24567
B23: Reference Data
B24: CEPCI 2018 | C24: 603.1
B25: CEPCI 2019 | C25: 607.5

Sheet Summary
F2: Unit/kg ammonia | G2: $/kg ammonia
B3: Purchased equipment cost 2019 (M$/year) | C3: =SUM(CAPEX!B115) -> 72.121736 | E3: Natural gas | F3: =(OPEX!D5+OPEX!D15)*1000/Summary!C23 -> 0.52672214 | G3: =(OPEX!G5+OPEX!G15)/Summary!C23 -> 0.16712795
B4: Installed capital cost | C4: =SUM(CAPEX!B116) -> 269.73529 | E4: Water | F4: =(OPEX!D6)*1000/Summary!C23 -> 0.82611497 | G4: =OPEX!G6/Summary!C23 -> 0.00014728914
B5: Offsites (OS) | C5: =SUM(CAPEX!B117) -> 80.920588 | E5: Nitrogen | F5: 0 | G5: 0
B6: Design and engineering (D&E) | C6: =SUM(CAPEX!B118) -> 105.19676 | E6: Hydrogen | F6: 0 | G6: 0
B7: Contingency (X) | C7: =SUM(CAPEX!B119) -> 35.065588 | E7: Electricity | F7: =OPEX!D9/Summary!C23 -> 0.93539058 | G7: =OPEX!G9/Summary!C23 -> 0.063505281
B8: Fixed capital investment | C8: =SUM(CAPEX!B120) -> 490.91823 | E8: Other utilities | F8: 0 | G8: =(OPEX!G8+OPEX!G10+OPEX!G12+OPEX!G13+OPEX!G16+OPEX!G17+OPEX!G19+OPEX!G20*1000000/8000)/Summary!C23 -> 0.050640799
B9: Working capital | C9: =SUM(CAPEX!B121) -> 73.637735 | E9: CAPEX | F9: 0 | G9: =C18*10^6/8000/C23 -> 0.13305437
B10: Total investment | C10: =SUM(CAPEX!B122) -> 564.55597 | E10: Fixed costs | F10: 0 | G10: =C19*10^6/8000/C23 -> 0.068199818
B11: Labor costs | C11: =SUM('Production Costs'!C9) -> 7.340625 | G11: =SUM(G3:G10) -> 0.4826755
B12: Maintanance costs | C12: =SUM('Production Costs'!C12) -> 8.0920588
B13: Overhead expenses | C13: =SUM('Production Costs'!C16) -> 17.044362
B14: Interest | C14: =SUM('Production Costs'!C19) -> 4.4182641
B15: Project lifetime | C15: =SUM(CAPEX!B123) -> 25
B16: Interest rate | C16: =SUM(CAPEX!B124) -> 0.12
B17: ACCR | C17: =SUM(CAPEX!B125) -> 0.12749997
B18: CAPEX (M$/year) | C18: =SUM(CAPEX!B127) -> 71.980869
B19: Fixed Production Costs (M$/year) | C19: ='Production Costs'!C20 -> 36.89531
B20: OPEX (M$/year) | C20: =SUM(OPEX!G21) -> 152.24567
B21: Total Expenses (M$/year) | C21: =(C18+C19+C20) -> 261.12185
B22: Total Expenses ($/hr) | C22: =(C21)*1000000/8000 -> 32640.231
B23: Total Ammonia Produced (kg/hr) | C23: 67623.55
B24: Cost of Ammonia per kg | C24: =C22/C23 -> 0.4826755
