Workbook

Sheet CAPEX
A1: Cost factors
A2: Equipment erection | B2: fer | C2: 0.3
A3: Piping | B3: fp | C3: 0.8
A4: Instrumentation and control | B4: fi | C4: 0.3
A5: Electrical | B5: fel | C5: 0.2
A6: Civil | B6: fc | C6: 0.3
A7: Structures and buildings | B7: fs | C7: 0.2
A8: Lagging and paint | B8: fl | C8: 0.1
A9: Material factor for 304 SS | B9: fm | C9: 1.3
A12: Equipment | B12: Equipment approximated as | C12: Dimension needed | D12: Value | E12: a | F12: b | G12: n | H12: Purchased Cost (Ce,i,a) | J12: Equipment | K12: Internal diameter (m) | L12: h (m) | M12: External diameter (m) | N12: Area for shell (m2) | O12: Volume | P12: Density (kg/m3) | Q12: Shell mass (kg)
A13: Compressors | J13: BED1 | K13: 2 | L13: 2.13 | M13: =K13+0.0254 -> 2.0254 | N13: =PI()*(M13*M13-K13*K13)/4 -> 0.080303161 | O13: =N13*L13 -> 0.17104573 | P13: 8000 | Q13: =P13*O13 -> 1368.3659
A14: K-102 | B14: Centrifugal Compressor | C14: Power, kW | D14: 4367.6289 | E14: 580000 | F14: 20000 | G14: 0.6 | H14: =(E14+(F14*(D14^G14)))/1000000 -> 3.6361695 | J14: BED2 | K14: 2 | L14: 3.07 | M14: =K14+0.0254 -> 2.0254 | N14: =PI()*(M14*M14-K14*K14)/4 -> 0.080303161 | O14: =N14*L14 -> 0.2465307 | P14: 8000 | Q14: =P14*O14 -> 1972.2456
A15: K-103 | B15: Centrifugal Compressor | C15: Power, kW | D15: 7075.0868 | E15: 580000 | F15: 20000 | G15: 0.6 | H15: =(E15+(F15*(D15^G15)))/1000000 -> 4.661963 | J15: BED3 | K15: 2 | L15: 4.84 | M15: =K15+0.0254 -> 2.0254 | N15: =PI()*(M15*M15-K15*K15)/4 -> 0.080303161 | O15: =N15*L15 -> 0.3886673 | P15: 8000 | Q15: =P15*O15 -> 3109.3384
A16: K-104 | B16: Centrifugal Compressor | C16: Power, kW | D16: 9353.2605 | E16: 580000 | F16: 20000 | G16: 0.6 | H16: =(E16+(F16*(D16^G16)))/1000000 -> 5.4062278 | J16: V-502 | K16: 3 | L16: 5 | M16: =K16+0.0254 -> 3.0254 | N16: =PI()*(M16*M16-K16*K16)/4 -> 0.12020139 | O16: =N16*L16 -> 0.60100694 | P16: 8000 | Q16: =P16*O16 -> 4808.0555
A17: K-105 | B17: Centrifugal Compressor | C17: Power, kW | D17: 12399.27 | E17: 580000 | F17: 20000 | G17: 0.6 | H17: =(E17+(F17*(D17^G17)))/1000000 -> 6.2956769 | J17: V-100 | K17: 3 | L17: 5 | M17: =K17+0.0254 -> 3.0254 | N17: =PI()*(M17*M17-K17*K17)/4 -> 0.12020139 | O17: =N17*L17 -> 0.60100694 | P17: 8000 | Q17: =P17*O17 -> 4808.0555
A18: K-402 | B18: Centrifugal Compressor | C18: Power, kW | D18: 2473.4333 | E18: 580000 | F18: 20000 | G18: 0.6 | H18: =(E18+(F18*(D18^G18)))/1000000 -> 2.7527518 | J18: V-101 | K18: 3 | L18: 5 | M18: =K18+0.0254 -> 3.0254 | N18: =PI()*(M18*M18-K18*K18)/4 -> 0.12020139 | O18: =N18*L18 -> 0.60100694 | P18: 8000 | Q18: =P18*O18 -> 4808.0555
A19: K-100 | B19: Centrifugal Compressor | C19: Power, kW | D19: 35.308765 | E19: 580000 | F19: 20000 | G19: 0.6 | H19: =(E19+(F19*(D19^G19)))/1000000 -> 0.74973035
A20: K-101 | B20: Centrifugal Compressor | C20: Power, kW | D20: 1945.1569 | E20: 580000 | F20: 20000 | G20: 0.6 | H20: =(E20+(F20*(D20^G20)))/1000000 -> 2.4610606
A21: K-109 | B21: Centrifugal Compressor | C21: Power, kW | D21: 4534.3358 | E21: 580000 | F21: 20000 | G21: 0.6 | H21: =(E21+(F21*(D21^G21)))/1000000 -> 3.7056346
A22: Heat Exchangers
A23: E-112 | B23: U Tube HEX | C23: Area | D23: 227.78362 | E23: 28000 | F23: 54 | G23: 1.2 | H23: =(E23+(F23*(D23^G23)))/1000000 -> 0.064426777
A24: E-108 | B24: U Tube HEX | C24: Area | D24: 1121.5349 | E24: 28000 | F24: 54 | G24: 1.2 | H24: =(E24+(F24*(D24^G24)))/1000000 -> 0.27469997
A25: E-110 | B25: U Tube HEX | C25: Area | D25: 410.71821 | E25: 28000 | F25: 54 | G25: 1.2 | H25: =(E25+(F25*(D25^G25)))/1000000 -> 0.10190035
A26: E-117 | B26: U Tube HEX | C26: Area | D26: 11551.869 | E26: 28000 | F26: 54 | G26: 1.2 | H26: =(E26+(F26*(D26^G26)))/1000000 -> 4.0791328
A27: E-119 | B27: U Tube HEX | C27: Area | D27: 91.614607 | E27: 28000 | F27: 54 | G27: 1.2 | H27: =(E27+(F27*(D27^G27)))/1000000 -> 0.040211006
A28: E-113 | B28: U Tube HEX | C28: Area | D28: 228.3426 | E28: 28000 | F28: 54 | G28: 1.2 | H28: =(E28+(F28*(D28^G28)))/1000000 -> 0.064534072
A29: E-109 | B29: U Tube HEX | C29: Area | D29: 862.2824 | E29: 28000 | F29: 54 | G29: 1.2 | H29: =(E29+(F29*(D29^G29)))/1000000 -> 0.20795884
A30: E-114 | B30: U Tube HEX | C30: Area | D30: 10254.848 | E30: 28000 | F30: 54 | G30: 1.2 | H30: =(E30+(F30*(D30^G30)))/1000000 -> 3.5396306
A31: E-116 | B31: U Tube HEX | C31: Area | D31: 11.991158 | E31: 28000 | F31: 54 | G31: 1.2 | H31: =(E31+(F31*(D31^G31)))/1000000 -> 0.029064209
A32: E-118 | B32: U Tube HEX | C32: Area | D32: 587.02522 | E32: 28000 | F32: 54 | G32: 1.2 | H32: =(E32+(F32*(D32^G32)))/1000000 -> 0.14144409
A33: E-115 | B33: U Tube HEX | C33: Area | D33: 4.2970784 | E33: 28000 | F33: 54 | G33: 1.2 | H33: =(E33+(F33*(D33^G33)))/1000000 -> 0.0283106
A34: E-121 | B34: U Tube HEX | C34: Area | D34: 1477.1083 | E34: 28000 | F34: 54 | G34: 1.2 | H34: =(E34+(F34*(D34^G34)))/1000000 -> 0.37131166
... A37: E-122 | B37: U Tube HEX | C37: Area | D37: 64.058395 | E37: 28000 | F37: 54 | G37: 1.2 | H37: =(E37+(F37*(D37^G37)))/1000000 -> 0.035948497
A38: Reactors
A39: BED1 | B39: Pressure Vessel | C39: Shell mass, kg | D39: =SUM(Q13) -> 1368.3659 | E39: 17400 | F39: 79 | G39: 0.85 | H39: =(E39+(F39*(D39^G39)))/1000000 -> 0.053993082
A40: BED2 | B40: Pressure Vessel | C40: Shell mass, kg | D40: =SUM(Q14) -> 1972.2456 | E40: 17400 | F40: 79 | G40: 0.85 | H40: =(E40+(F40*(D40^G40)))/1000000 -> 0.067327974
A41: BED3 | B41: Pressure Vessel | C41: Shell mass, kg | D41: =SUM(Q15) -> 3109.3384 | E41: 17400 | F41: 79 | G41: 0.85 | H41: =(E41+(F41*(D41^G41)))/1000000 -> 0.090918203
A42: Flash Separators
A43: V-502 | B43: Pressure Vessel | C43: Shell mass, kg | D43: =SUM(Q16) -> 4808.0555 | E43: 12800 | F43: 73 | G43: 0.85 | H43: =(E43+(F43*(D43^G43)))/1000000 -> 0.11120041
A44: V-100 | B44: Pressure Vessel | C44: Shell mass, kg | D44: =SUM(Q17) -> 4808.0555 | E44: 12800 | F44: 73 | G44: 0.85 | H44: =(E44+(F44*(D44^G44)))/1000000 -> 0.11120041
...

Sheet Production Costs
A4: Description | B4: Assumption | C4: M$/year
A5: Labor Costs
A6: Operating labor | B6: 9 shift positions, 9 operators/shift | C6: =50000*9*9/1000000 -> 4.05
A7: Supervision | B7: 25% of operating Labor | C7: =0.25*C6 -> 1.0125
A8: Direct overhead | B8: 45% of labor and supervision | C8: =0.45*(C6+C7) -> 2.278125
C9: =SUM(C6:C8) -> 7.340625
A10: Maintanance Costs
A11: Maintanance | B11: 3% of the installed capital cost | C11: =0.03*CAPEX!B57 -> 5.035135
C12: =C11 -> 5.035135
A13: Overhead Expenses
A14: Plant overhead | B14: 65% of labor and maintanace | C14: =0.65*(C6+C7+C8+C11) -> 8.044244
A15: Tax & Insurance | B15: 2% of installed cost and offsites | C15: =0.02*(CAPEX!B57+CAPEX!B58) -> 4.3637837
C16: =SUM(C14:C15) -> 12.408028
A17: Interest
A18: Interest on debit | B18: 6% of working capital | C18: =0.06*CAPEX!B62 -> 2.7491837
C19: =C18 -> 2.7491837
A20: Total fixed production costs | C20: =C9+C12+C16+C19 -> 27.532972

Sheet Catalyst Costs
A2: Unit operation | B2: Catalyst used | C2: Total kg | D2: Year | E2: $/kg | F2: $ | G2: 2019$ | H2: Reference
A3: Ammonia synthesis | B3: Fe2O3 | C3: 3.8664904 | D3: 2015 | E3: =2.23*1.2 -> 2.676 | F3: =C3*E3 -> 10.346728 | G3: =F3*$B$7/$B$6 -> 11.28886 | H3: Cora2019 (table S4)
A4: Total catalayst cost (M$/year) | G4: =SUM(G3:G3)*8000/1000000 -> 0.090310884
A6: CEPCI 2015 | B6: 556.8
A7: CEPCI 2019 | B7: 607.5

Sheet OPEX
B3: Material | C3: Unit | D3: Quantity | E3: Price ($/unit) | F3: Total cost | G3: 2019 costs | H3: Reference
B4: Raw Material Costs
B5: Nitrogen | C5: ton/hr | D5: =57114.3306483769/1000 -> 57.114331 | E5: 90.4 | F5: =E5*D5 -> 5163.1355 | G5: =F5*C$25/C$24 -> 5200.8039 | H5: Lin2018 (Pg. 4) | J5: =D5*1000/Summary!$C$25 -> 0.81539029
B6: Hydrogen | C6: ton/hr | D6: =12342.7922526459/1000 -> 12.342792 | E6: 0 | F6: =E6*D6 -> 0 | G6: =F6 -> 0 | H6: Chi2017 (Pg. 3) | J6: =D6*1000/Summary!$C$25 -> 0.17621134
B7: Hydrogen (nuclear) | C7: ton/hr | D7: =12342.7922526459/1000 -> 12.342792 | E7: =7.0877*1000 -> 7087.7 | F7: =E7*D7 -> 87482.009 | G7: =F7 -> 87482.009 | H7: Additional Economics Parameters
B8: Hydrogen (solar) | C8: ton/hr | D8: =12342.7922526459/1000 -> 12.342792 | E8: =10.1123*1000 -> 10112.3 | F8: =E8*D8 -> 124814.02 | G8: =F8 -> 124814.02 | H8: Additional Economics Parameters
B9: Hydrogen (wind) | C9: ton/hr | D9: =12342.7922526459/1000 -> 12.342792 | E9: =9.5241*1000 -> 9524.1 | F9: =E9*D9 -> 117553.99 | G9: =F9 -> 117553.99 | H9: Additional Economics Parameters
B10: Utility Costs
B11: Cooling water | C11: GJ/hr | D11: =180494151.174171/1000000 -> 180.49415 | E11: 0.378 | F11: =E11*D11 -> 68.226789 | G11: =F11*C$25/C$24 -> 68.724547 | H11: Turton2018 (Pg. 246) | J11: =D11*1000/Summary!$C$25 -> 2.576817 | L11: =J11+J16 -> 3.1077155
B12: Electricity | C12: kWh | D12: 32913.905 | E12: 0.0674 | F12: =E12*D12 -> 2218.3972 | G12: =F12*C$25/C$24 -> 2234.5818 | H12: Turton2018 (Pg. 246) | J12: =D12*1000/Summary!$C$25 -> 469.89395
B13: Additional Costs (purge,etc)
B14: Flue gas emissions | C14: ton/hr | D14: 0.481 | E14: 0 | F14: =E14*D14 -> 0 | G14: =F14*C$25/C$24 -> 0 | H14: Turton2018 (Pg. 246) | J14: =D14*1000/Summary!$C$25 -> 0.0068669758
B15: HP and LP Steam Utilization
B16: Cooling water | C16: GJ/hr | D16: =37186990.5184449/1000000 -> 37.186991 | E16: 0.378 | F16: =E16*D16 -> 14.056682 | G16: =F16*C$25/C$24 -> 14.159235 | H16: Turton2018 (Pg. 246) | J16: =D16*1000/Summary!$C$25 -> 0.53089847
B17: Catalyst costs | G17: =SUM('Catalyst Costs'!G4) -> 0.090310884 | H17: Refer Catalyst Costs sheet
B18: Total OPEX (electricity mix) | C18: M$/year | G18: =(G$5+G6+G$11+G$12+G$14+G$16)*8000/1000000+G$17 -> 60.236467
B19: Total OPEX (nuclear) | C19: M$/year | G19: =(G$5+G7+G$11+G$12+G$14+G$16)*8000/1000000+G$17 -> 760.09254
B20: Total OPEX (solar) | C20: M$/year | G20: =(G$5+G8+G$11+G$12+G$14+G$16)*8000/1000000+G$17 -> 1058.7486
B21: Total OPEX (wind) | C21: M$/year | G21: =(G$5+G9+G$11+G$12+G$14+G$16)*8000/1000000+G$17 -> 1000.6684
B23: Reference Data
B24: CEPCI 2018 | C24: 603.1
B25: CEPCI 2019 | C25: 607.5

Sheet Summary
F2: Unit/kg ammonia | G2: $/kg ammonia
B3: Purchased equipment cost 2019 (M$/year) | C3: =SUM(CAPEX!B56) -> 44.876426 | E3: Natural gas | F3: 0 | G3: 0
B4: Installed capital cost | C4: =SUM(CAPEX!B57) -> 167.83783 | E4: Water | F4: 0 | G4: 0
B5: Offsites (OS) | C5: =SUM(CAPEX!B58) -> 50.35135 | E5: Nitrogen | F5: =OPEX!D5*1000/Summary!C25 -> 0.81539029 | G5: =OPEX!G5/Summary!C25 -> 0.074249053
B6: Design and engineering (D&E) | C6: =SUM(CAPEX!B59) -> 65.456756 | E6: Hydrogen | F6: =OPEX!D7*1000/Summary!C25 -> 0.17621134 | G6: =OPEX!G7/Summary!C25 -> 1.2489331
B7: Contingency (X) | C7: =SUM(CAPEX!B60) -> 21.818919 | E7: Electricity | F7: =OPEX!D12/C25 -> 0.46989395 | G7: =OPEX!G12/Summary!C25 -> 0.031901912
B8: Fixed capital investment | C8: =SUM(CAPEX!B61) -> 305.46486 | E8: Other utilities | F8: 0 | G8: =(OPEX!G11+OPEX!G14+OPEX!G16+OPEX!G17*10^6/8000)/C25 -> 0.0013444517
B9: Working capital | C9: =SUM(CAPEX!B62) -> 45.819729 | E9: CAPEX | F9: 0 | G9: =C18*10^6/8000/C25 -> 0.079928127
B10: Total investment | C10: =SUM(CAPEX!B63) -> 351.28459 | E10: Fixed costs | F10: 0 | G10: =C19*10^6/8000/C25 -> 0.049134161
B11: Labor costs | C11: =SUM('Production Costs'!C9) -> 7.340625 | G11: =SUM(G3:G10) -> 1.4854908
B12: Maintanance costs | C12: =SUM('Production Costs'!C12) -> 5.035135
B13: Overhead expenses | C13: =SUM('Production Costs'!C16) -> 12.408028
B14: Interest | C14: =SUM('Production Costs'!C19) -> 2.7491837
B15: Project lifetime | C15: =SUM(CAPEX!B64) -> 25
B16: Interest rate | C16: =SUM(CAPEX!B65) -> 0.12
B17: ACCR | C17: =SUM(CAPEX!B66) -> 0.12749997
B18: CAPEX (M$/year) | C18: =SUM(CAPEX!B68) -> 44.788774
B19: Fixed Production Costs (M$/year) | C19: ='Production Costs'!C20 -> 27.532972
C21: Base case | D21: Nuclear | E21: Solar | F21: Wind
B22: OPEX (M$/year) | C22: =SUM(OPEX!G18) -> 60.236467 | D22: =SUM(OPEX!G19) -> 760.09254 | E22: =SUM(OPEX!G20) -> 1058.7486 | F22: =SUM(OPEX!G21) -> 1000.6684
B23: Total Expenses (M$/year) | C23: =($C$18+$C$19+C22) -> 132.55821 | D23: =($C$18+$C$19+D22) -> 832.41428 | E23: =($C$18+$C$19+E22) -> 1131.0704 | F23: =($C$18+$C$19+F22) -> 1072.9901
B24: Total Expenses ($/hr) | C24: =(C23)*1000000/8000 -> 16569.777 | D24: =(D23)*1000000/8000 -> 104051.79 | E24: =(E23)*1000000/8000 -> 141383.79 | F24: =(F23)*1000000/8000 -> 134123.76
B25: Total Ammonia Produced (kg/hr) | C25: 70045.39 | D25: 70045.39 | E25: 70045.39 | F25: 70045.39
B26: Cost of Ammonia per kg | C26: =C24/C25 -> 0.2365577 | D26: =D24/D25 -> 1.4854908 | E26: =E24/E25 -> 2.0184597 | F26: =F24/F25 -> 1.9148122
B27: Increase from Base case | D27: =D26/$C$26 -> 6.279613 | E27: =E26/$C$26 -> 8.5326313 | F27: =F26/$C$26 -> 8.0944824
