Workbook

Sheet Ammonia
A1: NG price | B1: BAU | C1: Biomass | D1: Wind | E1: Solar | F1: Nuclear | G1: CO2 Biomass | H1: CO2 Wind | I1: CO2 Solar | J1: CO2 Nuclear | K1: Coal | M1: Process | N1: GWP | P1: H2 BAU | Q1: H2 Biomass | R1: H2 Wind | S1: H2 Solar | T1: H2 Nuclear | U1: H2 Coal
A2: 0 | B2: 411.21982 | C2: 842.03715 | D2: 1534.3206 | E2: 2380.4448 | F2: 1392.1344 | G2: =(B2-C2)/($N$3-$N$2) -> 197.62263 | H2: =(B2-D2)/($N$4-$N$2) -> 3424.0878 | I2: =(B2-E2)/($N$5-$N$2) -> -19692.25 | J2: =(B2-F2)/($N$6-$N$2) -> 1073.2107 | K2: 438.34265 | M2: BAU | N2: 1.04 | P2: 600.38772 | Q2: 3002.7523 | R2: 6931.4634 | S2: 11733.221 | T2: 6124.5564 | U2: 711.78457
A3: 50 | B3: 437.56332 | C3: =$C$2 -> 842.03715 | D3: =$D$2 -> 1534.3206 | E3: =$E$2 -> 2380.4448 | F3: =$F$2 -> 1392.1344 | G3: =(B3-C3)/($N$3-$N$2) -> 185.53845 | H3: =(B3-D3)/($N$4-$N$2) -> 3343.7722 | I3: =(B3-E3)/($N$5-$N$2) -> -19428.815 | J3: =(B3-F3)/($N$6-$N$2) -> 1044.3885 | K3: 494.9946 | M3: Biomass | N3: -1.14 | P3: 744.75085 | Q3: =Q2 -> 3002.7523 | R3: =R2 -> 6931.4634 | S3: =S2 -> 11733.221 | T3: =T2 -> 6124.5564 | U3: 1033.2846
A4: 100 | B4: 463.90682 | C4: =$C$2 -> 842.03715 | D4: =$D$2 -> 1534.3206 | E4: =$E$2 -> 2380.4448 | F4: =$F$2 -> 1392.1344 | G4: =(B4-C4)/($N$3-$N$2) -> 173.45428 | H4: =(B4-D4)/($N$4-$N$2) -> 3263.4567 | I4: =(B4-E4)/($N$5-$N$2) -> -19165.38 | J4: =(B4-F4)/($N$6-$N$2) -> 1015.5663 | K4: 551.64655 | M4: Wind | N4: 0.712 | P4: 889.11398 | Q4: =Q3 -> 3002.7523 | R4: =R3 -> 6931.4634 | S4: =S3 -> 11733.221 | T4: =T3 -> 6124.5564 | U4: 1354.7846
A5: 150 | B5: 490.25032 | C5: =$C$2 -> 842.03715 | D5: =$D$2 -> 1534.3206 | E5: =$E$2 -> 2380.4448 | F5: =$F$2 -> 1392.1344 | G5: =(B5-C5)/($N$3-$N$2) -> 161.3701 | H5: =(B5-D5)/($N$4-$N$2) -> 3183.1411 | I5: =(B5-E5)/($N$5-$N$2) -> -18901.945 | J5: =(B5-F5)/($N$6-$N$2) -> 986.74412 | K5: 608.2985 | M5: Solar | N5: 1.14 | P5: 1033.4771 | Q5: =Q4 -> 3002.7523 | R5: =R4 -> 6931.4634 | S5: =S4 -> 11733.221 | T5: =T4 -> 6124.5564 | U5: 1676.2846
A6: 200 | B6: 516.59382 | C6: =$C$2 -> 842.03715 | D6: =$D$2 -> 1534.3206 | E6: =$E$2 -> 2380.4448 | F6: =$F$2 -> 1392.1344 | G6: =(B6-C6)/($N$3-$N$2) -> 149.28593 | H6: =(B6-D6)/($N$4-$N$2) -> 3102.8256 | I6: =(B6-E6)/($N$5-$N$2) -> -18638.51 | J6: =(B6-F6)/($N$6-$N$2) -> 957.92191 | K6: 664.95044 | M6: Nuclear | N6: 0.126 | P6: 1177.8402 | Q6: =Q5 -> 3002.7523 | R6: =R5 -> 6931.4634 | S6: =S5 -> 11733.221 | T6: =T5 -> 6124.5564 | U6: 1997.7846
A7: 250 | B7: 542.93732 | C7: =$C$2 -> 842.03715 | D7: =$D$2 -> 1534.3206 | E7: =$E$2 -> 2380.4448 | F7: =$F$2 -> 1392.1344 | G7: =(B7-C7)/($N$3-$N$2) -> 137.20176 | H7: =(B7-D7)/($N$4-$N$2) -> 3022.51 | I7: =(B7-E7)/($N$5-$N$2) -> -18375.075 | J7: =(B7-F7)/($N$6-$N$2) -> 929.0997 | K7: 721.60239 | M7: Coal | P7: 1322.2034 | Q7: =Q6 -> 3002.7523 | R7: =R6 -> 6931.4634 | S7: =S6 -> 11733.221 | T7: =T6 -> 6124.5564 | U7: 2319.2846
A8: 300 | B8: 569.28082 | C8: =$C$2 -> 842.03715 | D8: =$D$2 -> 1534.3206 | E8: =$E$2 -> 2380.4448 | F8: =$F$2 -> 1392.1344 | G8: =(B8-C8)/($N$3-$N$2) -> 125.11758 | H8: =(B8-D8)/($N$4-$N$2) -> 2942.1945 | I8: =(B8-E8)/($N$5-$N$2) -> -18111.64 | J8: =(B8-F8)/($N$6-$N$2) -> 900.27749 | K8: 778.25434 | P8: 1466.5665 | Q8: =Q7 -> 3002.7523 | R8: =R7 -> 6931.4634 | S8: =S7 -> 11733.221 | T8: =T7 -> 6124.5564 | U8: 2640.7846
A9: 350 | B9: 595.62432 | C9: =$C$2 -> 842.03715 | D9: =$D$2 -> 1534.3206 | E9: =$E$2 -> 2380.4448 | F9: =$F$2 -> 1392.1344 | G9: =(B9-C9)/($N$3-$N$2) -> 113.03341 | H9: =(B9-D9)/($N$4-$N$2) -> 2861.8789 | I9: =(B9-E9)/($N$5-$N$2) -> -17848.205 | J9: =(B9-F9)/($N$6-$N$2) -> 871.45528 | K9: 834.90628 | P9: 1610.9296 | Q9: =Q8 -> 3002.7523 | R9: =R8 -> 6931.4634 | S9: =S8 -> 11733.221 | T9: =T8 -> 6124.5564 | U9: 2962.2846
A10: 400 | B10: 621.96782 | C10: =$C$2 -> 842.03715 | D10: =$D$2 -> 1534.3206 | E10: =$E$2 -> 2380.4448 | F10: =$F$2 -> 1392.1344 | G10: =(B10-C10)/($N$3-$N$2) -> 100.94923 | H10: =(B10-D10)/($N$4-$N$2) -> 2781.5634 | I10: =(B10-E10)/($N$5-$N$2) -> -17584.77 | J10: =(B10-F10)/($N$6-$N$2) -> 842.63307 | K10: 891.55823 | P10: 1755.2928 | Q10: =Q9 -> 3002.7523 | R10: =R9 -> 6931.4634 | S10: =S9 -> 11733.221 | T10: =T9 -> 6124.5564 | U10: 3283.7846
A11: 450 | B11: 648.31132 | C11: =$C$2 -> 842.03715 | D11: =$D$2 -> 1534.3206 | E11: =$E$2 -> 2380.4448 | F11: =$F$2 -> 1392.1344 | G11: =(B11-C11)/($N$3-$N$2) -> 88.865057 | H11: =(B11-D11)/($N$4-$N$2) -> 2701.2478 | I11: =(B11-E11)/($N$5-$N$2) -> -17321.335 | J11: =(B11-F11)/($N$6-$N$2) -> 813.81085 | K11: 948.21018 | P11: 1899.6559 | Q11: =Q10 -> 3002.7523 | R11: =R10 -> 6931.4634 | S11: =S10 -> 11733.221 | T11: =T10 -> 6124.5564 | U11: 3605.2846
A12: 500 | B12: 674.65483 | C12: =$C$2 -> 842.03715 | D12: =$D$2 -> 1534.3206 | E12: =$E$2 -> 2380.4448 | F12: =$F$2 -> 1392.1344 | G12: =(B12-C12)/($N$3-$N$2) -> 76.780883 | H12: =(B12-D12)/($N$4-$N$2) -> 2620.9323 | I12: =(B12-E12)/($N$5-$N$2) -> -17057.9 | J12: =(B12-F12)/($N$6-$N$2) -> 784.98864 | K12: 1004.8621 | P12: 2044.019 | Q12: =Q11 -> 3002.7523 | R12: =R11 -> 6931.4634 | S12: =S11 -> 11733.221 | T12: =T11 -> 6124.5564 | U12: 3926.7846
A13: 550 | B13: 700.99833 | C13: =$C$2 -> 842.03715 | D13: =$D$2 -> 1534.3206 | E13: =$E$2 -> 2380.4448 | F13: =$F$2 -> 1392.1344 | G13: =(B13-C13)/($N$3-$N$2) -> 64.696708 | H13: =(B13-D13)/($N$4-$N$2) -> 2540.6167 | I13: =(B13-E13)/($N$5-$N$2) -> -16794.465 | J13: =(B13-F13)/($N$6-$N$2) -> 756.16643 | K13: 1061.5141 | P13: 2188.3822 | Q13: =Q12 -> 3002.7523 | R13: =R12 -> 6931.4634 | S13: =S12 -> 11733.221 | T13: =T12 -> 6124.5564 | U13: 4248.2846
A14: 600 | B14: 727.34183 | C14: =$C$2 -> 842.03715 | D14: =$D$2 -> 1534.3206 | E14: =$E$2 -> 2380.4448 | F14: =$F$2 -> 1392.1344 | G14: =(B14-C14)/($N$3-$N$2) -> 52.612534 | H14: =(B14-D14)/($N$4-$N$2) -> 2460.3012 | I14: =(B14-E14)/($N$5-$N$2) -> -16531.03 | J14: =(B14-F14)/($N$6-$N$2) -> 727.34422 | K14: 1118.166 | P14: 2332.7453 | Q14: =Q13 -> 3002.7523 | R14: =R13 -> 6931.4634 | S14: =S13 -> 11733.221 | T14: =T13 -> 6124.5564 | U14: 4569.7846
A15: 650 | B15: 753.68533 | C15: =$C$2 -> 842.03715 | D15: =$D$2 -> 1534.3206 | E15: =$E$2 -> 2380.4448 | F15: =$F$2 -> 1392.1344 | G15: =(B15-C15)/($N$3-$N$2) -> 40.528359 | H15: =(B15-D15)/($N$4-$N$2) -> 2379.9856 | I15: =(B15-E15)/($N$5-$N$2) -> -16267.595 | J15: =(B15-F15)/($N$6-$N$2) -> 698.52201 | K15: 1174.818 | P15: 2477.1084 | Q15: =Q14 -> 3002.7523 | R15: =R14 -> 6931.4634 | S15: =S14 -> 11733.221 | T15: =T14 -> 6124.5564 | U15: 4891.2846
A16: 700 | B16: 780.02883 | C16: =$C$2 -> 842.03715 | D16: =$D$2 -> 1534.3206 | E16: =$E$2 -> 2380.4448 | F16: =$F$2 -> 1392.1344 | G16: =(B16-C16)/($N$3-$N$2) -> 28.444185 | H16: =(B16-D16)/($N$4-$N$2) -> 2299.6701 | I16: =(B16-E16)/($N$5-$N$2) -> -16004.16 | J16: =(B16-F16)/($N$6-$N$2) -> 669.6998 | K16: 1231.4699 | P16: 2621.4716 | Q16: =Q15 -> 3002.7523 | R16: =R15 -> 6931.4634 | S16: =S15 -> 11733.221 | T16: =T15 -> 6124.5564 | U16: 5212.7846
A17: 750 | B17: 806.37233 | C17: =$C$2 -> 842.03715 | D17: =$D$2 -> 1534.3206 | E17: =$E$2 -> 2380.4448 | F17: =$F$2 -> 1392.1344 | G17: =(B17-C17)/($N$3-$N$2) -> 16.36001 | H17: =(B17-D17)/($N$4-$N$2) -> 2219.3545 | I17: =(B17-E17)/($N$5-$N$2) -> -15740.725 | J17: =(B17-F17)/($N$6-$N$2) -> 640.87759 | K17: 1288.1219 | P17: 2765.8347 | Q17: =Q16 -> 3002.7523 | R17: =R16 -> 6931.4634 | S17: =S16 -> 11733.221 | T17: =T16 -> 6124.5564 | U17: 5534.2846
A18: 800 | B18: 832.71583 | C18: =$C$2 -> 842.03715 | D18: =$D$2 -> 1534.3206 | E18: =$E$2 -> 2380.4448 | F18: =$F$2 -> 1392.1344 | G18: =(B18-C18)/($N$3-$N$2) -> 4.275836 | H18: =(B18-D18)/($N$4-$N$2) -> 2139.039 | I18: =(B18-E18)/($N$5-$N$2) -> -15477.29 | J18: =(B18-F18)/($N$6-$N$2) -> 612.05538 | K18: 1344.7738 | P18: 2910.1978 | Q18: =Q17 -> 3002.7523 | R18: =R17 -> 6931.4634 | S18: =S17 -> 11733.221 | T18: =T17 -> 6124.5564 | U18: 5855.7846
A19: 850 | B19: 859.05933 | C19: =$C$2 -> 842.03715 | D19: =$D$2 -> 1534.3206 | E19: =$E$2 -> 2380.4448 | F19: =$F$2 -> 1392.1344 | G19: =(B19-C19)/($N$3-$N$2) -> -7.8083385 | H19: =(B19-D19)/($N$4-$N$2) -> 2058.7234 | I19: =(B19-E19)/($N$5-$N$2) -> -15213.855 | J19: =(B19-F19)/($N$6-$N$2) -> 583.23317 | K19: 1401.4258 | P19: 3054.561 | Q19: =Q18 -> 3002.7523 | R19: =R18 -> 6931.4634 | S19: =S18 -> 11733.221 | T19: =T18 -> 6124.5564 | U19: 6177.2846
... A102: 5000 | B102: 3045.5699 | C102: =$C$2 -> 842.03715 | D102: =$D$2 -> 1534.3206 | E102: =$E$2 -> 2380.4448 | F102: =$F$2 -> 1392.1344 | G102: =(B102-C102)/($N$3-$N$2) -> -1010.7948 | H102: =(B102-D102)/($N$4-$N$2) -> -4607.4672 | I102: =(B102-E102)/($N$5-$N$2) -> 6651.2501 | J102: =(B102-F102)/($N$6-$N$2) -> -1809.0103 | K102: 6103.5373 | P102: 15036.701 | Q102: =Q101 -> 3002.7523 | R102: =R101 -> 6931.4634 | S102: =S101 -> 11733.221 | T102: =T101 -> 6124.5564 | U102: 32861.785

Sheet Ammonia high low
A1: NG price | B1: BAU price | C1: Wind low | D1: Wind high | E1: Solar low | F1: Solar high | G1: Nuclear low | H1: Nuclear high | I1: CO2 Wind low | J1: CO2 Wind high | K1: CO2 Solar low | L1: CO2 Solar high | M1: CO2 Nuclear low | N1: CO2 Nuclear high | P1: Process | Q1: GWP | S1: H2 Wind low | T1: H2 Wind high | U1: H2 Solar low | V1: H2 Solar high | W1: H2 Nuclear low | X1: H2 Nuclear high
A2: 0 | B2: 411.21982 | C2: 1142.7259 | D2: 2834.9744 | E2: 1091.4457 | F2: 4345.411 | G2: 1079.7911 | H2: 1713.8015 | I2: =(B2-C2)/($Q$4-$Q$2) -> 2230.2015 | J2: =(B2-D2)/($Q$4-$Q$2) -> 7389.4956 | K2: =(B2-E2)/($Q$5-$Q$2) -> -6802.2585 | L2: =(B2-F2)/($Q$5-$Q$2) -> -39341.912 | M2: =(B2-G2)/($Q$6-$Q$2) -> 731.47839 | N2: =(B2-H2)/($Q$6-$Q$2) -> 1425.1441 | P2: BAU | Q2: 1.04 | S2: 4709.1621 | T2: 14312.678 | U2: 4418.1465 | V2: 22884.412 | W2: 4352.0066 | X2: 7950.0181
A3: 50 | B3: 437.56332 | C3: =$C$2 -> 1142.7259 | D3: =$D$2 -> 2834.9744 | E3: =$E$2 -> 1091.4457 | F3: =$F$2 -> 4345.411 | G3: =$G$2 -> 1079.7911 | H3: =$H$2 -> 1713.8015 | I3: =(B3-C3)/($Q$4-$Q$2) -> 2149.886 | J3: =(B3-D3)/($Q$4-$Q$2) -> 7309.1801 | K3: =(B3-E3)/($Q$5-$Q$2) -> -6538.8235 | L3: =(B3-F3)/($Q$5-$Q$2) -> -39078.477 | M3: =(B3-G3)/($Q$6-$Q$2) -> 702.65617 | N3: =(B3-H3)/($Q$6-$Q$2) -> 1396.3219 | P3: Biomass | Q3: -1.14 | S3: =S2 -> 4709.1621 | T3: =T2 -> 14312.678 | U3: =U2 -> 4418.1465 | V3: =V2 -> 22884.412 | W3: =W2 -> 4352.0066 | X3: =X2 -> 7950.0181
A4: 100 | B4: 463.90682 | C4: =$C$2 -> 1142.7259 | D4: =$D$2 -> 2834.9744 | E4: =$E$2 -> 1091.4457 | F4: =$F$2 -> 4345.411 | G4: =$G$2 -> 1079.7911 | H4: =$H$2 -> 1713.8015 | I4: =(B4-C4)/($Q$4-$Q$2) -> 2069.5704 | J4: =(B4-D4)/($Q$4-$Q$2) -> 7228.8645 | K4: =(B4-E4)/($Q$5-$Q$2) -> -6275.3885 | L4: =(B4-F4)/($Q$5-$Q$2) -> -38815.042 | M4: =(B4-G4)/($Q$6-$Q$2) -> 673.83396 | N4: =(B4-H4)/($Q$6-$Q$2) -> 1367.4997 | P4: Wind | Q4: 0.712 | S4: =S3 -> 4709.1621 | T4: =T3 -> 14312.678 | U4: =U3 -> 4418.1465 | V4: =V3 -> 22884.412 | W4: =W3 -> 4352.0066 | X4: =X3 -> 7950.0181
A5: 150 | B5: 490.25032 | C5: =$C$2 -> 1142.7259 | D5: =$D$2 -> 2834.9744 | E5: =$E$2 -> 1091.4457 | F5: =$F$2 -> 4345.411 | G5: =$G$2 -> 1079.7911 | H5: =$H$2 -> 1713.8015 | I5: =(B5-C5)/($Q$4-$Q$2) -> 1989.2549 | J5: =(B5-D5)/($Q$4-$Q$2) -> 7148.549 | K5: =(B5-E5)/($Q$5-$Q$2) -> -6011.9535 | L5: =(B5-F5)/($Q$5-$Q$2) -> -38551.607 | M5: =(B5-G5)/($Q$6-$Q$2) -> 645.01175 | N5: =(B5-H5)/($Q$6-$Q$2) -> 1338.6774 | P5: Solar | Q5: 1.14 | S5: =S4 -> 4709.1621 | T5: =T4 -> 14312.678 | U5: =U4 -> 4418.1465 | V5: =V4 -> 22884.412 | W5: =W4 -> 4352.0066 | X5: =X4 -> 7950.0181
A6: 200 | B6: 516.59382 | C6: =$C$2 -> 1142.7259 | D6: =$D$2 -> 2834.9744 | E6: =$E$2 -> 1091.4457 | F6: =$F$2 -> 4345.411 | G6: =$G$2 -> 1079.7911 | H6: =$H$2 -> 1713.8015 | I6: =(B6-C6)/($Q$4-$Q$2) -> 1908.9393 | J6: =(B6-D6)/($Q$4-$Q$2) -> 7068.2334 | K6: =(B6-E6)/($Q$5-$Q$2) -> -5748.5185 | L6: =(B6-F6)/($Q$5-$Q$2) -> -38288.172 | M6: =(B6-G6)/($Q$6-$Q$2) -> 616.18954 | N6: =(B6-H6)/($Q$6-$Q$2) -> 1309.8552 | P6: Nuclear | Q6: 0.126 | S6: =S5 -> 4709.1621 | T6: =T5 -> 14312.678 | U6: =U5 -> 4418.1465 | V6: =V5 -> 22884.412 | W6: =W5 -> 4352.0066 | X6: =X5 -> 7950.0181
A7: 250 | B7: 542.93732 | C7: =$C$2 -> 1142.7259 | D7: =$D$2 -> 2834.9744 | E7: =$E$2 -> 1091.4457 | F7: =$F$2 -> 4345.411 | G7: =$G$2 -> 1079.7911 | H7: =$H$2 -> 1713.8015 | I7: =(B7-C7)/($Q$4-$Q$2) -> 1828.6238 | J7: =(B7-D7)/($Q$4-$Q$2) -> 6987.9179 | K7: =(B7-E7)/($Q$5-$Q$2) -> -5485.0835 | L7: =(B7-F7)/($Q$5-$Q$2) -> -38024.737 | M7: =(B7-G7)/($Q$6-$Q$2) -> 587.36733 | N7: =(B7-H7)/($Q$6-$Q$2) -> 1281.033 | P7: Coal | S7: =S6 -> 4709.1621 | T7: =T6 -> 14312.678 | U7: =U6 -> 4418.1465 | V7: =V6 -> 22884.412 | W7: =W6 -> 4352.0066 | X7: =X6 -> 7950.0181
A8: 300 | B8: 569.28082 | C8: =$C$2 -> 1142.7259 | D8: =$D$2 -> 2834.9744 | E8: =$E$2 -> 1091.4457 | F8: =$F$2 -> 4345.411 | G8: =$G$2 -> 1079.7911 | H8: =$H$2 -> 1713.8015 | I8: =(B8-C8)/($Q$4-$Q$2) -> 1748.3082 | J8: =(B8-D8)/($Q$4-$Q$2) -> 6907.6023 | K8: =(B8-E8)/($Q$5-$Q$2) -> -5221.6485 | L8: =(B8-F8)/($Q$5-$Q$2) -> -37761.302 | M8: =(B8-G8)/($Q$6-$Q$2) -> 558.54512 | N8: =(B8-H8)/($Q$6-$Q$2) -> 1252.2108 | S8: =S7 -> 4709.1621 | T8: =T7 -> 14312.678 | U8: =U7 -> 4418.1465 | V8: =V7 -> 22884.412 | W8: =W7 -> 4352.0066 | X8: =X7 -> 7950.0181
A9: 350 | B9: 595.62432 | C9: =$C$2 -> 1142.7259 | D9: =$D$2 -> 2834.9744 | E9: =$E$2 -> 1091.4457 | F9: =$F$2 -> 4345.411 | G9: =$G$2 -> 1079.7911 | H9: =$H$2 -> 1713.8015 | I9: =(B9-C9)/($Q$4-$Q$2) -> 1667.9927 | J9: =(B9-D9)/($Q$4-$Q$2) -> 6827.2868 | K9: =(B9-E9)/($Q$5-$Q$2) -> -4958.2135 | L9: =(B9-F9)/($Q$5-$Q$2) -> -37497.867 | M9: =(B9-G9)/($Q$6-$Q$2) -> 529.72291 | N9: =(B9-H9)/($Q$6-$Q$2) -> 1223.3886 | S9: =S8 -> 4709.1621 | T9: =T8 -> 14312.678 | U9: =U8 -> 4418.1465 | V9: =V8 -> 22884.412 | W9: =W8 -> 4352.0066 | X9: =X8 -> 7950.0181
A10: 400 | B10: 621.96782 | C10: =$C$2 -> 1142.7259 | D10: =$D$2 -> 2834.9744 | E10: =$E$2 -> 1091.4457 | F10: =$F$2 -> 4345.411 | G10: =$G$2 -> 1079.7911 | H10: =$H$2 -> 1713.8015 | I10: =(B10-C10)/($Q$4-$Q$2) -> 1587.6771 | J10: =(B10-D10)/($Q$4-$Q$2) -> 6746.9712 | K10: =(B10-E10)/($Q$5-$Q$2) -> -4694.7785 | L10: =(B10-F10)/($Q$5-$Q$2) -> -37234.432 | M10: =(B10-G10)/($Q$6-$Q$2) -> 500.9007 | N10: =(B10-H10)/($Q$6-$Q$2) -> 1194.5664 | S10: =S9 -> 4709.1621 | T10: =T9 -> 14312.678 | U10: =U9 -> 4418.1465 | V10: =V9 -> 22884.412 | W10: =W9 -> 4352.0066 | X10: =X9 -> 7950.0181
A11: 450 | B11: 648.31132 | C11: =$C$2 -> 1142.7259 | D11: =$D$2 -> 2834.9744 | E11: =$E$2 -> 1091.4457 | F11: =$F$2 -> 4345.411 | G11: =$G$2 -> 1079.7911 | H11: =$H$2 -> 1713.8015 | I11: =(B11-C11)/($Q$4-$Q$2) -> 1507.3616 | J11: =(B11-D11)/($Q$4-$Q$2) -> 6666.6557 | K11: =(B11-E11)/($Q$5-$Q$2) -> -4431.3434 | L11: =(B11-F11)/($Q$5-$Q$2) -> -36970.997 | M11: =(B11-G11)/($Q$6-$Q$2) -> 472.07849 | N11: =(B11-H11)/($Q$6-$Q$2) -> 1165.7442 | S11: =S10 -> 4709.1621 | T11: =T10 -> 14312.678 | U11: =U10 -> 4418.1465 | V11: =V10 -> 22884.412 | W11: =W10 -> 4352.0066 | X11: =X10 -> 7950.0181
A12: 500 | B12: 674.65483 | C12: =$C$2 -> 1142.7259 | D12: =$D$2 -> 2834.9744 | E12: =$E$2 -> 1091.4457 | F12: =$F$2 -> 4345.411 | G12: =$G$2 -> 1079.7911 | H12: =$H$2 -> 1713.8015 | I12: =(B12-C12)/($Q$4-$Q$2) -> 1427.046 | J12: =(B12-D12)/($Q$4-$Q$2) -> 6586.3401 | K12: =(B12-E12)/($Q$5-$Q$2) -> -4167.9084 | L12: =(B12-F12)/($Q$5-$Q$2) -> -36707.562 | M12: =(B12-G12)/($Q$6-$Q$2) -> 443.25628 | N12: =(B12-H12)/($Q$6-$Q$2) -> 1136.922 | S12: =S11 -> 4709.1621 | T12: =T11 -> 14312.678 | U12: =U11 -> 4418.1465 | V12: =V11 -> 22884.412 | W12: =W11 -> 4352.0066 | X12: =X11 -> 7950.0181
A13: 550 | B13: 700.99833 | C13: =$C$2 -> 1142.7259 | D13: =$D$2 -> 2834.9744 | E13: =$E$2 -> 1091.4457 | F13: =$F$2 -> 4345.411 | G13: =$G$2 -> 1079.7911 | H13: =$H$2 -> 1713.8015 | I13: =(B13-C13)/($Q$4-$Q$2) -> 1346.7305 | J13: =(B13-D13)/($Q$4-$Q$2) -> 6506.0246 | K13: =(B13-E13)/($Q$5-$Q$2) -> -3904.4734 | L13: =(B13-F13)/($Q$5-$Q$2) -> -36444.127 | M13: =(B13-G13)/($Q$6-$Q$2) -> 414.43407 | N13: =(B13-H13)/($Q$6-$Q$2) -> 1108.0998 | S13: =S12 -> 4709.1621 | T13: =T12 -> 14312.678 | U13: =U12 -> 4418.1465 | V13: =V12 -> 22884.412 | W13: =W12 -> 4352.0066 | X13: =X12 -> 7950.0181
A14: 600 | B14: 727.34183 | C14: =$C$2 -> 1142.7259 | D14: =$D$2 -> 2834.9744 | E14: =$E$2 -> 1091.4457 | F14: =$F$2 -> 4345.411 | G14: =$G$2 -> 1079.7911 | H14: =$H$2 -> 1713.8015 | I14: =(B14-C14)/($Q$4-$Q$2) -> 1266.4149 | J14: =(B14-D14)/($Q$4-$Q$2) -> 6425.709 | K14: =(B14-E14)/($Q$5-$Q$2) -> -3641.0384 | L14: =(B14-F14)/($Q$5-$Q$2) -> -36180.692 | M14: =(B14-G14)/($Q$6-$Q$2) -> 385.61186 | N14: =(B14-H14)/($Q$6-$Q$2) -> 1079.2776 | S14: =S13 -> 4709.1621 | T14: =T13 -> 14312.678 | U14: =U13 -> 4418.1465 | V14: =V13 -> 22884.412 | W14: =W13 -> 4352.0066 | X14: =X13 -> 7950.0181
A15: 650 | B15: 753.68533 | C15: =$C$2 -> 1142.7259 | D15: =$D$2 -> 2834.9744 | E15: =$E$2 -> 1091.4457 | F15: =$F$2 -> 4345.411 | G15: =$G$2 -> 1079.7911 | H15: =$H$2 -> 1713.8015 | I15: =(B15-C15)/($Q$4-$Q$2) -> 1186.0994 | J15: =(B15-D15)/($Q$4-$Q$2) -> 6345.3935 | K15: =(B15-E15)/($Q$5-$Q$2) -> -3377.6034 | L15: =(B15-F15)/($Q$5-$Q$2) -> -35917.257 | M15: =(B15-G15)/($Q$6-$Q$2) -> 356.78965 | N15: =(B15-H15)/($Q$6-$Q$2) -> 1050.4553 | S15: =S14 -> 4709.1621 | T15: =T14 -> 14312.678 | U15: =U14 -> 4418.1465 | V15: =V14 -> 22884.412 | W15: =W14 -> 4352.0066 | X15: =X14 -> 7950.0181
A16: 700 | B16: 780.02883 | C16: =$C$2 -> 1142.7259 | D16: =$D$2 -> 2834.9744 | E16: =$E$2 -> 1091.4457 | F16: =$F$2 -> 4345.411 | G16: =$G$2 -> 1079.7911 | H16: =$H$2 -> 1713.8015 | I16: =(B16-C16)/($Q$4-$Q$2) -> 1105.7838 | J16: =(B16-D16)/($Q$4-$Q$2) -> 6265.0779 | K16: =(B16-E16)/($Q$5-$Q$2) -> -3114.1684 | L16: =(B16-F16)/($Q$5-$Q$2) -> -35653.822 | M16: =(B16-G16)/($Q$6-$Q$2) -> 327.96744 | N16: =(B16-H16)/($Q$6-$Q$2) -> 1021.6331 | S16: =S15 -> 4709.1621 | T16: =T15 -> 14312.678 | U16: =U15 -> 4418.1465 | V16: =V15 -> 22884.412 | W16: =W15 -> 4352.0066 | X16: =X15 -> 7950.0181
A17: 750 | B17: 806.37233 | C17: =$C$2 -> 1142.7259 | D17: =$D$2 -> 2834.9744 | E17: =$E$2 -> 1091.4457 | F17: =$F$2 -> 4345.411 | G17: =$G$2 -> 1079.7911 | H17: =$H$2 -> 1713.8015 | I17: =(B17-C17)/($Q$4-$Q$2) -> 1025.4683 | J17: =(B17-D17)/($Q$4-$Q$2) -> 6184.7624 | K17: =(B17-E17)/($Q$5-$Q$2) -> -2850.7334 | L17: =(B17-F17)/($Q$5-$Q$2) -> -35390.387 | M17: =(B17-G17)/($Q$6-$Q$2) -> 299.14523 | N17: =(B17-H17)/($Q$6-$Q$2) -> 992.81092 | S17: =S16 -> 4709.1621 | T17: =T16 -> 14312.678 | U17: =U16 -> 4418.1465 | V17: =V16 -> 22884.412 | W17: =W16 -> 4352.0066 | X17: =X16 -> 7950.0181
A18: 800 | B18: 832.71583 | C18: =$C$2 -> 1142.7259 | D18: =$D$2 -> 2834.9744 | E18: =$E$2 -> 1091.4457 | F18: =$F$2 -> 4345.411 | G18: =$G$2 -> 1079.7911 | H18: =$H$2 -> 1713.8015 | I18: =(B18-C18)/($Q$4-$Q$2) -> 945.15274 | J18: =(B18-D18)/($Q$4-$Q$2) -> 6104.4468 | K18: =(B18-E18)/($Q$5-$Q$2) -> -2587.2984 | L18: =(B18-F18)/($Q$5-$Q$2) -> -35126.952 | M18: =(B18-G18)/($Q$6-$Q$2) -> 270.32302 | N18: =(B18-H18)/($Q$6-$Q$2) -> 963.98871 | S18: =S17 -> 4709.1621 | T18: =T17 -> 14312.678 | U18: =U17 -> 4418.1465 | V18: =V17 -> 22884.412 | W18: =W17 -> 4352.0066 | X18: =X17 -> 7950.0181
A19: 850 | B19: 859.05933 | C19: =$C$2 -> 1142.7259 | D19: =$D$2 -> 2834.9744 | E19: =$E$2 -> 1091.4457 | F19: =$F$2 -> 4345.411 | G19: =$G$2 -> 1079.7911 | H19: =$H$2 -> 1713.8015 | I19: =(B19-C19)/($Q$4-$Q$2) -> 864.83719 | J19: =(B19-D19)/($Q$4-$Q$2) -> 6024.1313 | K19: =(B19-E19)/($Q$5-$Q$2) -> -2323.8634 | L19: =(B19-F19)/($Q$5-$Q$2) -> -34863.517 | M19: =(B19-G19)/($Q$6-$Q$2) -> 241.50081 | N19: =(B19-H19)/($Q$6-$Q$2) -> 935.1665 | S19: =S18 -> 4709.1621 | T19: =T18 -> 14312.678 | U19: =U18 -> 4418.1465 | V19: =V18 -> 22884.412 | W19: =W18 -> 4352.0066 | X19: =X18 -> 7950.0181
... A102: 5000 | B102: 3045.5699 | C102: =$C$2 -> 1142.7259 | D102: =$D$2 -> 2834.9744 | E102: =$E$2 -> 1091.4457 | F102: =$F$2 -> 4345.411 | G102: =$G$2 -> 1079.7911 | H102: =$H$2 -> 1713.8015 | I102: =(B102-C102)/($Q$4-$Q$2) -> -5801.3534 | J102: =(B102-D102)/($Q$4-$Q$2) -> -642.05935 | K102: =(B102-E102)/($Q$5-$Q$2) -> 19541.242 | L102: =(B102-F102)/($Q$5-$Q$2) -> -12998.412 | M102: =(B102-G102)/($Q$6-$Q$2) -> -2150.7427 | N102: =(B102-H102)/($Q$6-$Q$2) -> -1457.077 | S102: =S101 -> 4709.1621 | T102: =T101 -> 14312.678 | U102: =U101 -> 4418.1465 | V102: =V101 -> 22884.412 | W102: =W101 -> 4352.0066 | X102: =X101 -> 7950.0181

Sheet Methanol
A1: NG price | B1: BAU | C1: DAC + wind | D1: DAC + solar | E1: DAC + nuclear | F1: CO2 DAC + wind | G1: CO2 DAC + solar | H1: CO2 DAC + nuclear | I1: Coal | K1: Process | L1: GWP | N1: H2 BAU | O1: H2 Wind | P1: H2 Solar | Q1: H2 Nuclear
A2: 0 | B2: 200.1 | C2: 1598.4522 | D2: 2520.3898 | E2: 1443.5261 | F2: 1467.7566 | G2: =(B2-D2)/($L$4-$L$2) -> 5371.0412 | H2: =(B2-E2)/($L$5-$L$2) -> 925.16823 | I2: 142.39781 | K2: BAU | L2: 0.658 | N2: =Ammonia!P2 -> 600.38772 | O2: =Ammonia!R2 -> 6931.4634 | P2: =Ammonia!S2 -> 11733.221 | Q2: =Ammonia!T2 -> 6124.5564
A3: 50 | B3: 235.13185 | C3: 1606.5365 | D3: 2528.474 | E3: 1451.6103 | F3: 1458.4371 | G3: =(B3-D3)/($L$4-$L$2) -> 5308.6625 | H3: =(B3-E3)/($L$5-$L$2) -> 905.11793 | I3: 237.77533 | K3: DAC + wind | L3: -0.556 | N3: =Ammonia!P3 -> 744.75085 | O3: =Ammonia!R3 -> 6931.4634 | P3: =Ammonia!S3 -> 11733.221 | Q3: =Ammonia!T3 -> 6124.5564
A4: 100 | B4: 270.16369 | C4: 1614.6207 | D4: 2536.5583 | E4: 1459.6946 | F4: 1452.4409 | G4: =(B4-D4)/($L$4-$L$2) -> 5246.2837 | H4: =(B4-E4)/($L$5-$L$2) -> 885.06763 | I4: 333.15284 | K4: DAC + solar | L4: 0.226 | N4: =Ammonia!P4 -> 889.11398 | O4: =Ammonia!R4 -> 6931.4634 | P4: =Ammonia!S4 -> 11733.221 | Q4: =Ammonia!T4 -> 6124.5564
A5: 150 | B5: 305.19554 | C5: 1622.705 | D5: 2544.6425 | E5: 1467.7788 | F5: 1450.5626 | G5: =(B5-D5)/($L$4-$L$2) -> 5183.905 | H5: =(B5-E5)/($L$5-$L$2) -> 865.01733 | I5: 428.53036 | K5: DAC + nuclear | L5: -0.686 | N5: =Ammonia!P5 -> 1033.4771 | O5: =Ammonia!R5 -> 6931.4634 | P5: =Ammonia!S5 -> 11733.221 | Q5: =Ammonia!T5 -> 6124.5564
A6: 200 | B6: 340.22739 | C6: 1630.7892 | D6: 2552.7268 | E6: 1475.8631 | F6: 1446.3724 | G6: =(B6-D6)/($L$4-$L$2) -> 5121.5263 | H6: =(B6-E6)/($L$5-$L$2) -> 844.96703 | I6: 523.90788 | N6: =Ammonia!P6 -> 1177.8402 | O6: =Ammonia!R6 -> 6931.4634 | P6: =Ammonia!S6 -> 11733.221 | Q6: =Ammonia!T6 -> 6124.5564
A7: 250 | B7: 375.25924 | C7: 1638.8735 | D7: 2560.811 | E7: 1483.9473 | F7: 1440.9541 | G7: =(B7-D7)/($L$4-$L$2) -> 5059.1476 | H7: =(B7-E7)/($L$5-$L$2) -> 824.91674 | I7: 619.2854 | N7: =Ammonia!P7 -> 1322.2034 | O7: =Ammonia!R7 -> 6931.4634 | P7: =Ammonia!S7 -> 11733.221 | Q7: =Ammonia!T7 -> 6124.5564
A8: 300 | B8: 410.29108 | C8: 1646.9577 | D8: 2568.8953 | E8: 1492.0316 | F8: 1441.1709 | G8: =(B8-D8)/($L$4-$L$2) -> 4996.7689 | H8: =(B8-E8)/($L$5-$L$2) -> 804.86644 | I8: 714.66291 | N8: =Ammonia!P8 -> 1466.5665 | O8: =Ammonia!R8 -> 6931.4634 | P8: =Ammonia!S8 -> 11733.221 | Q8: =Ammonia!T8 -> 6124.5564
A9: 350 | B9: 445.32293 | C9: 1655.042 | D9: 2576.9795 | E9: 1500.1158 | F9: 1441.6043 | G9: =(B9-D9)/($L$4-$L$2) -> 4934.3902 | H9: =(B9-E9)/($L$5-$L$2) -> 784.81614 | I9: 810.04043 | N9: =Ammonia!P9 -> 1610.9296 | O9: =Ammonia!R9 -> 6931.4634 | P9: =Ammonia!S9 -> 11733.221 | Q9: =Ammonia!T9 -> 6124.5564
A10: 400 | B10: 480.35478 | C10: 1663.1262 | D10: 2585.0638 | E10: 1508.2001 | F10: 1445.4333 | G10: =(B10-D10)/($L$4-$L$2) -> 4872.0115 | H10: =(B10-E10)/($L$5-$L$2) -> 764.76584 | I10: 905.41795 | N10: =Ammonia!P10 -> 1755.2928 | O10: =Ammonia!R10 -> 6931.4634 | P10: =Ammonia!S10 -> 11733.221 | Q10: =Ammonia!T10 -> 6124.5564
A11: 450 | B11: 515.38662 | C11: 1671.2105 | D11: 2593.148 | E11: 1516.2843 | F11: 1451.574 | G11: =(B11-D11)/($L$4-$L$2) -> 4809.6328 | H11: =(B11-E11)/($L$5-$L$2) -> 744.71554 | I11: 1000.7955 | N11: =Ammonia!P11 -> 1899.6559 | O11: =Ammonia!R11 -> 6931.4634 | P11: =Ammonia!S11 -> 11733.221 | Q11: =Ammonia!T11 -> 6124.5564
A12: 500 | B12: 550.41847 | C12: 1679.2947 | D12: 2601.2322 | E12: 1524.3686 | F12: 1452.2242 | G12: =(B12-D12)/($L$4-$L$2) -> 4747.2541 | H12: =(B12-E12)/($L$5-$L$2) -> 724.66524 | I12: 1096.173 | N12: =Ammonia!P12 -> 2044.019 | O12: =Ammonia!R12 -> 6931.4634 | P12: =Ammonia!S12 -> 11733.221 | Q12: =Ammonia!T12 -> 6124.5564
A13: 550 | B13: 585.45032 | C13: 1687.3789 | D13: 2609.3165 | E13: 1532.4528 | F13: 1448.3952 | G13: =(B13-D13)/($L$4-$L$2) -> 4684.8754 | H13: =(B13-E13)/($L$5-$L$2) -> 704.61495 | I13: 1191.5505 | N13: =Ammonia!P13 -> 2188.3822 | O13: =Ammonia!R13 -> 6931.4634 | P13: =Ammonia!S13 -> 11733.221 | Q13: =Ammonia!T13 -> 6124.5564
A14: 600 | B14: 620.48217 | C14: 1695.4632 | D14: 2617.4007 | E14: 1540.5371 | F14: 1211.2895 | G14: =(B14-D14)/($L$4-$L$2) -> 4622.4967 | H14: =(B14-E14)/($L$5-$L$2) -> 684.56465 | I14: 1286.928 | N14: =Ammonia!P14 -> 2332.7453 | O14: =Ammonia!R14 -> 6931.4634 | P14: =Ammonia!S14 -> 11733.221 | Q14: =Ammonia!T14 -> 6124.5564
A15: 650 | B15: 655.51401 | C15: 1703.5474 | D15: 2625.485 | E15: 1548.6213 | F15: 1206.088 | G15: =(B15-D15)/($L$4-$L$2) -> 4560.118 | H15: =(B15-E15)/($L$5-$L$2) -> 664.51435 | I15: 1382.3055 | N15: =Ammonia!P15 -> 2477.1084 | O15: =Ammonia!R15 -> 6931.4634 | P15: =Ammonia!S15 -> 11733.221 | Q15: =Ammonia!T15 -> 6124.5564
A16: 700 | B16: 690.54586 | C16: 1711.6317 | D16: 2633.5692 | E16: 1556.7055 | F16: 1204.7154 | G16: =(B16-D16)/($L$4-$L$2) -> 4497.7393 | H16: =(B16-E16)/($L$5-$L$2) -> 644.46405 | I16: 1477.6831 | N16: =Ammonia!P16 -> 2621.4716 | O16: =Ammonia!R16 -> 6931.4634 | P16: =Ammonia!S16 -> 11733.221 | Q16: =Ammonia!T16 -> 6124.5564
A17: 750 | B17: 725.57771 | C17: 1719.7159 | D17: 2641.6535 | E17: 1564.7898 | F17: 1200.3807 | G17: =(B17-D17)/($L$4-$L$2) -> 4435.3606 | H17: =(B17-E17)/($L$5-$L$2) -> 624.41375 | I17: 1573.0606 | N17: =Ammonia!P17 -> 2765.8347 | O17: =Ammonia!R17 -> 6931.4634 | P17: =Ammonia!S17 -> 11733.221 | Q17: =Ammonia!T17 -> 6124.5564
... A46: 2200 | B46: 1741.5013 | C46: 1954.1591 | D46: 2876.0966 | E46: 1799.2329 | F46: 2022.0518 | G46: =(B46-D46)/($L$4-$L$2) -> 2626.3781 | H46: =(B46-E46)/($L$5-$L$2) -> 42.955101 | I46: 4339.0086 | N46: =Ammonia!P46 -> 6952.3655 | O46: =Ammonia!R46 -> 6931.4634 | P46: =Ammonia!S46 -> 11733.221 | Q46: =Ammonia!T46 -> 6124.5564
A47: 2250 | B47: 1776.5331 | C47: 1962.2433 | D47: 2884.1809 | E47: 1807.3172 | F47: =(B47-C47)/($L$3-$L$2) -> 152.9738 | G47: =(B47-D47)/($L$4-$L$2) -> 2563.9994 | H47: =(B47-E47)/($L$5-$L$2) -> 22.904803 | I47: 4434.3861 | N47: =Ammonia!P47 -> 7096.7286 | O47: =Ammonia!R47 -> 6931.4634 | P47: =Ammonia!S47 -> 11733.221 | Q47: =Ammonia!T47 -> 6124.5564
A48: 2300 | B48: 1811.565 | C48: 1970.3276 | D48: 2892.2651 | E48: 1815.4014 | F48: =(B48-C48)/($L$3-$L$2) -> 130.77644 | G48: =(B48-D48)/($L$4-$L$2) -> 2501.6207 | H48: =(B48-E48)/($L$5-$L$2) -> 2.8545044 | I48: 4529.7636 | N48: =Ammonia!P48 -> 7241.0918 | O48: =Ammonia!R48 -> 6931.4634 | P48: =Ammonia!S48 -> 11733.221 | Q48: =Ammonia!T48 -> 6124.5564
A49: 2350 | B49: 1846.5968 | C49: 1978.4118 | D49: 2900.3494 | E49: 1823.4857 | F49: =(B49-C49)/($L$3-$L$2) -> 108.57907 | G49: =(B49-D49)/($L$4-$L$2) -> 2439.242 | H49: =(B49-E49)/($L$5-$L$2) -> -17.195794 | I49: 4625.1411 | N49: =Ammonia!P49 -> 7385.4549 | O49: =Ammonia!R49 -> 6931.4634 | P49: =Ammonia!S49 -> 11733.221 | Q49: =Ammonia!T49 -> 6124.5564
A50: 2400 | B50: 1881.6287 | C50: 1986.4961 | D50: 2908.4336 | E50: 1831.5699 | F50: =(B50-C50)/($L$3-$L$2) -> 86.381709 | G50: =(B50-D50)/($L$4-$L$2) -> 2376.8633 | H50: =(B50-E50)/($L$5-$L$2) -> -37.246092 | I50: 4720.5186 | N50: =Ammonia!P50 -> 7529.818 | O50: =Ammonia!R50 -> 6931.4634 | P50: =Ammonia!S50 -> 11733.221 | Q50: =Ammonia!T50 -> 6124.5564
A51: 2450 | B51: 1916.6605 | C51: 1994.5803 | D51: 2916.5178 | E51: 1839.6542 | F51: =(B51-C51)/($L$3-$L$2) -> 64.184345 | G51: =(B51-D51)/($L$4-$L$2) -> 2314.4846 | H51: =(B51-E51)/($L$5-$L$2) -> -57.296391 | I51: 4815.8962 | N51: =Ammonia!P51 -> 7674.1811 | O51: =Ammonia!R51 -> 6931.4634 | P51: =Ammonia!S51 -> 11733.221 | Q51: =Ammonia!T51 -> 6124.5564
A52: 2500 | B52: 1951.6924 | C52: 2002.6645 | D52: 2924.6021 | E52: 1847.7384 | F52: =(B52-C52)/($L$3-$L$2) -> 41.98698 | G52: =(B52-D52)/($L$4-$L$2) -> 2252.1059 | H52: =(B52-E52)/($L$5-$L$2) -> -77.346689 | I52: 4911.2737 | N52: =Ammonia!P52 -> 7818.5443 | O52: =Ammonia!R52 -> 6931.4634 | P52: =Ammonia!S52 -> 11733.221 | Q52: =Ammonia!T52 -> 6124.5564
A53: 2550 | B53: 1986.7242 | C53: 2010.7488 | D53: 2932.6863 | E53: 1855.8227 | F53: =(B53-C53)/($L$3-$L$2) -> 19.789615 | G53: =(B53-D53)/($L$4-$L$2) -> 2189.7272 | H53: =(B53-E53)/($L$5-$L$2) -> -97.396987 | I53: 5006.6512 | N53: =Ammonia!P53 -> 7962.9074 | O53: =Ammonia!R53 -> 6931.4634 | P53: =Ammonia!S53 -> 11733.221 | Q53: =Ammonia!T53 -> 6124.5564
A54: 2600 | B54: 2021.7561 | C54: 2018.833 | D54: 2940.7706 | E54: 1863.9069 | F54: =(B54-C54)/($L$3-$L$2) -> -2.4077501 | G54: =(B54-D54)/($L$4-$L$2) -> 2127.3485 | H54: =(B54-E54)/($L$5-$L$2) -> -117.44729 | I54: 5102.0287 | N54: =Ammonia!P54 -> 8107.2705 | O54: =Ammonia!R54 -> 6931.4634 | P54: =Ammonia!S54 -> 11733.221 | Q54: =Ammonia!T54 -> 6124.5564
A55: 2650 | B55: 2056.7879 | C55: 2026.9173 | D55: 2948.8548 | E55: 1871.9911 | F55: =(B55-C55)/($L$3-$L$2) -> -24.605115 | G55: =(B55-D55)/($L$4-$L$2) -> 2064.9697 | H55: =(B55-E55)/($L$5-$L$2) -> -137.49758 | I55: 5197.4062 | N55: =Ammonia!P55 -> 8251.6337 | O55: =Ammonia!R55 -> 6931.4634 | P55: =Ammonia!S55 -> 11733.221 | Q55: =Ammonia!T55 -> 6124.5564
A56: 2700 | B56: 2091.8197 | C56: 2035.0015 | D56: 2956.9391 | E56: 1880.0754 | F56: =(B56-C56)/($L$3-$L$2) -> -46.80248 | G56: =(B56-D56)/($L$4-$L$2) -> 2002.591 | H56: =(B56-E56)/($L$5-$L$2) -> -157.54788 | I56: 5292.7838 | N56: =Ammonia!P56 -> 8395.9968 | O56: =Ammonia!R56 -> 6931.4634 | P56: =Ammonia!S56 -> 11733.221 | Q56: =Ammonia!T56 -> 6124.5564
A57: 2750 | B57: 2126.8516 | C57: 2043.0858 | D57: 2965.0233 | E57: 1888.1596 | F57: =(B57-C57)/($L$3-$L$2) -> -68.999845 | G57: =(B57-D57)/($L$4-$L$2) -> 1940.2123 | H57: =(B57-E57)/($L$5-$L$2) -> -177.59818 | I57: 5388.1613 | N57: =Ammonia!P57 -> 8540.3599 | O57: =Ammonia!R57 -> 6931.4634 | P57: =Ammonia!S57 -> 11733.221 | Q57: =Ammonia!T57 -> 6124.5564
A58: 2800 | B58: 2161.8834 | C58: 2051.17 | D58: 2973.1076 | E58: 1896.2439 | F58: =(B58-C58)/($L$3-$L$2) -> -91.19721 | G58: =(B58-D58)/($L$4-$L$2) -> 1877.8336 | H58: =(B58-E58)/($L$5-$L$2) -> -197.64848 | I58: 5483.5388 | N58: =Ammonia!P58 -> 8684.7231 | O58: =Ammonia!R58 -> 6931.4634 | P58: =Ammonia!S58 -> 11733.221 | Q58: =Ammonia!T58 -> 6124.5564
... A102: 5000 | B102: 3703.2847 | C102: 2406.8769 | D102: 3328.8144 | E102: 2251.9507 | F102: =(B102-C102)/($L$3-$L$2) -> -1067.8813 | G102: =(B102-D102)/($L$4-$L$2) -> -866.82943 | H102: =(B102-E102)/($L$5-$L$2) -> -1079.8616 | I102: 9680.1496 | N102: =Ammonia!P102 -> 15036.701 | O102: =Ammonia!R102 -> 6931.4634 | P102: =Ammonia!S102 -> 11733.221 | Q102: =Ammonia!T102 -> 6124.5564

Sheet Methanol high low
A1: NG price | B1: BAU | C1: DAC + wind low | D1: DAC + wind high | E1: DAC + solar low | F1: DAC + solar high | G1: DAC + nuclear low | H1: DAC + nuclear high | I1: CO2 DAC + wind low | J1: CO2 DAC + wind high | K1: CO2 DAC + solar low | L1: CO2 DAC + solar high | M1: CO2 DAC + nuclear low | N1: CO2 DAC + nuclear high | P1: Process | Q1: GWP | S1: H2 Wind low | T1: H2 Wind high | U1: H2 Solar low | V1: H2 Solar high | W1: H2 Nuclear low | X1: H2 Nuclear high
A2: 0 | B2: 200.1 | C2: 1033.8687 | D2: 3153.5472 | E2: 977.99367 | F2: 4799.32 | G2: 965.29481 | H2: 1931.9165 | I2: =(B2-C2)/($Q$3-$Q$2) -> 686.79463 | J2: =(B2-D2)/($Q$3-$Q$2) -> 2432.8231 | K2: =(B2-E2)/($Q$4-$Q$2) -> 1800.6798 | L2: =(B2-F2)/($Q$4-$Q$2) -> 10646.343 | M2: =(B2-G2)/($Q$5-$Q$2) -> 569.34138 | N2: =(B2-H2)/($Q$5-$Q$2) -> 1288.5539 | P2: BAU | Q2: 0.658 | S2: 4709.1621 | T2: 14312.678 | U2: 4418.1465 | V2: 22884.412 | W2: 4352.0066 | X2: 7950.0181
A3: 50 | B3: 235.13185 | C3: 1041.9529 | D3: 3161.6315 | E3: 986.07792 | F3: 4807.4043 | G3: 973.37905 | H3: 1940.0007 | I3: =(B3-C3)/($Q$3-$Q$2) -> 664.59726 | J3: =(B3-D3)/($Q$3-$Q$2) -> 2410.6257 | K3: =(B3-E3)/($Q$4-$Q$2) -> 1738.3011 | L3: =(B3-F3)/($Q$4-$Q$2) -> 10583.964 | M3: =(B3-G3)/($Q$5-$Q$2) -> 549.29108 | N3: =(B3-H3)/($Q$5-$Q$2) -> 1268.5036 | P3: DAC + wind | Q3: -0.556 | S3: 4709.1621 | T3: 14312.678 | U3: 4418.1465 | V3: 22884.412 | W3: 4352.0066 | X3: 7950.0181
A4: 100 | B4: 270.16369 | C4: 1050.0372 | D4: 3169.7157 | E4: 994.16217 | F4: 4815.4885 | G4: 981.4633 | H4: 1948.085 | I4: =(B4-C4)/($Q$3-$Q$2) -> 642.3999 | J4: =(B4-D4)/($Q$3-$Q$2) -> 2388.4283 | K4: =(B4-E4)/($Q$4-$Q$2) -> 1675.9224 | L4: =(B4-F4)/($Q$4-$Q$2) -> 10521.585 | M4: =(B4-G4)/($Q$5-$Q$2) -> 529.24078 | N4: =(B4-H4)/($Q$5-$Q$2) -> 1248.4533 | P4: DAC + solar | Q4: 0.226 | S4: 4709.1621 | T4: 14312.678 | U4: 4418.1465 | V4: 22884.412 | W4: 4352.0066 | X4: 7950.0181
A5: 150 | B5: 305.19554 | C5: 1058.1214 | D5: 3177.8 | E5: 1002.2464 | F5: 4823.5728 | G5: 989.54755 | H5: 1956.1692 | I5: =(B5-C5)/($Q$3-$Q$2) -> 620.20253 | J5: =(B5-D5)/($Q$3-$Q$2) -> 2366.231 | K5: =(B5-E5)/($Q$4-$Q$2) -> 1613.5437 | L5: =(B5-F5)/($Q$4-$Q$2) -> 10459.207 | M5: =(B5-G5)/($Q$5-$Q$2) -> 509.19048 | N5: =(B5-H5)/($Q$5-$Q$2) -> 1228.403 | P5: DAC + nuclear | Q5: -0.686 | S5: 4709.1621 | T5: 14312.678 | U5: 4418.1465 | V5: 22884.412 | W5: 4352.0066 | X5: 7950.0181
A6: 200 | B6: 340.22739 | C6: 1066.2057 | D6: 3185.8842 | E6: 1010.3307 | F6: 4831.657 | G6: 997.63179 | H6: 1964.2535 | I6: =(B6-C6)/($Q$3-$Q$2) -> 598.00517 | J6: =(B6-D6)/($Q$3-$Q$2) -> 2344.0336 | K6: =(B6-E6)/($Q$4-$Q$2) -> 1551.165 | L6: =(B6-F6)/($Q$4-$Q$2) -> 10396.828 | M6: =(B6-G6)/($Q$5-$Q$2) -> 489.14018 | N6: =(B6-H6)/($Q$5-$Q$2) -> 1208.3527 | S6: 4709.1621 | T6: 14312.678 | U6: 4418.1465 | V6: 22884.412 | W6: 4352.0066 | X6: 7950.0181
A7: 250 | B7: 375.25924 | C7: 1074.2899 | D7: 3193.9684 | E7: 1018.4149 | F7: 4839.7412 | G7: 1005.716 | H7: 1972.3377 | I7: =(B7-C7)/($Q$3-$Q$2) -> 575.8078 | J7: =(B7-D7)/($Q$3-$Q$2) -> 2321.8363 | K7: =(B7-E7)/($Q$4-$Q$2) -> 1488.7863 | L7: =(B7-F7)/($Q$4-$Q$2) -> 10334.449 | M7: =(B7-G7)/($Q$5-$Q$2) -> 469.08988 | N7: =(B7-H7)/($Q$5-$Q$2) -> 1188.3024 | S7: 4709.1621 | T7: 14312.678 | U7: 4418.1465 | V7: 22884.412 | W7: 4352.0066 | X7: 7950.0181
A8: 300 | B8: 410.29108 | C8: 1082.3742 | D8: 3202.0527 | E8: 1026.4992 | F8: 4847.8255 | G8: 1013.8003 | H8: 1980.422 | I8: =(B8-C8)/($Q$3-$Q$2) -> 553.61044 | J8: =(B8-D8)/($Q$3-$Q$2) -> 2299.6389 | K8: =(B8-E8)/($Q$4-$Q$2) -> 1426.4076 | L8: =(B8-F8)/($Q$4-$Q$2) -> 10272.07 | M8: =(B8-G8)/($Q$5-$Q$2) -> 449.03959 | N8: =(B8-H8)/($Q$5-$Q$2) -> 1168.2521 | S8: 4709.1621 | T8: 14312.678 | U8: 4418.1465 | V8: 22884.412 | W8: 4352.0066 | X8: 7950.0181
A9: 350 | B9: 445.32293 | C9: 1090.4584 | D9: 3210.1369 | E9: 1034.5834 | F9: 4855.9097 | G9: 1021.8845 | H9: 1988.5062 | I9: =(B9-C9)/($Q$3-$Q$2) -> 531.41307 | J9: =(B9-D9)/($Q$3-$Q$2) -> 2277.4415 | K9: =(B9-E9)/($Q$4-$Q$2) -> 1364.0289 | L9: =(B9-F9)/($Q$4-$Q$2) -> 10209.692 | M9: =(B9-G9)/($Q$5-$Q$2) -> 428.98929 | N9: =(B9-H9)/($Q$5-$Q$2) -> 1148.2018 | S9: 4709.1621 | T9: 14312.678 | U9: 4418.1465 | V9: 22884.412 | W9: 4352.0066 | X9: 7950.0181
A10: 400 | B10: 480.35478 | C10: 1098.5426 | D10: 3218.2212 | E10: 1042.6676 | F10: 4863.994 | G10: 1029.9688 | H10: 1996.5904 | I10: =(B10-C10)/($Q$3-$Q$2) -> 509.21571 | J10: =(B10-D10)/($Q$3-$Q$2) -> 2255.2442 | K10: =(B10-E10)/($Q$4-$Q$2) -> 1301.6502 | L10: =(B10-F10)/($Q$4-$Q$2) -> 10147.313 | M10: =(B10-G10)/($Q$5-$Q$2) -> 408.93899 | N10: =(B10-H10)/($Q$5-$Q$2) -> 1128.1515 | S10: 4709.1621 | T10: 14312.678 | U10: 4418.1465 | V10: 22884.412 | W10: 4352.0066 | X10: 7950.0181
A11: 450 | B11: 515.38662 | C11: 1106.6269 | D11: 3226.3054 | E11: 1050.7519 | F11: 4872.0782 | G11: 1038.053 | H11: 2004.6747 | I11: =(B11-C11)/($Q$3-$Q$2) -> 487.01834 | J11: =(B11-D11)/($Q$3-$Q$2) -> 2233.0468 | K11: =(B11-E11)/($Q$4-$Q$2) -> 1239.2714 | L11: =(B11-F11)/($Q$4-$Q$2) -> 10084.934 | M11: =(B11-G11)/($Q$5-$Q$2) -> 388.88869 | N11: =(B11-H11)/($Q$5-$Q$2) -> 1108.1012 | S11: 4709.1621 | T11: 14312.678 | U11: 4418.1465 | V11: 22884.412 | W11: 4352.0066 | X11: 7950.0181
A12: 500 | B12: 550.41847 | C12: 1114.7111 | D12: 3234.3897 | E12: 1058.8361 | F12: 4880.1625 | G12: 1046.1373 | H12: 2012.7589 | I12: =(B12-C12)/($Q$3-$Q$2) -> 464.82098 | J12: =(B12-D12)/($Q$3-$Q$2) -> 2210.8494 | K12: =(B12-E12)/($Q$4-$Q$2) -> 1176.8927 | L12: =(B12-F12)/($Q$4-$Q$2) -> 10022.556 | M12: =(B12-G12)/($Q$5-$Q$2) -> 368.83839 | N12: =(B12-H12)/($Q$5-$Q$2) -> 1088.0509 | S12: 4709.1621 | T12: 14312.678 | U12: 4418.1465 | V12: 22884.412 | W12: 4352.0066 | X12: 7950.0181
A13: 550 | B13: 585.45032 | C13: 1122.7954 | D13: 3242.4739 | E13: 1066.9204 | F13: 4888.2467 | G13: 1054.2215 | H13: 2020.8432 | I13: =(B13-C13)/($Q$3-$Q$2) -> 442.62361 | J13: =(B13-D13)/($Q$3-$Q$2) -> 2188.6521 | K13: =(B13-E13)/($Q$4-$Q$2) -> 1114.514 | L13: =(B13-F13)/($Q$4-$Q$2) -> 9960.1769 | M13: =(B13-G13)/($Q$5-$Q$2) -> 348.78809 | N13: =(B13-H13)/($Q$5-$Q$2) -> 1068.0006 | S13: 4709.1621 | T13: 14312.678 | U13: 4418.1465 | V13: 22884.412 | W13: 4352.0066 | X13: 7950.0181
A14: 600 | B14: 620.48217 | C14: 1130.8796 | D14: 3250.5582 | E14: 1075.0046 | F14: 4896.331 | G14: 1062.3058 | H14: 2028.9274 | I14: =(B14-C14)/($Q$3-$Q$2) -> 420.42625 | J14: =(B14-D14)/($Q$3-$Q$2) -> 2166.4547 | K14: =(B14-E14)/($Q$4-$Q$2) -> 1052.1353 | L14: =(B14-F14)/($Q$4-$Q$2) -> 9897.7982 | M14: =(B14-G14)/($Q$5-$Q$2) -> 328.7378 | N14: =(B14-H14)/($Q$5-$Q$2) -> 1047.9503 | S14: 4709.1621 | T14: 14312.678 | U14: 4418.1465 | V14: 22884.412 | W14: 4352.0066 | X14: 7950.0181
A15: 650 | B15: 655.51401 | C15: 1138.9639 | D15: 3258.6424 | E15: 1083.0889 | F15: 4904.4152 | G15: 1070.39 | H15: 2037.0117 | I15: =(B15-C15)/($Q$3-$Q$2) -> 398.22888 | J15: =(B15-D15)/($Q$3-$Q$2) -> 2144.2573 | K15: =(B15-E15)/($Q$4-$Q$2) -> 989.75662 | L15: =(B15-F15)/($Q$4-$Q$2) -> 9835.4194 | M15: =(B15-G15)/($Q$5-$Q$2) -> 308.6875 | N15: =(B15-H15)/($Q$5-$Q$2) -> 1027.9 | S15: 4709.1621 | T15: 14312.678 | U15: 4418.1465 | V15: 22884.412 | W15: 4352.0066 | X15: 7950.0181
A16: 700 | B16: 690.54586 | C16: 1147.0481 | D16: 3266.7267 | E16: 1091.1731 | F16: 4912.4995 | G16: 1078.4743 | H16: 2045.0959 | I16: =(B16-C16)/($Q$3-$Q$2) -> 376.03152 | J16: =(B16-D16)/($Q$3-$Q$2) -> 2122.06 | K16: =(B16-E16)/($Q$4-$Q$2) -> 927.37792 | L16: =(B16-F16)/($Q$4-$Q$2) -> 9773.0407 | M16: =(B16-G16)/($Q$5-$Q$2) -> 288.6372 | N16: =(B16-H16)/($Q$5-$Q$2) -> 1007.8498 | S16: 4709.1621 | T16: 14312.678 | U16: 4418.1465 | V16: 22884.412 | W16: 4352.0066 | X16: 7950.0181
A17: 750 | B17: 725.57771 | C17: 1155.1324 | D17: 3274.8109 | E17: 1099.2574 | F17: 4920.5837 | G17: 1086.5585 | H17: 2053.1802 | I17: =(B17-C17)/($Q$3-$Q$2) -> 353.83415 | J17: =(B17-D17)/($Q$3-$Q$2) -> 2099.8626 | K17: =(B17-E17)/($Q$4-$Q$2) -> 864.99921 | L17: =(B17-F17)/($Q$4-$Q$2) -> 9710.662 | M17: =(B17-G17)/($Q$5-$Q$2) -> 268.5869 | N17: =(B17-H17)/($Q$5-$Q$2) -> 987.79945 | S17: 4709.1621 | T17: 14312.678 | U17: 4418.1465 | V17: 22884.412 | W17: 4352.0066 | X17: 7950.0181
... A102: 5000 | B102: 3703.2847 | C102: 1842.2933 | D102: 3961.9718 | E102: 1786.4183 | F102: 5607.7446 | G102: 1773.7194 | H102: 2740.3411 | I102: =(B102-C102)/($Q$3-$Q$2) -> -1532.9419 | J102: =(B102-D102)/($Q$3-$Q$2) -> 213.08659 | K102: =(B102-E102)/($Q$4-$Q$2) -> -4437.1908 | L102: =(B102-F102)/($Q$4-$Q$2) -> 4408.472 | M102: =(B102-G102)/($Q$5-$Q$2) -> -1435.6885 | N102: =(B102-H102)/($Q$5-$Q$2) -> -716.47591 | S102: 4709.1621 | T102: 14312.678 | U102: 4418.1465 | V102: 22884.412 | W102: 4352.0066 | X102: 7950.0181

Sheet Propanol
A1: NG price | B1: BAU | C1: DAC + wind + BAU ethylene | D1: DAC + solar + BAU ethylene | E1: DAC + nuclear + BAU ethylene | F1: DAC + wind + gEthylene | G1: DAC + solar + gEthylene | H1: DAC + nuclear + gEthylene | I1: CO2 DAC + wind + BAU ethylene | J1: CO2 DAC + solar + BAU ethylene | K1: CO2 DAC + nuclear + BAU ethylene | L1: CO2 DAC + wind + gEthylene | M1: CO2 DAC + solar + gEthylene | N1: CO2 DAC + nuclear + gEthylene | P1: Process | Q1: GWP
A2: 0 | B2: 1086.3027 | C2: 2023.4303 | D2: 2501.4577 | E2: 1943.1007 | F2: 3086.6387 | G2: 4174.807 | H2: 2903.7785 | I2: =(B2-C2)/($Q$3-$Q$2) -> 229.29475 | J2: =(B2-D2)/($Q$4-$Q$2) -> 384.34412 | K2: =(B2-E2)/($Q$5-$Q$2) -> 206.25854 | L2: =(B2-F2)/($Q$6-$Q$2) -> 382.32722 | M2: =(B2-G2)/($Q$7-$Q$2) -> 790.10086 | N2: =(B2-H2)/($Q$8-$Q$2) -> 333.4818 | P2: BAU | Q2: 4.63
A3: 50 | B3: 1101.4175 | C3: 2029.0325 | D3: 2507.0599 | E3: 1948.7028 | F3: 3101.5118 | G3: 4189.6801 | H3: 2918.6516 | I3: =(B3-C3)/($Q$3-$Q$2) -> 226.9672 | J3: =(B3-D3)/($Q$4-$Q$2) -> 381.76055 | K3: =(B3-E3)/($Q$5-$Q$2) -> 203.96853 | L3: =(B3-F3)/($Q$6-$Q$2) -> 382.28102 | M3: =(B3-G3)/($Q$7-$Q$2) -> 790.03902 | N3: =(B3-H3)/($Q$8-$Q$2) -> 333.43744 | P3: DAC + wind + BAU ethylene | Q3: 0.543
A4: 100 | B4: 1116.5324 | C4: 2034.6346 | D4: 2512.662 | E4: 1954.305 | F4: 3116.3849 | G4: 4204.5532 | H4: 2933.5247 | I4: =(B4-C4)/($Q$3-$Q$2) -> 224.63965 | J4: =(B4-D4)/($Q$4-$Q$2) -> 379.17698 | K4: =(B4-E4)/($Q$5-$Q$2) -> 201.67852 | L4: =(B4-F4)/($Q$6-$Q$2) -> 382.23482 | M4: =(B4-G4)/($Q$7-$Q$2) -> 789.97719 | N4: =(B4-H4)/($Q$8-$Q$2) -> 333.39309 | P4: DAC + solar + BAU ethylene | Q4: 0.948
A5: 150 | B5: 1131.6472 | C5: 2040.2368 | D5: 2518.2642 | E5: 1959.9071 | F5: 3131.2581 | G5: 4219.4263 | H5: 2948.3978 | I5: =(B5-C5)/($Q$3-$Q$2) -> 222.3121 | J5: =(B5-D5)/($Q$4-$Q$2) -> 376.59341 | K5: =(B5-E5)/($Q$5-$Q$2) -> 199.38851 | L5: =(B5-F5)/($Q$6-$Q$2) -> 382.18862 | M5: =(B5-G5)/($Q$7-$Q$2) -> 789.91535 | N5: =(B5-H5)/($Q$8-$Q$2) -> 333.34874 | P5: DAC + nuclear + BAU ethylene | Q5: 0.476
A6: 200 | B6: 1146.7621 | C6: 2045.8389 | D6: 2523.8663 | E6: 1965.5093 | F6: 3146.1312 | G6: 4234.2994 | H6: 2963.271 | I6: =(B6-C6)/($Q$3-$Q$2) -> 219.98455 | J6: =(B6-D6)/($Q$4-$Q$2) -> 374.00984 | K6: =(B6-E6)/($Q$5-$Q$2) -> 197.0985 | L6: =(B6-F6)/($Q$6-$Q$2) -> 382.14242 | M6: =(B6-G6)/($Q$7-$Q$2) -> 789.85351 | N6: =(B6-H6)/($Q$8-$Q$2) -> 333.30438 | P6: DAC + wind + gEthylene | Q6: -0.602
A7: 250 | B7: 1161.8769 | C7: 2051.4411 | D7: 2529.4685 | E7: 1971.1114 | F7: 3161.0043 | G7: 4249.1726 | H7: 2978.1441 | I7: =(B7-C7)/($Q$3-$Q$2) -> 217.657 | J7: =(B7-D7)/($Q$4-$Q$2) -> 371.42627 | K7: =(B7-E7)/($Q$5-$Q$2) -> 194.80849 | L7: =(B7-F7)/($Q$6-$Q$2) -> 382.09622 | M7: =(B7-G7)/($Q$7-$Q$2) -> 789.79167 | N7: =(B7-H7)/($Q$8-$Q$2) -> 333.26003 | P7: DAC + solar + gEthylene | Q7: 0.721
A8: 300 | B8: 1176.9918 | C8: 2057.0432 | D8: 2535.0706 | E8: 1976.7136 | F8: 3175.8774 | G8: 4264.0457 | H8: 2993.0172 | I8: =(B8-C8)/($Q$3-$Q$2) -> 215.32945 | J8: =(B8-D8)/($Q$4-$Q$2) -> 368.84271 | K8: =(B8-E8)/($Q$5-$Q$2) -> 192.51849 | L8: =(B8-F8)/($Q$6-$Q$2) -> 382.05001 | M8: =(B8-G8)/($Q$7-$Q$2) -> 789.72984 | N8: =(B8-H8)/($Q$8-$Q$2) -> 333.21568 | P8: DAC + nuclear + gEthylene | Q8: -0.82
A9: 350 | B9: 1192.1066 | C9: 2062.6454 | D9: 2540.6728 | E9: 1982.3157 | F9: 3190.7506 | G9: 4278.9188 | H9: 3007.8903 | I9: =(B9-C9)/($Q$3-$Q$2) -> 213.0019 | J9: =(B9-D9)/($Q$4-$Q$2) -> 366.25914 | K9: =(B9-E9)/($Q$5-$Q$2) -> 190.22848 | L9: =(B9-F9)/($Q$6-$Q$2) -> 382.00381 | M9: =(B9-G9)/($Q$7-$Q$2) -> 789.668 | N9: =(B9-H9)/($Q$8-$Q$2) -> 333.17133
A10: 400 | B10: 1207.2215 | C10: 2068.2475 | D10: 2546.2749 | E10: 1987.9178 | F10: 3205.6237 | G10: 4293.7919 | H10: 3022.7635 | I10: =(B10-C10)/($Q$3-$Q$2) -> 210.67435 | J10: =(B10-D10)/($Q$4-$Q$2) -> 363.67557 | K10: =(B10-E10)/($Q$5-$Q$2) -> 187.93847 | L10: =(B10-F10)/($Q$6-$Q$2) -> 381.95761 | M10: =(B10-G10)/($Q$7-$Q$2) -> 789.60616 | N10: =(B10-H10)/($Q$8-$Q$2) -> 333.12697
A11: 450 | B11: 1222.3363 | C11: 2073.8497 | D11: 2551.877 | E11: 1993.52 | F11: 3220.4968 | G11: 4308.6651 | H11: 3037.6366 | I11: =(B11-C11)/($Q$3-$Q$2) -> 208.3468 | J11: =(B11-D11)/($Q$4-$Q$2) -> 361.092 | K11: =(B11-E11)/($Q$5-$Q$2) -> 185.64846 | L11: =(B11-F11)/($Q$6-$Q$2) -> 381.91141 | M11: =(B11-G11)/($Q$7-$Q$2) -> 789.54432 | N11: =(B11-H11)/($Q$8-$Q$2) -> 333.08262
A12: 500 | B12: 1237.4511 | C12: 2079.4518 | D12: 2557.4792 | E12: 1999.1221 | F12: 3235.3699 | G12: 4323.5382 | H12: 3052.5097 | I12: =(B12-C12)/($Q$3-$Q$2) -> 206.01925 | J12: =(B12-D12)/($Q$4-$Q$2) -> 358.50843 | K12: =(B12-E12)/($Q$5-$Q$2) -> 183.35845 | L12: =(B12-F12)/($Q$6-$Q$2) -> 381.86521 | M12: =(B12-G12)/($Q$7-$Q$2) -> 789.48249 | N12: =(B12-H12)/($Q$8-$Q$2) -> 333.03827
A13: 550 | B13: 1252.566 | C13: 2085.054 | D13: 2563.0813 | E13: 2004.7243 | F13: 3250.2431 | G13: 4338.4113 | H13: 3067.3828 | I13: =(B13-C13)/($Q$3-$Q$2) -> 203.6917 | J13: =(B13-D13)/($Q$4-$Q$2) -> 355.92486 | K13: =(B13-E13)/($Q$5-$Q$2) -> 181.06844 | L13: =(B13-F13)/($Q$6-$Q$2) -> 381.81901 | M13: =(B13-G13)/($Q$7-$Q$2) -> 789.42065 | N13: =(B13-H13)/($Q$8-$Q$2) -> 332.99391
A14: 600 | B14: 1267.6808 | C14: 2090.6561 | D14: 2568.6835 | E14: 2010.3264 | F14: 3265.1162 | G14: 4353.2844 | H14: 3082.256 | I14: =(B14-C14)/($Q$3-$Q$2) -> 201.36415 | J14: =(B14-D14)/($Q$4-$Q$2) -> 353.3413 | K14: =(B14-E14)/($Q$5-$Q$2) -> 178.77843 | L14: =(B14-F14)/($Q$6-$Q$2) -> 381.77281 | M14: =(B14-G14)/($Q$7-$Q$2) -> 789.35881 | N14: =(B14-H14)/($Q$8-$Q$2) -> 332.94956
A15: 650 | B15: 1282.7957 | C15: 2096.2583 | D15: 2574.2856 | E15: 2015.9286 | F15: 3279.9893 | G15: 4368.1576 | H15: 3097.1291 | I15: =(B15-C15)/($Q$3-$Q$2) -> 199.0366 | J15: =(B15-D15)/($Q$4-$Q$2) -> 350.75773 | K15: =(B15-E15)/($Q$5-$Q$2) -> 176.48842 | L15: =(B15-F15)/($Q$6-$Q$2) -> 381.72661 | M15: =(B15-G15)/($Q$7-$Q$2) -> 789.29697 | N15: =(B15-H15)/($Q$8-$Q$2) -> 332.90521
A16: 700 | B16: 1297.9105 | C16: 2101.8604 | D16: 2579.8878 | E16: 2021.5307 | F16: 3294.8624 | G16: 4383.0307 | H16: 3112.0022 | I16: =(B16-C16)/($Q$3-$Q$2) -> 196.70905 | J16: =(B16-D16)/($Q$4-$Q$2) -> 348.17416 | K16: =(B16-E16)/($Q$5-$Q$2) -> 174.19841 | L16: =(B16-F16)/($Q$6-$Q$2) -> 381.68041 | M16: =(B16-G16)/($Q$7-$Q$2) -> 789.23514 | N16: =(B16-H16)/($Q$8-$Q$2) -> 332.86086
A17: 750 | B17: 1313.0254 | C17: 2107.4625 | D17: 2585.4899 | E17: 2027.1329 | F17: 3309.7356 | G17: 4397.9038 | H17: 3126.8753 | I17: =(B17-C17)/($Q$3-$Q$2) -> 194.38149 | J17: =(B17-D17)/($Q$4-$Q$2) -> 345.59059 | K17: =(B17-E17)/($Q$5-$Q$2) -> 171.9084 | L17: =(B17-F17)/($Q$6-$Q$2) -> 381.63421 | M17: =(B17-G17)/($Q$7-$Q$2) -> 789.1733 | N17: =(B17-H17)/($Q$8-$Q$2) -> 332.8165
A18: 800 | B18: 1328.1402 | C18: 2113.0647 | D18: 2591.0921 | E18: 2032.735 | F18: 3324.6087 | G18: 4412.7769 | H18: 3141.7484 | I18: =(B18-C18)/($Q$3-$Q$2) -> 192.05394 | J18: =(B18-D18)/($Q$4-$Q$2) -> 343.00702 | K18: =(B18-E18)/($Q$5-$Q$2) -> 169.61839 | L18: =(B18-F18)/($Q$6-$Q$2) -> 381.58801 | M18: =(B18-G18)/($Q$7-$Q$2) -> 789.11146 | N18: =(B18-H18)/($Q$8-$Q$2) -> 332.77215
A19: 850 | B19: 1343.2551 | C19: 2118.6668 | D19: 2596.6942 | E19: 2038.3372 | F19: 3339.4818 | G19: 4427.65 | H19: 3156.6216 | I19: =(B19-C19)/($Q$3-$Q$2) -> 189.72639 | J19: =(B19-D19)/($Q$4-$Q$2) -> 340.42345 | K19: =(B19-E19)/($Q$5-$Q$2) -> 167.32838 | L19: =(B19-F19)/($Q$6-$Q$2) -> 381.54181 | M19: =(B19-G19)/($Q$7-$Q$2) -> 789.04962 | N19: =(B19-H19)/($Q$8-$Q$2) -> 332.7278
A20: 900 | B20: 1358.3699 | C20: 2124.269 | D20: 2602.2964 | E20: 2043.9393 | F20: 3354.3549 | G20: 4442.5232 | H20: 3171.4947 | I20: =(B20-C20)/($Q$3-$Q$2) -> 187.39884 | J20: =(B20-D20)/($Q$4-$Q$2) -> 337.83989 | K20: =(B20-E20)/($Q$5-$Q$2) -> 165.03837 | L20: =(B20-F20)/($Q$6-$Q$2) -> 381.4956 | M20: =(B20-G20)/($Q$7-$Q$2) -> 788.98779 | N20: =(B20-H20)/($Q$8-$Q$2) -> 332.68344
... A102: 5000 | B102: 2597.7873 | C102: 2583.6451 | D102: 3061.6724 | E102: 2503.3154 | F102: 4573.951 | G102: 5662.1193 | H102: 4391.0908 | I102: =(B102-C102)/($Q$3-$Q$2) -> -3.4602972 | J102: =(B102-D102)/($Q$4-$Q$2) -> 125.98728 | K102: =(B102-E102)/($Q$5-$Q$2) -> -22.742394 | L102: =(B102-F102)/($Q$6-$Q$2) -> 377.70714 | M102: =(B102-G102)/($Q$7-$Q$2) -> 783.91711 | N102: =(B102-H102)/($Q$8-$Q$2) -> 329.04652

Sheet Propanol high low
A1: NG price | B1: BAU price | C1: DAC + wind + BAU ethylene low | D1: DAC + wind + BAU ethylene high | E1: DAC + solar + BAU ethylene low | F1: DAC + solar + BAU ethylene high | G1: DAC + nuclear + BAU ethylene low | H1: DAC + nuclear + BAU ethylene high | I1: DAC + wind + gEthylene low | J1: DAC + wind + gEthylene high | K1: DAC + solar + gEthylene low | L1: DAC + solar + gEthylene high | M1: DAC + nuclear + gEthylene low | N1: DAC + nuclear + gEthylene high | O1: CO2 DAC + wind + BAU ethylene low | P1: CO2 DAC + wind + BAU ethylene high | Q1: CO2 DAC + solar + BAU ethylene low | R1: CO2 DAC + solar + BAU ethylene high | S1: CO2 DAC + nuclear + BAU ethylene low | T1: CO2 DAC + nuclear + BAU ethylene high | U1: CO2 DAC + wind + gEthylene low | V1: CO2 DAC + wind + gEthylene high | W1: CO2 DAC + solar + gEthylene low | X1: CO2 DAC + solar + gEthylene high | Y1: CO2 DAC + nuclear + gEthylene low | Z1: CO2 DAC + nuclear + gEthylene high | AB1: Process | AC1: GWP
A2: 0 | B2: 1086.3027 | C2: 1802.1945 | D2: 2758.2493 | E2: 1773.2232 | F2: 3611.5874 | G2: 1766.6388 | H2: 2124.8301 | I2: 2583.0236 | J2: 4759.3601 | K2: 2517.0741 | L2: 6701.8754 | M2: 2502.0855 | N2: 3317.4623 | O2: =(B2-C2)/($AC$3-$AC$2) -> 175.16316 | P2: =(B2-D2)/($AC$3-$AC$2) -> 409.08897 | Q2: =(B2-E2)/($AC$4-$AC$2) -> 186.56178 | R2: =(B2-F2)/($AC$4-$AC$2) -> 685.84594 | S2: =(B2-G2)/($AC$5-$AC$2) -> 163.77855 | T2: =(B2-H2)/($AC$5-$AC$2) -> 250.0066 | U2: =(B2-I2)/($AC$6-$AC$2) -> 286.07052 | V2: =(B2-J2)/($AC$6-$AC$2) -> 702.03698 | W2: =(B2-K2)/($AC$7-$AC$2) -> 366.01979 | X2: =(B2-L2)/($AC$7-$AC$2) -> 1436.5753 | Y2: =(B2-M2)/($AC$8-$AC$2) -> 259.77666 | Z2: =(B2-N2)/($AC$8-$AC$2) -> 409.38708 | AB2: BAU | AC2: 4.63
A3: 50 | B3: 1101.4175 | C3: 1807.7967 | D3: 2763.8514 | E3: 1778.8253 | F3: 3617.1896 | G3: 1772.2409 | H3: 2130.4322 | I3: 2597.8968 | J3: 4774.2333 | K3: 2531.9472 | L3: 6716.7485 | M3: 2516.9586 | N3: 3332.3354 | O3: =(B3-C3)/($AC$3-$AC$2) -> 172.83561 | P3: =(B3-D3)/($AC$3-$AC$2) -> 406.76142 | Q3: =(B3-E3)/($AC$4-$AC$2) -> 183.97821 | R3: =(B3-F3)/($AC$4-$AC$2) -> 683.26237 | S3: =(B3-G3)/($AC$5-$AC$2) -> 161.48854 | T3: =(B3-H3)/($AC$5-$AC$2) -> 247.71659 | U3: =(B3-I3)/($AC$6-$AC$2) -> 286.02432 | V3: =(B3-J3)/($AC$6-$AC$2) -> 701.99077 | W3: =(B3-K3)/($AC$7-$AC$2) -> 365.95795 | X3: =(B3-L3)/($AC$7-$AC$2) -> 1436.5134 | Y3: =(B3-M3)/($AC$8-$AC$2) -> 259.73231 | Z3: =(B3-N3)/($AC$8-$AC$2) -> 409.34273 | AB3: DAC + wind + BAU ethylene | AC3: 0.543
A4: 100 | B4: 1116.5324 | C4: 1813.3988 | D4: 2769.4536 | E4: 1784.4275 | F4: 3622.7917 | G4: 1777.8431 | H4: 2136.0344 | I4: 2612.7699 | J4: 4789.1064 | K4: 2546.8203 | L4: 6731.6216 | M4: 2531.8318 | N4: 3347.2085 | O4: =(B4-C4)/($AC$3-$AC$2) -> 170.50806 | P4: =(B4-D4)/($AC$3-$AC$2) -> 404.43387 | Q4: =(B4-E4)/($AC$4-$AC$2) -> 181.39465 | R4: =(B4-F4)/($AC$4-$AC$2) -> 680.6788 | S4: =(B4-G4)/($AC$5-$AC$2) -> 159.19853 | T4: =(B4-H4)/($AC$5-$AC$2) -> 245.42658 | U4: =(B4-I4)/($AC$6-$AC$2) -> 285.97812 | V4: =(B4-J4)/($AC$6-$AC$2) -> 701.94457 | W4: =(B4-K4)/($AC$7-$AC$2) -> 365.89612 | X4: =(B4-L4)/($AC$7-$AC$2) -> 1436.4516 | Y4: =(B4-M4)/($AC$8-$AC$2) -> 259.68796 | Z4: =(B4-N4)/($AC$8-$AC$2) -> 409.29837 | AB4: DAC + solar + BAU ethylene | AC4: 0.948
A5: 150 | B5: 1131.6472 | C5: 1819.001 | D5: 2775.0557 | E5: 1790.0296 | F5: 3628.3939 | G5: 1783.4452 | H5: 2141.6365 | I5: 2627.643 | J5: 4803.9795 | K5: 2561.6934 | L5: 6746.4947 | M5: 2546.7049 | N5: 3362.0816 | O5: =(B5-C5)/($AC$3-$AC$2) -> 168.18051 | P5: =(B5-D5)/($AC$3-$AC$2) -> 402.10632 | Q5: =(B5-E5)/($AC$4-$AC$2) -> 178.81108 | R5: =(B5-F5)/($AC$4-$AC$2) -> 678.09523 | S5: =(B5-G5)/($AC$5-$AC$2) -> 156.90852 | T5: =(B5-H5)/($AC$5-$AC$2) -> 243.13657 | U5: =(B5-I5)/($AC$6-$AC$2) -> 285.93192 | V5: =(B5-J5)/($AC$6-$AC$2) -> 701.89837 | W5: =(B5-K5)/($AC$7-$AC$2) -> 365.83428 | X5: =(B5-L5)/($AC$7-$AC$2) -> 1436.3897 | Y5: =(B5-M5)/($AC$8-$AC$2) -> 259.64361 | Z5: =(B5-N5)/($AC$8-$AC$2) -> 409.25402 | AB5: DAC + nuclear + BAU ethylene | AC5: 0.476
A6: 200 | B6: 1146.7621 | C6: 1824.6031 | D6: 2780.6579 | E6: 1795.6318 | F6: 3633.996 | G6: 1789.0474 | H6: 2147.2387 | I6: 2642.5161 | J6: 4818.8526 | K6: 2576.5665 | L6: 6761.3679 | M6: 2561.578 | N6: 3376.9548 | O6: =(B6-C6)/($AC$3-$AC$2) -> 165.85296 | P6: =(B6-D6)/($AC$3-$AC$2) -> 399.77876 | Q6: =(B6-E6)/($AC$4-$AC$2) -> 176.22751 | R6: =(B6-F6)/($AC$4-$AC$2) -> 675.51167 | S6: =(B6-G6)/($AC$5-$AC$2) -> 154.61851 | T6: =(B6-H6)/($AC$5-$AC$2) -> 240.84656 | U6: =(B6-I6)/($AC$6-$AC$2) -> 285.88572 | V6: =(B6-J6)/($AC$6-$AC$2) -> 701.85217 | W6: =(B6-K6)/($AC$7-$AC$2) -> 365.77244 | X6: =(B6-L6)/($AC$7-$AC$2) -> 1436.3279 | Y6: =(B6-M6)/($AC$8-$AC$2) -> 259.59925 | Z6: =(B6-N6)/($AC$8-$AC$2) -> 409.20967 | AB6: DAC + wind + gEthylene | AC6: -0.602
A7: 250 | B7: 1161.8769 | C7: 1830.2053 | D7: 2786.26 | E7: 1801.2339 | F7: 3639.5982 | G7: 1794.6495 | H7: 2152.8408 | I7: 2657.3893 | J7: 4833.7258 | K7: 2591.4397 | L7: 6776.241 | M7: 2576.4511 | N7: 3391.8279 | O7: =(B7-C7)/($AC$3-$AC$2) -> 163.52541 | P7: =(B7-D7)/($AC$3-$AC$2) -> 397.45121 | Q7: =(B7-E7)/($AC$4-$AC$2) -> 173.64394 | R7: =(B7-F7)/($AC$4-$AC$2) -> 672.9281 | S7: =(B7-G7)/($AC$5-$AC$2) -> 152.3285 | T7: =(B7-H7)/($AC$5-$AC$2) -> 238.55655 | U7: =(B7-I7)/($AC$6-$AC$2) -> 285.83951 | V7: =(B7-J7)/($AC$6-$AC$2) -> 701.80597 | W7: =(B7-K7)/($AC$7-$AC$2) -> 365.7106 | X7: =(B7-L7)/($AC$7-$AC$2) -> 1436.2661 | Y7: =(B7-M7)/($AC$8-$AC$2) -> 259.5549 | Z7: =(B7-N7)/($AC$8-$AC$2) -> 409.16532 | AB7: DAC + solar + gEthylene | AC7: 0.721
A8: 300 | B8: 1176.9918 | C8: 1835.8074 | D8: 2791.8622 | E8: 1806.8361 | F8: 3645.2003 | G8: 1800.2517 | H8: 2158.443 | I8: 2672.2624 | J8: 4848.5989 | K8: 2606.3128 | L8: 6791.1141 | M8: 2591.3242 | N8: 3406.701 | O8: =(B8-C8)/($AC$3-$AC$2) -> 161.19786 | P8: =(B8-D8)/($AC$3-$AC$2) -> 395.12366 | Q8: =(B8-E8)/($AC$4-$AC$2) -> 171.06037 | R8: =(B8-F8)/($AC$4-$AC$2) -> 670.34453 | S8: =(B8-G8)/($AC$5-$AC$2) -> 150.03849 | T8: =(B8-H8)/($AC$5-$AC$2) -> 236.26654 | U8: =(B8-I8)/($AC$6-$AC$2) -> 285.79331 | V8: =(B8-J8)/($AC$6-$AC$2) -> 701.75977 | W8: =(B8-K8)/($AC$7-$AC$2) -> 365.64877 | X8: =(B8-L8)/($AC$7-$AC$2) -> 1436.2042 | Y8: =(B8-M8)/($AC$8-$AC$2) -> 259.51055 | Z8: =(B8-N8)/($AC$8-$AC$2) -> 409.12096 | AB8: DAC + nuclear + gEthylene | AC8: -0.82
A9: 350 | B9: 1192.1066 | C9: 1841.4096 | D9: 2797.4643 | E9: 1812.4382 | F9: 3650.8025 | G9: 1805.8538 | H9: 2164.0451 | I9: 2687.1355 | J9: 4863.472 | K9: 2621.1859 | L9: 6805.9872 | M9: 2606.1974 | N9: 3421.5741 | O9: =(B9-C9)/($AC$3-$AC$2) -> 158.87031 | P9: =(B9-D9)/($AC$3-$AC$2) -> 392.79611 | Q9: =(B9-E9)/($AC$4-$AC$2) -> 168.4768 | R9: =(B9-F9)/($AC$4-$AC$2) -> 667.76096 | S9: =(B9-G9)/($AC$5-$AC$2) -> 147.74848 | T9: =(B9-H9)/($AC$5-$AC$2) -> 233.97653 | U9: =(B9-I9)/($AC$6-$AC$2) -> 285.74711 | V9: =(B9-J9)/($AC$6-$AC$2) -> 701.71357 | W9: =(B9-K9)/($AC$7-$AC$2) -> 365.58693 | X9: =(B9-L9)/($AC$7-$AC$2) -> 1436.1424 | Y9: =(B9-M9)/($AC$8-$AC$2) -> 259.46619 | Z9: =(B9-N9)/($AC$8-$AC$2) -> 409.07661
A10: 400 | B10: 1207.2215 | C10: 1847.0117 | D10: 2803.0665 | E10: 1818.0403 | F10: 3656.4046 | G10: 1811.4559 | H10: 2169.6473 | I10: 2702.0086 | J10: 4878.3451 | K10: 2636.059 | L10: 6820.8604 | M10: 2621.0705 | N10: 3436.4473 | O10: =(B10-C10)/($AC$3-$AC$2) -> 156.54276 | P10: =(B10-D10)/($AC$3-$AC$2) -> 390.46856 | Q10: =(B10-E10)/($AC$4-$AC$2) -> 165.89323 | R10: =(B10-F10)/($AC$4-$AC$2) -> 665.17739 | S10: =(B10-G10)/($AC$5-$AC$2) -> 145.45847 | T10: =(B10-H10)/($AC$5-$AC$2) -> 231.68652 | U10: =(B10-I10)/($AC$6-$AC$2) -> 285.70091 | V10: =(B10-J10)/($AC$6-$AC$2) -> 701.66737 | W10: =(B10-K10)/($AC$7-$AC$2) -> 365.52509 | X10: =(B10-L10)/($AC$7-$AC$2) -> 1436.0806 | Y10: =(B10-M10)/($AC$8-$AC$2) -> 259.42184 | Z10: =(B10-N10)/($AC$8-$AC$2) -> 409.03226
A11: 450 | B11: 1222.3363 | C11: 1852.6139 | D11: 2808.6686 | E11: 1823.6425 | F11: 3662.0068 | G11: 1817.0581 | H11: 2175.2494 | I11: 2716.8818 | J11: 4893.2183 | K11: 2650.9322 | L11: 6835.7335 | M11: 2635.9436 | N11: 3451.3204 | O11: =(B11-C11)/($AC$3-$AC$2) -> 154.21521 | P11: =(B11-D11)/($AC$3-$AC$2) -> 388.14101 | Q11: =(B11-E11)/($AC$4-$AC$2) -> 163.30967 | R11: =(B11-F11)/($AC$4-$AC$2) -> 662.59382 | S11: =(B11-G11)/($AC$5-$AC$2) -> 143.16846 | T11: =(B11-H11)/($AC$5-$AC$2) -> 229.39651 | U11: =(B11-I11)/($AC$6-$AC$2) -> 285.65471 | V11: =(B11-J11)/($AC$6-$AC$2) -> 701.62117 | W11: =(B11-K11)/($AC$7-$AC$2) -> 365.46325 | X11: =(B11-L11)/($AC$7-$AC$2) -> 1436.0187 | Y11: =(B11-M11)/($AC$8-$AC$2) -> 259.37749 | Z11: =(B11-N11)/($AC$8-$AC$2) -> 408.9879
A12: 500 | B12: 1237.4511 | C12: 1858.216 | D12: 2814.2708 | E12: 1829.2446 | F12: 3667.6089 | G12: 1822.6602 | H12: 2180.8516 | I12: 2731.7549 | J12: 4908.0914 | K12: 2665.8053 | L12: 6850.6066 | M12: 2650.8167 | N12: 3466.1935 | O12: =(B12-C12)/($AC$3-$AC$2) -> 151.88766 | P12: =(B12-D12)/($AC$3-$AC$2) -> 385.81346 | Q12: =(B12-E12)/($AC$4-$AC$2) -> 160.7261 | R12: =(B12-F12)/($AC$4-$AC$2) -> 660.01026 | S12: =(B12-G12)/($AC$5-$AC$2) -> 140.87845 | T12: =(B12-H12)/($AC$5-$AC$2) -> 227.1065 | U12: =(B12-I12)/($AC$6-$AC$2) -> 285.60851 | V12: =(B12-J12)/($AC$6-$AC$2) -> 701.57497 | W12: =(B12-K12)/($AC$7-$AC$2) -> 365.40142 | X12: =(B12-L12)/($AC$7-$AC$2) -> 1435.9569 | Y12: =(B12-M12)/($AC$8-$AC$2) -> 259.33314 | Z12: =(B12-N12)/($AC$8-$AC$2) -> 408.94355
A13: 550 | B13: 1252.566 | C13: 1863.8181 | D13: 2819.8729 | E13: 1834.8468 | F13: 3673.2111 | G13: 1828.2624 | H13: 2186.4537 | I13: 2746.628 | J13: 4922.9645 | K13: 2680.6784 | L13: 6865.4797 | M13: 2665.6899 | N13: 3481.0666 | O13: =(B13-C13)/($AC$3-$AC$2) -> 149.56011 | P13: =(B13-D13)/($AC$3-$AC$2) -> 383.48591 | Q13: =(B13-E13)/($AC$4-$AC$2) -> 158.14253 | R13: =(B13-F13)/($AC$4-$AC$2) -> 657.42669 | S13: =(B13-G13)/($AC$5-$AC$2) -> 138.58844 | T13: =(B13-H13)/($AC$5-$AC$2) -> 224.81649 | U13: =(B13-I13)/($AC$6-$AC$2) -> 285.56231 | V13: =(B13-J13)/($AC$6-$AC$2) -> 701.52877 | W13: =(B13-K13)/($AC$7-$AC$2) -> 365.33958 | X13: =(B13-L13)/($AC$7-$AC$2) -> 1435.895 | Y13: =(B13-M13)/($AC$8-$AC$2) -> 259.28878 | Z13: =(B13-N13)/($AC$8-$AC$2) -> 408.8992
A14: 600 | B14: 1267.6808 | C14: 1869.4203 | D14: 2825.4751 | E14: 1840.4489 | F14: 3678.8132 | G14: 1833.8645 | H14: 2192.0559 | I14: 2761.5011 | J14: 4937.8376 | K14: 2695.5515 | L14: 6880.3528 | M14: 2680.563 | N14: 3495.9397 | O14: =(B14-C14)/($AC$3-$AC$2) -> 147.23255 | P14: =(B14-D14)/($AC$3-$AC$2) -> 381.15836 | Q14: =(B14-E14)/($AC$4-$AC$2) -> 155.55896 | R14: =(B14-F14)/($AC$4-$AC$2) -> 654.84312 | S14: =(B14-G14)/($AC$5-$AC$2) -> 136.29843 | T14: =(B14-H14)/($AC$5-$AC$2) -> 222.52648 | U14: =(B14-I14)/($AC$6-$AC$2) -> 285.51611 | V14: =(B14-J14)/($AC$6-$AC$2) -> 701.48257 | W14: =(B14-K14)/($AC$7-$AC$2) -> 365.27774 | X14: =(B14-L14)/($AC$7-$AC$2) -> 1435.8332 | Y14: =(B14-M14)/($AC$8-$AC$2) -> 259.24443 | Z14: =(B14-N14)/($AC$8-$AC$2) -> 408.85485
A15: 650 | B15: 1282.7957 | C15: 1875.0224 | D15: 2831.0772 | E15: 1846.0511 | F15: 3684.4153 | G15: 1839.4667 | H15: 2197.658 | I15: 2776.3742 | J15: 4952.7107 | K15: 2710.4247 | L15: 6895.226 | M15: 2695.4361 | N15: 3510.8129 | O15: =(B15-C15)/($AC$3-$AC$2) -> 144.905 | P15: =(B15-D15)/($AC$3-$AC$2) -> 378.83081 | Q15: =(B15-E15)/($AC$4-$AC$2) -> 152.97539 | R15: =(B15-F15)/($AC$4-$AC$2) -> 652.25955 | S15: =(B15-G15)/($AC$5-$AC$2) -> 134.00842 | T15: =(B15-H15)/($AC$5-$AC$2) -> 220.23647 | U15: =(B15-I15)/($AC$6-$AC$2) -> 285.46991 | V15: =(B15-J15)/($AC$6-$AC$2) -> 701.43636 | W15: =(B15-K15)/($AC$7-$AC$2) -> 365.2159 | X15: =(B15-L15)/($AC$7-$AC$2) -> 1435.7714 | Y15: =(B15-M15)/($AC$8-$AC$2) -> 259.20008 | Z15: =(B15-N15)/($AC$8-$AC$2) -> 408.81049
A16: 700 | B16: 1297.9105 | C16: 1880.6246 | D16: 2836.6794 | E16: 1851.6532 | F16: 3690.0175 | G16: 1845.0688 | H16: 2203.2601 | I16: 2791.2474 | J16: 4967.5839 | K16: 2725.2978 | L16: 6910.0991 | M16: 2710.3092 | N16: 3525.686 | O16: =(B16-C16)/($AC$3-$AC$2) -> 142.57745 | P16: =(B16-D16)/($AC$3-$AC$2) -> 376.50326 | Q16: =(B16-E16)/($AC$4-$AC$2) -> 150.39182 | R16: =(B16-F16)/($AC$4-$AC$2) -> 649.67598 | S16: =(B16-G16)/($AC$5-$AC$2) -> 131.71842 | T16: =(B16-H16)/($AC$5-$AC$2) -> 217.94647 | U16: =(B16-I16)/($AC$6-$AC$2) -> 285.42371 | V16: =(B16-J16)/($AC$6-$AC$2) -> 701.39016 | W16: =(B16-K16)/($AC$7-$AC$2) -> 365.15407 | X16: =(B16-L16)/($AC$7-$AC$2) -> 1435.7095 | Y16: =(B16-M16)/($AC$8-$AC$2) -> 259.15573 | Z16: =(B16-N16)/($AC$8-$AC$2) -> 408.76614
