Workbook

Sheet BAU breakdown
B1: Natural gas | C1: Water | D1: Nitrogen | E1: Hydrogen | F1: Electricity | G1: Other utilities | H1: CAPEX | I1: Fixed costs | J1: Total | K1: Low | L1: High
A2: Jan '19 | B2: 171.80479 | C2: 0.14728914 | D2: 0 | E2: 0 | F2: 46.217649 | G2: 50.640799 | H2: 133.05437 | I2: 68.199818 | J2: 470.06471 | K2: 0 | L2: 0 | M2: =(H2+I2)/J2*100 -> 42.814144
A3: Feb '19 | B3: 141.44477 | C3: 0.14728914 | D3: 0 | E3: 0 | F3: 40.044071 | G3: 50.640799 | H3: 133.05437 | I3: 68.199818 | J3: 433.53111 | K3: 0 | L3: 0 | M3: =(H3+I3)/J3*100 -> 46.422086
A4: Mar '19 | B4: 121.9108 | C4: 0.14728914 | D4: 0 | E4: 0 | F4: 28.632306 | G4: 50.640799 | H4: 133.05437 | I4: 68.199818 | J4: 402.58538 | K4: 0 | L4: 0 | M4: =(H4+I4)/J4*100 -> 49.990436
A5: Apr '19 | B5: 115.79172 | C5: 0.14728914 | D5: 0 | E5: 0 | F5: 34.58139 | G5: 50.640799 | H5: 133.05437 | I5: 68.199818 | J5: 402.41539 | K5: 0 | L5: 0 | M5: =(H5+I5)/J5*100 -> 50.011553
A6: May '19 | B6: 102.14148 | C6: 0.14728914 | D6: 0 | E6: 0 | F6: 35.385826 | G6: 50.640799 | H6: 133.05437 | I6: 68.199818 | J6: 389.56958 | K6: 0 | L6: 0 | M6: =(H6+I6)/J6*100 -> 51.660652
A7: Jun '19 | B7: 84.490301 | C7: 0.14728914 | D7: 0 | E7: 0 | F7: 30.400194 | G7: 50.640799 | H7: 133.05437 | I7: 68.199818 | J7: 366.93277 | K7: 0 | L7: 0 | M7: =(H7+I7)/J7*100 -> 54.8477
A8: Jul '19 | B8: 85.196349 | C8: 0.14728914 | D8: 0 | E8: 0 | F8: 37.14436 | G8: 50.640799 | H8: 133.05437 | I8: 68.199818 | J8: 374.38298 | K8: 0 | L8: 0 | M8: =(H8+I8)/J8*100 -> 53.756232
A9: Aug '19 | B9: 86.608443 | C9: 0.14728914 | D9: 0 | E9: 0 | F9: 34.441081 | G9: 50.640799 | H9: 133.05437 | I9: 68.199818 | J9: 373.0918 | K9: 0 | L9: 0 | M9: =(H9+I9)/J9*100 -> 53.94227
A10: Sep '19 | B10: 99.081941 | C10: 0.14728914 | D10: 0 | E10: 0 | F10: 33.458921 | G10: 50.640799 | H10: 133.05437 | I10: 68.199818 | J10: 384.58314 | K10: 0 | L10: 0 | M10: =(H10+I10)/J10*100 -> 52.330476
A11: Oct '19 | B11: 119.08661 | C11: 0.14728914 | D11: 0 | E11: 0 | F11: 34.562682 | G11: 50.640799 | H11: 133.05437 | I11: 68.199818 | J11: 405.69156 | K11: 0 | L11: 0 | M11: =(H11+I11)/J11*100 -> 49.607683
A12: Nov '19 | B12: 121.20475 | C12: 0.14728914 | D12: 0 | E12: 0 | F12: 38.351014 | G12: 50.640799 | H12: 133.05437 | I12: 68.199818 | J12: 411.59804 | K12: 0 | L12: 0 | M12: =(H12+I12)/J12*100 -> 48.895808
A13: Dec '19 | B13: 108.73125 | C13: 0.14728914 | D13: 0 | E13: 0 | F13: 29.904437 | G13: 50.640799 | H13: 133.05437 | I13: 68.199818 | J13: 390.67796 | K13: 0 | L13: 0 | M13: =(H13+I13)/J13*100 -> 51.514087
... A42: May '22 | B42: 686.51312 | C42: 0.1982039 | D42: 0 | E42: 0 | F42: 166.04118 | G42: 68.146261 | H42: 179.04847 | I42: 91.775063 | J42: 1191.7223 | K42: 0 | L42: 0 | M42: =(H42+I42)/J42*100 -> 22.725389
A43: Jun '22 | B43: 789.83134 | C43: 0.1982039 | D43: 0 | E43: 0 | F43: 204.08352 | G43: 68.146261 | H43: 179.04847 | I43: 91.775063 | J43: 1333.0829 | K43: 0 | L43: 0 | M43: =(H43+I43)/J43*100 -> 20.315581 | T43: kg NG/kg H2 | U43: 3.9582
A44: Jul '22 | B44: 1208.0466 | C44: 0.1982039 | D44: 0 | E44: 0 | F44: 294.89123 | G44: 68.146261 | H44: 179.04847 | I44: 91.775063 | J44: 1842.1058 | K44: 0 | L44: 0 | M44: =(H44+I44)/J44*100 -> 14.701845 | T44: without NG | U44: 1.0304
A45: Aug '22 | B45: 1648.3846 | C45: 0.1982039 | D45: 0 | E45: 0 | F45: 439.02557 | G45: 68.146261 | H45: 179.04847 | I45: 91.775063 | J45: 2426.5782 | K45: 0 | L45: 0 | M45: =(H45+I45)/J45*100 -> 11.160717
A46: Sep '22 | B46: 1390.9128 | C46: 0.1982039 | D46: 0 | E46: 0 | F46: 336.90898 | G46: 68.146261 | H46: 179.04847 | I46: 91.775063 | J46: 2066.9897 | K46: 0 | L46: 0 | M46: =(H46+I46)/J46*100 -> 13.102316
A47: Oct '22 | B47: 918.33191 | C47: 0.1982039 | D47: 0 | E47: 0 | F47: 147.58593 | G47: 68.146261 | H47: 179.04847 | I47: 91.775063 | J47: 1405.0858 | K47: 0 | L47: 0 | M47: =(H47+I47)/J47*100 -> 19.274519
A48: Nov '22 | B48: 840.66673 | C48: 0.1982039 | D48: 0 | E48: 0 | F48: 164.11428 | G48: 68.146261 | H48: 179.04847 | I48: 91.775063 | J48: 1343.949 | K48: 0 | L48: 0 | M48: =(H48+I48)/J48*100 -> 20.151325

Sheet Wind breakdown
B1: Natural gas | C1: Water | D1: Nitrogen | E1: Hydrogen | F1: Electricity | G1: Other utilities | H1: CAPEX | I1: Fixed costs | J1: Total | K1: Low | L1: High
A2: Jan '19 | B2: 0 | C2: 0 | D2: 74.249053 | E2: 1212.6512 | F2: 23.21746 | G2: 1.3444517 | H2: 79.928127 | I2: 49.134161 | J2: 1440.5245 | K2: 290.74872 | L2: 281.05709 | M2: =E2/J2*100 -> 84.18123 | N2: =F2/J2*100 -> 1.6117366
A3: Feb '19 | B3: 0 | C3: 0 | D3: 74.249053 | E3: 1212.6512 | F3: 20.11616 | G3: 1.3444517 | H3: 79.928127 | I3: 49.134161 | J3: 1437.4232 | K3: 290.74872 | L3: 281.05709 | M3: =E3/J3*100 -> 84.362855 | N3: =F3/J3*100 -> 1.3994598
A4: Mar '19 | B4: 0 | C4: 0 | D4: 74.249053 | E4: 1212.6512 | F4: 14.383454 | G4: 1.3444517 | H4: 79.928127 | I4: 49.134161 | J4: 1431.6905 | K4: 290.74872 | L4: 281.05709 | M4: =E4/J4*100 -> 84.700656 | N4: =F4/J4*100 -> 1.0046483
A5: Apr '19 | B5: 0 | C5: 0 | D5: 74.249053 | E5: 1212.6512 | F5: 17.371979 | G5: 1.3444517 | H5: 79.928127 | I5: 49.134161 | J5: 1434.679 | K5: 290.74872 | L5: 281.05709 | M5: =E5/J5*100 -> 84.52422 | N5: =F5/J5*100 -> 1.2108618
A6: May '19 | B6: 0 | C6: 0 | D6: 74.249053 | E6: 1212.6512 | F6: 17.776088 | G6: 1.3444517 | H6: 79.928127 | I6: 49.134161 | J6: 1435.0831 | K6: 290.74872 | L6: 281.05709 | M6: =E6/J6*100 -> 84.500418 | N6: =F6/J6*100 -> 1.2386801
A7: Jun '19 | B7: 0 | C7: 0 | D7: 74.249053 | E7: 1212.6512 | F7: 15.271553 | G7: 1.3444517 | H7: 79.928127 | I7: 49.134161 | J7: 1432.5786 | K7: 290.74872 | L7: 281.05709 | M7: =E7/J7*100 -> 84.648148 | N7: =F7/J7*100 -> 1.0660186
A8: Jul '19 | B8: 0 | C8: 0 | D8: 74.249053 | E8: 1212.6512 | F8: 18.659489 | G8: 1.3444517 | H8: 79.928127 | I8: 49.134161 | J8: 1435.9665 | K8: 290.74872 | L8: 281.05709 | M8: =E8/J8*100 -> 84.448434 | N8: =F8/J8*100 -> 1.2994376
A9: Aug '19 | B9: 0 | C9: 0 | D9: 74.249053 | E9: 1212.6512 | F9: 17.301495 | G9: 1.3444517 | H9: 79.928127 | I9: 49.134161 | J9: 1434.6085 | K9: 290.74872 | L9: 281.05709 | M9: =E9/J9*100 -> 84.528372 | N9: =F9/J9*100 -> 1.2060081
A10: Sep '19 | B10: 0 | C10: 0 | D10: 74.249053 | E10: 1212.6512 | F10: 16.808107 | G10: 1.3444517 | H10: 79.928127 | I10: 49.134161 | J10: 1434.1151 | K10: 290.74872 | L10: 281.05709 | M10: =E10/J10*100 -> 84.557453 | N10: =F10/J10*100 -> 1.1720193
A11: Oct '19 | B11: 0 | C11: 0 | D11: 74.249053 | E11: 1212.6512 | F11: 17.362582 | G11: 1.3444517 | H11: 79.928127 | I11: 49.134161 | J11: 1434.6696 | K11: 290.74872 | L11: 281.05709 | M11: =E11/J11*100 -> 84.524773 | N11: =F11/J11*100 -> 1.2102146
A12: Nov '19 | B12: 0 | C12: 0 | D12: 74.249053 | E12: 1212.6512 | F12: 19.265652 | G12: 1.3444517 | H12: 79.928127 | I12: 49.134161 | J12: 1436.5727 | K12: 290.74872 | L12: 281.05709 | M12: =E12/J12*100 -> 84.412801 | N12: =F12/J12*100 -> 1.3410844
A13: Dec '19 | B13: 0 | C13: 0 | D13: 74.249053 | E13: 1212.6512 | F13: 15.02251 | G13: 1.3444517 | H13: 79.928127 | I13: 49.134161 | J13: 1432.3295 | K13: 290.74872 | L13: 281.05709 | M13: =E13/J13*100 -> 84.662866 | N13: =F13/J13*100 -> 1.0488166
... A48: Nov '22 | B48: 0 | C48: 0 | D48: 99.915392 | E48: 1094.3941 | F48: 82.442894 | G48: 1.8092004 | H48: 107.5576 | I48: 66.118809 | J48: 1452.238 | K48: 179.04864 | L48: 190.23918 | M48: =E48/J48*100 -> 75.359143 | N48: =F48/J48*100 -> 5.6769546

Sheet Solar breakdown
B1: Natural gas | C1: Water | D1: Nitrogen | E1: Hydrogen | F1: Electricity | G1: Other utilities | H1: CAPEX | I1: Fixed costs | J1: Total | K1: Low | L1: High
A2: Jan '19 | B2: 0 | C2: 0 | D2: 74.249053 | E2: 1624.0518 | F2: 23.21746 | G2: 1.3444517 | H2: 79.928127 | I2: 49.134161 | J2: 1851.9251 | K2: 155.06598 | L2: 1182.3781
A3: Feb '19 | B3: 0 | C3: 0 | D3: 74.249053 | E3: 1624.0518 | F3: 20.11616 | G3: 1.3444517 | H3: 79.928127 | I3: 49.134161 | J3: 1848.8238 | K3: 155.06598 | L3: 1182.3781
A4: Mar '19 | B4: 0 | C4: 0 | D4: 74.249053 | E4: 1624.0518 | F4: 14.383454 | G4: 1.3444517 | H4: 79.928127 | I4: 49.134161 | J4: 1843.0911 | K4: 155.06598 | L4: 1182.3781
A5: Apr '19 | B5: 0 | C5: 0 | D5: 74.249053 | E5: 1624.0518 | F5: 17.371979 | G5: 1.3444517 | H5: 79.928127 | I5: 49.134161 | J5: 1846.0796 | K5: 155.06598 | L5: 1182.3781
A6: May '19 | B6: 0 | C6: 0 | D6: 74.249053 | E6: 1624.0518 | F6: 17.776088 | G6: 1.3444517 | H6: 79.928127 | I6: 49.134161 | J6: 1846.4837 | K6: 155.06598 | L6: 1182.3781
A7: Jun '19 | B7: 0 | C7: 0 | D7: 74.249053 | E7: 1624.0518 | F7: 15.271553 | G7: 1.3444517 | H7: 79.928127 | I7: 49.134161 | J7: 1843.9792 | K7: 155.06598 | L7: 1182.3781
A8: Jul '19 | B8: 0 | C8: 0 | D8: 74.249053 | E8: 1624.0518 | F8: 18.659489 | G8: 1.3444517 | H8: 79.928127 | I8: 49.134161 | J8: 1847.3671 | K8: 155.06598 | L8: 1182.3781
A9: Aug '19 | B9: 0 | C9: 0 | D9: 74.249053 | E9: 1624.0518 | F9: 17.301495 | G9: 1.3444517 | H9: 79.928127 | I9: 49.134161 | J9: 1846.0091 | K9: 155.06598 | L9: 1182.3781
A10: Sep '19 | B10: 0 | C10: 0 | D10: 74.249053 | E10: 1624.0518 | F10: 16.808107 | G10: 1.3444517 | H10: 79.928127 | I10: 49.134161 | J10: 1845.5157 | K10: 155.06598 | L10: 1182.3781
A11: Oct '19 | B11: 0 | C11: 0 | D11: 74.249053 | E11: 1624.0518 | F11: 17.362582 | G11: 1.3444517 | H11: 79.928127 | I11: 49.134161 | J11: 1846.0702 | K11: 155.06598 | L11: 1182.3781
A12: Nov '19 | B12: 0 | C12: 0 | D12: 74.249053 | E12: 1624.0518 | F12: 19.265652 | G12: 1.3444517 | H12: 79.928127 | I12: 49.134161 | J12: 1847.9733 | K12: 155.06598 | L12: 1182.3781
A13: Dec '19 | B13: 0 | C13: 0 | D13: 74.249053 | E13: 1624.0518 | F13: 15.02251 | G13: 1.3444517 | H13: 79.928127 | I13: 49.134161 | J13: 1843.7301 | K13: 155.06598 | L13: 1182.3781
... A48: Nov '22 | B48: 0 | C48: 0 | D48: 99.915392 | E48: 1670.8697 | F48: 82.442894 | G48: 1.8092004 | H48: 107.5576 | I48: 66.118809 | J48: 2028.7136 | K48: 212.62027 | L48: 805.7189

Sheet SMR CCS breakdown
B1: Natural gas | C1: Water | D1: Nitrogen | E1: Hydrogen | F1: Electricity | G1: Other utilities | H1: CAPEX | I1: Fixed costs | J1: Total | K1: Low | L1: High
A2: Jan '19 | B2: 0 | C2: 0 | D2: 74.249053 | E2: 409.06931 | F2: 23.21746 | G2: 1.3444517 | H2: 79.928127 | I2: 49.134161 | J2: 636.94256 | K2: 0 | L2: 0
A3: Feb '19 | B3: 0 | C3: 0 | D3: 74.249053 | E3: 368.8669 | F3: 20.11616 | G3: 1.3444517 | H3: 79.928127 | I3: 49.134161 | J3: 593.63885 | K3: 0 | L3: 0
A4: Mar '19 | B4: 0 | C4: 0 | D4: 74.249053 | E4: 343.00024 | F4: 14.383454 | G4: 1.3444517 | H4: 79.928127 | I4: 49.134161 | J4: 562.03949 | K4: 0 | L4: 0
A5: Apr '19 | B5: 0 | C5: 0 | D5: 74.249053 | E5: 334.89743 | F5: 17.371979 | G5: 1.3444517 | H5: 79.928127 | I5: 49.134161 | J5: 556.9252 | K5: 0 | L5: 0
A6: May '19 | B6: 0 | C6: 0 | D6: 74.249053 | E6: 316.82193 | F6: 17.776088 | G6: 1.3444517 | H6: 79.928127 | I6: 49.134161 | J6: 539.25381 | K6: 0 | L6: 0
A7: Jun '19 | B7: 0 | C7: 0 | D7: 74.249053 | E7: 293.44844 | F7: 15.271553 | G7: 1.3444517 | H7: 79.928127 | I7: 49.134161 | J7: 513.37579 | K7: 0 | L7: 0
A8: Jul '19 | B8: 0 | C8: 0 | D8: 74.249053 | E8: 294.38338 | F8: 18.659489 | G8: 1.3444517 | H8: 79.928127 | I8: 49.134161 | J8: 517.69866 | K8: 0 | L8: 0
A9: Aug '19 | B9: 0 | C9: 0 | D9: 74.249053 | E9: 296.25326 | F9: 17.301495 | G9: 1.3444517 | H9: 79.928127 | I9: 49.134161 | J9: 518.21055 | K9: 0 | L9: 0
A10: Sep '19 | B10: 0 | C10: 0 | D10: 74.249053 | E10: 312.77053 | F10: 16.808107 | G10: 1.3444517 | H10: 79.928127 | I10: 49.134161 | J10: 534.23443 | K10: 0 | L10: 0
A11: Oct '19 | B11: 0 | C11: 0 | D11: 74.249053 | E11: 339.26048 | F11: 17.362582 | G11: 1.3444517 | H11: 79.928127 | I11: 49.134161 | J11: 561.27886 | K11: 0 | L11: 0
A12: Nov '19 | B12: 0 | C12: 0 | D12: 74.249053 | E12: 342.0653 | F12: 19.265652 | G12: 1.3444517 | H12: 79.928127 | I12: 49.134161 | J12: 565.98675 | K12: 0 | L12: 0
A13: Dec '19 | B13: 0 | C13: 0 | D13: 74.249053 | E13: 325.54804 | F13: 15.02251 | G13: 1.3444517 | H13: 79.928127 | I13: 49.134161 | J13: 545.22634 | K13: 0 | L13: 0
... A48: Nov '22 | B48: 0 | C48: 0 | D48: 99.915392 | E48: 1357.5328 | F48: 82.442894 | G48: 1.8092004 | H48: 107.5576 | I48: 66.118809 | J48: 1715.3767 | K48: 0 | L48: 0

Sheet Summary
A1: Time | B1: Natural gas | C1: Water | D1: Nitrogen | E1: Hydrogen | F1: Electricity | G1: Other utilities | H1: CAPEX | I1: Fixed costs | J1: Total | K1: Low | L1: High
A2: Avg 19 | B2: =AVERAGE('BAU breakdown'!B2:B13) -> 113.12443 | C2: =AVERAGE('BAU breakdown'!C2:C13) -> 0.14728914 | D2: =AVERAGE('BAU breakdown'!D2:D13) -> 0 | E2: =AVERAGE('BAU breakdown'!E2:E13) -> 0 | F2: =AVERAGE('BAU breakdown'!F2:F13) -> 35.260327 | G2: =AVERAGE('BAU breakdown'!G2:G13) -> 50.640799 | H2: =AVERAGE('BAU breakdown'!H2:H13) -> 133.05437 | I2: =AVERAGE('BAU breakdown'!I2:I13) -> 68.199818 | J2: =AVERAGE('BAU breakdown'!J2:J13) -> 400.42703
A3: Avg 19 | B3: =AVERAGE('Wind breakdown'!B2:B13) -> 0 | C3: =AVERAGE('Wind breakdown'!C2:C13) -> 0 | D3: =AVERAGE('Wind breakdown'!D2:D13) -> 74.249053 | E3: =AVERAGE('Wind breakdown'!E2:E13) -> 1212.6512 | F3: =AVERAGE('Wind breakdown'!F2:F13) -> 17.713044 | G3: =AVERAGE('Wind breakdown'!G2:G13) -> 1.3444517 | H3: =AVERAGE('Wind breakdown'!H2:H13) -> 79.928127 | I3: =AVERAGE('Wind breakdown'!I2:I13) -> 49.134161 | J3: =AVERAGE('Wind breakdown'!J2:J13) -> 1435.0201 | K3: 270.5459 | L3: 261.53865
A4: Avg 19 | B4: 0 | C4: 0 | D4: 0 | E4: 0 | F4: 0 | G4: 0 | H4: 0 | I4: 0 | J4: 0
A5: Avg 20 | B5: =AVERAGE('BAU breakdown'!B14:B25) -> 76.311923 | C5: =AVERAGE('BAU breakdown'!C14:C25) -> 0.14454944 | D5: =AVERAGE('BAU breakdown'!D14:D25) -> 0 | E5: =AVERAGE('BAU breakdown'!E14:E25) -> 0 | F5: =AVERAGE('BAU breakdown'!F14:F25) -> 28.470171 | G5: =AVERAGE('BAU breakdown'!G14:G25) -> 49.698839 | H5: =AVERAGE('BAU breakdown'!H14:H25) -> 130.57945 | I5: =AVERAGE('BAU breakdown'!I14:I25) -> 66.931245 | J5: =AVERAGE('BAU breakdown'!J14:J25) -> 352.13617
A6: Avg 20 | B6: =AVERAGE('Wind breakdown'!B14:B25) -> 0 | C6: =AVERAGE('Wind breakdown'!C14:C25) -> 0 | D6: =AVERAGE('Wind breakdown'!D14:D25) -> 72.867959 | E6: =AVERAGE('Wind breakdown'!E14:E25) -> 993.16237 | F6: =AVERAGE('Wind breakdown'!F14:F25) -> 14.302006 | G6: =AVERAGE('Wind breakdown'!G14:G25) -> 1.3194438 | H6: =AVERAGE('Wind breakdown'!H14:H25) -> 78.441398 | I6: =AVERAGE('Wind breakdown'!I14:I25) -> 48.220225 | J6: =AVERAGE('Wind breakdown'!J14:J25) -> 1208.3134 | K6: 90.18382 | L6: 180.36764
A7: Avg 20 | B7: 0 | C7: 0 | D7: 0 | E7: 0 | F7: 0 | G7: 0 | H7: 0 | I7: 0 | J7: 0
A8: Jul '21 | B8: ='BAU breakdown'!B32 -> 294.42164 | C8: ='BAU breakdown'!C32 -> 0.17165549 | D8: ='BAU breakdown'!D32 -> 0 | E8: ='BAU breakdown'!E32 -> 0 | F8: ='BAU breakdown'!F32 -> 76.0379 | G8: ='BAU breakdown'!G32 -> 59.018413 | H8: ='BAU breakdown'!H32 -> 155.06583 | I8: ='BAU breakdown'!I32 -> 79.482257 | J8: ='BAU breakdown'!J32 -> 664.19769
A9: Jul '21 | B9: ='Wind breakdown'!B32 -> 0 | C9: ='Wind breakdown'!C32 -> 0 | D9: ='Wind breakdown'!D32 -> 86.532229 | E9: ='Wind breakdown'!E32 -> 947.80557 | F9: ='Wind breakdown'!F32 -> 38.197679 | G9: ='Wind breakdown'!G32 -> 1.5668671 | H9: ='Wind breakdown'!H32 -> 93.150804 | I9: ='Wind breakdown'!I32 -> 57.262528 | ... L9: ='Wind breakdown'!L32 -> 164.75761
A10: Jul '21 | B10: 0 | C10: 0 | D10: 0 | E10: 0 | F10: 0 | G10: 0 | H10: 0 | I10: 0 | J10: 0
A11: Oct '21 | B11: ='BAU breakdown'!B35 -> 730.75874 | C11: ='BAU breakdown'!C35 -> 0.17165549 | D11: ='BAU breakdown'!D35 -> 0 | E11: ='BAU breakdown'!E35 -> 0 | F11: ='BAU breakdown'!F35 -> 130.5244 | G11: ='BAU breakdown'!G35 -> 59.018413 | H11: ='BAU breakdown'!H35 -> 155.06583 | I11: ='BAU breakdown'!I35 -> 79.482257 | J11: ='BAU breakdown'!J35 -> 1155.0213
A12: Oct '21 | B12: ='Wind breakdown'!B35 -> 0 | C12: ='Wind breakdown'!C35 -> 0 | D12: ='Wind breakdown'!D35 -> 86.532229 | E12: ='Wind breakdown'!E35 -> 947.80557 | F12: ='Wind breakdown'!F35 -> 65.569002 | G12: ='Wind breakdown'!G35 -> 1.5668671 | H12: ='Wind breakdown'!H35 -> 93.150804 | I12: ='Wind breakdown'!I35 -> 57.262528 | ... L12: ='Wind breakdown'!L35 -> 164.75761
A13: Oct '21 | B13: 0 | C13: 0 | D13: 0 | E13: 0 | F13: 0 | G13: 0 | H13: 0 | I13: 0 | J13: 0
A14: Jan '22 | B14: ='BAU breakdown'!B38 -> 665.09636 | C14: ='BAU breakdown'!C38 -> 0.1982039 | D14: ='BAU breakdown'!D38 -> 0 | E14: ='BAU breakdown'!E38 -> 0 | F14: ='BAU breakdown'!F38 -> 157.02402 | G14: ='BAU breakdown'!G38 -> 68.146261 | H14: ='BAU breakdown'!H38 -> 179.04847 | I14: ='BAU breakdown'!I38 -> 91.775063 | J14: ='BAU breakdown'!J38 -> 1161.2884
A15: Jan '22 | B15: ='Wind breakdown'!B38 -> 0 | C15: ='Wind breakdown'!C38 -> 0 | D15: ='Wind breakdown'!D38 -> 99.915392 | E15: ='Wind breakdown'!E38 -> 1094.3941 | F15: ='Wind breakdown'!F38 -> 78.881098 | G15: ='Wind breakdown'!G38 -> 1.8092004 | H15: ='Wind breakdown'!H38 -> 107.5576 | I15: ='Wind breakdown'!I38 -> 66.118809 | ... L15: ='Wind breakdown'!L38 -> 190.23918
A16: Jan '22 | B16: 0 | C16: 0 | D16: 0 | E16: 0 | F16: 0 | G16: 0 | H16: 0 | I16: 0 | J16: 0
A17: Apr '22 | B17: ='BAU breakdown'!B41 -> 757.82387 | C17: ='BAU breakdown'!C41 -> 0.1982039 | D17: ='BAU breakdown'!D41 -> 0 | E17: ='BAU breakdown'!E41 -> 0 | F17: ='BAU breakdown'!F41 -> 155.27484 | G17: ='BAU breakdown'!G41 -> 68.146261 | H17: ='BAU breakdown'!H41 -> 179.04847 | I17: ='BAU breakdown'!I41 -> 91.775063 | J17: ='BAU breakdown'!J41 -> 1252.2667
A18: Apr '22 | B18: ='Wind breakdown'!B41 -> 0 | C18: ='Wind breakdown'!C41 -> 0 | D18: ='Wind breakdown'!D41 -> 99.915392 | E18: ='Wind breakdown'!E41 -> 1094.3941 | F18: ='Wind breakdown'!F41 -> 78.002396 | G18: ='Wind breakdown'!G41 -> 1.8092004 | H18: ='Wind breakdown'!H41 -> 107.5576 | I18: ='Wind breakdown'!I41 -> 66.118809 | ... L18: ='Wind breakdown'!L41 -> 190.23918
A19: Apr '22 | B19: 0 | C19: 0 | D19: 0 | E19: 0 | F19: 0 | G19: 0 | H19: 0 | I19: 0 | J19: 0
A20: Jul '22 | B20: ='BAU breakdown'!B44 -> 1208.0466 | C20: ='BAU breakdown'!C44 -> 0.1982039 | D20: ='BAU breakdown'!D44 -> 0 | E20: ='BAU breakdown'!E44 -> 0 | F20: ='BAU breakdown'!F44 -> 294.89123 | G20: ='BAU breakdown'!G44 -> 68.146261 | H20: ='BAU breakdown'!H44 -> 179.04847 | I20: ='BAU breakdown'!I44 -> 91.775063 | J20: ='BAU breakdown'!J44 -> 1842.1058
A21: Jul '22 | B21: ='Wind breakdown'!B44 -> 0 | C21: ='Wind breakdown'!C44 -> 0 | D21: ='Wind breakdown'!D44 -> 99.915392 | E21: ='Wind breakdown'!E44 -> 1094.3941 | F21: ='Wind breakdown'!F44 -> 148.13877 | G21: ='Wind breakdown'!G44 -> 1.8092004 | H21: ='Wind breakdown'!H44 -> 107.5576 | I21: ='Wind breakdown'!I44 -> 66.118809 | ... L21: ='Wind breakdown'!L44 -> 190.23918
A22: Jul '22 | B22: 0 | C22: 0 | D22: 0 | E22: 0 | F22: 0 | G22: 0 | H22: 0 | I22: 0 | J22: 0
A23: Aug '22 | B23: ='BAU breakdown'!B45 -> 1648.3846 | C23: ='BAU breakdown'!C45 -> 0.1982039 | D23: ='BAU breakdown'!D45 -> 0 | E23: ='BAU breakdown'!E45 -> 0 | F23: ='BAU breakdown'!F45 -> 439.02557 | G23: ='BAU breakdown'!G45 -> 68.146261 | H23: ='BAU breakdown'!H45 -> 179.04847 | I23: ='BAU breakdown'!I45 -> 91.775063 | J23: ='BAU breakdown'!J45 -> 2426.5782
A24: Aug '22 | B24: ='Wind breakdown'!B45 -> 0 | C24: ='Wind breakdown'!C45 -> 0 | D24: ='Wind breakdown'!D45 -> 99.915392 | E24: ='Wind breakdown'!E45 -> 1094.3941 | F24: ='Wind breakdown'!F45 -> 220.54473 | G24: ='Wind breakdown'!G45 -> 1.8092004 | H24: ='Wind breakdown'!H45 -> 107.5576 | I24: ='Wind breakdown'!I45 -> 66.118809 | ... L24: ='Wind breakdown'!L45 -> 190.23918
A25: Aug '22 | B25: 0 | C25: 0 | D25: 0 | E25: 0 | F25: 0 | G25: 0 | H25: 0 | I25: 0 | J25: 0
A26: Sep '22 | B26: ='BAU breakdown'!B46 -> 1390.9128 | C26: ='BAU breakdown'!C46 -> 0.1982039 | D26: ='BAU breakdown'!D46 -> 0 | E26: ='BAU breakdown'!E46 -> 0 | F26: ='BAU breakdown'!F46 -> 336.90898 | G26: ='BAU breakdown'!G46 -> 68.146261 | H26: ='BAU breakdown'!H46 -> 179.04847 | I26: ='BAU breakdown'!I46 -> 91.775063 | J26: ='BAU breakdown'!J46 -> 2066.9897
A27: Sep '22 | B27: ='Wind breakdown'!B46 -> 0 | C27: ='Wind breakdown'!C46 -> 0 | D27: ='Wind breakdown'!D46 -> 99.915392 | E27: ='Wind breakdown'!E46 -> 1094.3941 | F27: ='Wind breakdown'!F46 -> 169.2464 | G27: ='Wind breakdown'!G46 -> 1.8092004 | H27: ='Wind breakdown'!H46 -> 107.5576 | I27: ='Wind breakdown'!I46 -> 66.118809 | ... L27: ='Wind breakdown'!L46 -> 190.23918
A28: Sep '22 | B28: 0 | C28: 0 | D28: 0 | E28: 0 | F28: 0 | G28: 0 | H28: 0 | I28: 0 | J28: 0
A29: Nov '22 | B29: ='BAU breakdown'!B48 -> 840.66673 | C29: ='BAU breakdown'!C48 -> 0.1982039 | D29: ='BAU breakdown'!D48 -> 0 | E29: ='BAU breakdown'!E48 -> 0 | F29: ='BAU breakdown'!F48 -> 164.11428 | G29: ='BAU breakdown'!G48 -> 68.146261 | H29: ='BAU breakdown'!H48 -> 179.04847 | I29: ='BAU breakdown'!I48 -> 91.775063 | J29: ='BAU breakdown'!J48 -> 1343.949
A30: Nov '22 | B30: ='Wind breakdown'!B48 -> 0 | C30: ='Wind breakdown'!C48 -> 0 | D30: ='Wind breakdown'!D48 -> 99.915392 | E30: ='Wind breakdown'!E48 -> 1094.3941 | F30: ='Wind breakdown'!F48 -> 82.442894 | G30: ='Wind breakdown'!G48 -> 1.8092004 | H30: ='Wind breakdown'!H48 -> 107.5576 | I30: ='Wind breakdown'!I48 -> 66.118809 | ... L30: ='Wind breakdown'!L48 -> 190.23918
A31: Nov '22 | B31: 0 | C31: 0 | D31: 0 | E31: 0 | F31: 0 | G31: 0 | H31: 0 | I31: 0 | J31: 0

Sheet Summary SI
A1: Time | B1: Natural gas | C1: Water | D1: Nitrogen | E1: Hydrogen | F1: Electricity | G1: Other utilities | H1: CAPEX | I1: Fixed costs | J1: Total | K1: Low | L1: High
A2: Avg 19 | B2: =AVERAGE('BAU breakdown'!B2:B13) -> 113.12443 | C2: =AVERAGE('BAU breakdown'!C2:C13) -> 0.14728914 | D2: =AVERAGE('BAU breakdown'!D2:D13) -> 0 | E2: =AVERAGE('BAU breakdown'!E2:E13) -> 0 | F2: =AVERAGE('BAU breakdown'!F2:F13) -> 35.260327 | G2: =AVERAGE('BAU breakdown'!G2:G13) -> 50.640799 | H2: =AVERAGE('BAU breakdown'!H2:H13) -> 133.05437 | I2: =AVERAGE('BAU breakdown'!I2:I13) -> 68.199818 | J2: =AVERAGE('BAU breakdown'!J2:J13) -> 400.42703
A3: Avg 19 | B3: =AVERAGE('Wind breakdown'!B2:B13) -> 0 | C3: =AVERAGE('Wind breakdown'!C2:C13) -> 0 | D3: =AVERAGE('Wind breakdown'!D2:D13) -> 74.249053 | E3: =AVERAGE('Wind breakdown'!E2:E13) -> 1212.6512 | F3: =AVERAGE('Wind breakdown'!F2:F13) -> 17.713044 | G3: =AVERAGE('Wind breakdown'!G2:G13) -> 1.3444517 | H3: =AVERAGE('Wind breakdown'!H2:H13) -> 79.928127 | I3: =AVERAGE('Wind breakdown'!I2:I13) -> 49.134161 | J3: =AVERAGE('Wind breakdown'!J2:J13) -> 1435.0201 | K3: 270.5459 | L3: 261.53865
A4: Avg 19 | B4: =AVERAGE('Solar breakdown'!B2:B13) -> 0 | C4: =AVERAGE('Solar breakdown'!C2:C13) -> 0 | D4: =AVERAGE('Solar breakdown'!D2:D13) -> 74.249053 | E4: =AVERAGE('Solar breakdown'!E2:E13) -> 1624.0518 | F4: =AVERAGE('Solar breakdown'!F2:F13) -> 17.713044 | G4: =AVERAGE('Solar breakdown'!G2:G13) -> 1.3444517 | H4: =AVERAGE('Solar breakdown'!H2:H13) -> 79.928127 | I4: =AVERAGE('Solar breakdown'!I2:I13) -> 49.134161 | ... L4: =AVERAGE('Solar breakdown'!L2:L13) -> 1182.3781
A5: Avg 19 | B5: =AVERAGE('SMR CCS breakdown'!B2:B13) -> 0 | C5: =AVERAGE('SMR CCS breakdown'!C2:C13) -> 0 | D5: =AVERAGE('SMR CCS breakdown'!D2:D13) -> 74.249053 | E5: =AVERAGE('SMR CCS breakdown'!E2:E13) -> 331.36544 | F5: =AVERAGE('SMR CCS breakdown'!F2:F13) -> 17.713044 | G5: =AVERAGE('SMR CCS breakdown'!G2:G13) -> 1.3444517 | H5: =AVERAGE('SMR CCS breakdown'!H2:H13) -> 79.928127 | I5: =AVERAGE('SMR CCS breakdown'!I2:I13) -> 49.134161 | J5: =AVERAGE('SMR CCS breakdown'!J2:J13) -> 553.73427
A6: Avg 19 | B6: 0 | C6: 0 | D6: 0 | E6: 0 | F6: 0 | G6: 0 | H6: 0 | I6: 0 | J6: 0
A7: Avg 20 | B7: =AVERAGE('BAU breakdown'!B14:B25) -> 76.311923 | C7: =AVERAGE('BAU breakdown'!C14:C25) -> 0.14454944 | D7: =AVERAGE('BAU breakdown'!D14:D25) -> 0 | E7: =AVERAGE('BAU breakdown'!E14:E25) -> 0 | F7: =AVERAGE('BAU breakdown'!F14:F25) -> 28.470171 | G7: =AVERAGE('BAU breakdown'!G14:G25) -> 49.698839 | H7: =AVERAGE('BAU breakdown'!H14:H25) -> 130.57945 | I7: =AVERAGE('BAU breakdown'!I14:I25) -> 66.931245 | J7: =AVERAGE('BAU breakdown'!J14:J25) -> 352.13617
A8: Avg 20 | B8: =AVERAGE('Wind breakdown'!B14:B25) -> 0 | C8: =AVERAGE('Wind breakdown'!C14:C25) -> 0 | D8: =AVERAGE('Wind breakdown'!D14:D25) -> 72.867959 | E8: =AVERAGE('Wind breakdown'!E14:E25) -> 993.16237 | F8: =AVERAGE('Wind breakdown'!F14:F25) -> 14.302006 | G8: =AVERAGE('Wind breakdown'!G14:G25) -> 1.3194438 | H8: =AVERAGE('Wind breakdown'!H14:H25) -> 78.441398 | I8: =AVERAGE('Wind breakdown'!I14:I25) -> 48.220225 | J8: =AVERAGE('Wind breakdown'!J14:J25) -> 1208.3134 | K8: 90.18382 | L8: 180.36764
A9: Avg 20 | B9: =AVERAGE('Solar breakdown'!B14:B25) -> 0 | C9: =AVERAGE('Solar breakdown'!C14:C25) -> 0 | D9: =AVERAGE('Solar breakdown'!D14:D25) -> 72.867959 | E9: =AVERAGE('Solar breakdown'!E14:E25) -> 1594.2545 | F9: =AVERAGE('Solar breakdown'!F14:F25) -> 14.302006 | G9: =AVERAGE('Solar breakdown'!G14:G25) -> 1.3194438 | H9: =AVERAGE('Solar breakdown'!H14:H25) -> 78.441398 | I9: =AVERAGE('Solar breakdown'!I14:I25) -> 48.220225 | ... L9: =AVERAGE('Solar breakdown'!L14:L25) -> 1027.3121
A10: Avg 20 | B10: =AVERAGE('SMR CCS breakdown'!B14:B25) -> 0 | C10: =AVERAGE('SMR CCS breakdown'!C14:C25) -> 0 | D10: =AVERAGE('SMR CCS breakdown'!D14:D25) -> 72.867959 | E10: =AVERAGE('SMR CCS breakdown'!E14:E25) -> 279.24142 | F10: =AVERAGE('SMR CCS breakdown'!F14:F25) -> 14.302006 | G10: =AVERAGE('SMR CCS breakdown'!G14:G25) -> 1.3194438 | H10: =AVERAGE('SMR CCS breakdown'!H14:H25) -> 78.441398 | I10: =AVERAGE('SMR CCS breakdown'!I14:I25) -> 48.220225 | J10: =AVERAGE('SMR CCS breakdown'!J14:J25) -> 494.39246
A11: Avg 20 | B11: 0 | C11: 0 | D11: 0 | E11: 0 | F11: 0 | G11: 0 | H11: 0 | I11: 0 | J11: 0
A12: Jul '21 | B12: ='BAU breakdown'!B32 -> 294.42164 | C12: ='BAU breakdown'!C32 -> 0.17165549 | D12: ='BAU breakdown'!D32 -> 0 | E12: ='BAU breakdown'!E32 -> 0 | F12: ='BAU breakdown'!F32 -> 76.0379 | G12: ='BAU breakdown'!G32 -> 59.018413 | H12: ='BAU breakdown'!H32 -> 155.06583 | I12: ='BAU breakdown'!I32 -> 79.482257 | J12: ='BAU breakdown'!J32 -> 664.19769
A13: Jul '21 | B13: ='Wind breakdown'!B32 -> 0 | C13: ='Wind breakdown'!C32 -> 0 | D13: ='Wind breakdown'!D32 -> 86.532229 | E13: ='Wind breakdown'!E32 -> 947.80557 | F13: ='Wind breakdown'!F32 -> 38.197679 | G13: ='Wind breakdown'!G32 -> 1.5668671 | H13: ='Wind breakdown'!H32 -> 93.150804 | I13: ='Wind breakdown'!I32 -> 57.262528 | ... L13: ='Wind breakdown'!L32 -> 164.75761
A14: Jul '21 | B14: ='Solar breakdown'!B32 -> 0 | C14: ='Solar breakdown'!C32 -> 0 | D14: ='Solar breakdown'!D32 -> 86.532229 | E14: ='Solar breakdown'!E32 -> 1447.0652 | F14: ='Solar breakdown'!F32 -> 38.197679 | G14: ='Solar breakdown'!G32 -> 1.5668671 | H14: ='Solar breakdown'!H32 -> 93.150804 | I14: ='Solar breakdown'!I32 -> 57.262528 | ... L14: ='Solar breakdown'!L32 -> 697.79692
A15: Jul '21 | B15: ='SMR CCS breakdown'!B32 -> 0 | C15: ='SMR CCS breakdown'!C32 -> 0 | D15: ='SMR CCS breakdown'!D32 -> 86.532229 | E15: ='SMR CCS breakdown'!E32 -> 601.47421 | F15: ='SMR CCS breakdown'!F32 -> 38.197679 | G15: ='SMR CCS breakdown'!G32 -> 1.5668671 | H15: ='SMR CCS breakdown'!H32 -> 93.150804 | I15: ='SMR CCS breakdown'!I32 -> 57.262528 | J15: ='SMR CCS breakdown'!J32 -> 878.18432
A16: Jul '21 | B16: 0 | C16: 0 | D16: 0 | E16: 0 | F16: 0 | G16: 0 | H16: 0 | I16: 0 | J16: 0
A17: Oct '21 | B17: ='BAU breakdown'!B35 -> 730.75874 | C17: ='BAU breakdown'!C35 -> 0.17165549 | D17: ='BAU breakdown'!D35 -> 0 | E17: ='BAU breakdown'!E35 -> 0 | F17: ='BAU breakdown'!F35 -> 130.5244 | G17: ='BAU breakdown'!G35 -> 59.018413 | H17: ='BAU breakdown'!H35 -> 155.06583 | I17: ='BAU breakdown'!I35 -> 79.482257 | J17: ='BAU breakdown'!J35 -> 1155.0213
A18: Oct '21 | B18: ='Wind breakdown'!B35 -> 0 | C18: ='Wind breakdown'!C35 -> 0 | D18: ='Wind breakdown'!D35 -> 86.532229 | E18: ='Wind breakdown'!E35 -> 947.80557 | F18: ='Wind breakdown'!F35 -> 65.569002 | G18: ='Wind breakdown'!G35 -> 1.5668671 | H18: ='Wind breakdown'!H35 -> 93.150804 | I18: ='Wind breakdown'!I35 -> 57.262528 | ... L18: ='Wind breakdown'!L35 -> 164.75761
A19: Oct '21 | B19: ='Solar breakdown'!B35 -> 0 | C19: ='Solar breakdown'!C35 -> 0 | D19: ='Solar breakdown'!D35 -> 86.532229 | E19: ='Solar breakdown'!E35 -> 1447.0652 | F19: ='Solar breakdown'!F35 -> 65.569002 | G19: ='Solar breakdown'!G35 -> 1.5668671 | H19: ='Solar breakdown'!H35 -> 93.150804 | I19: ='Solar breakdown'!I35 -> 57.262528 | ... L19: ='Solar breakdown'!L35 -> 697.79692
A20: Oct '21 | B20: ='SMR CCS breakdown'!B35 -> 0 | C20: ='SMR CCS breakdown'!C35 -> 0 | D20: ='SMR CCS breakdown'!D35 -> 86.532229 | E20: ='SMR CCS breakdown'!E35 -> 1179.2669 | F20: ='SMR CCS breakdown'!F35 -> 65.569002 | G20: ='SMR CCS breakdown'!G35 -> 1.5668671 | H20: ='SMR CCS breakdown'!H35 -> 93.150804 | I20: ='SMR CCS breakdown'!I35 -> 57.262528 | J20: ='SMR CCS breakdown'!J35 -> 1483.3483
A21: Oct '21 | B21: 0 | C21: 0 | D21: 0 | E21: 0 | F21: 0 | G21: 0 | H21: 0 | I21: 0 | J21: 0
A22: Jan '22 | B22: ='BAU breakdown'!B38 -> 665.09636 | C22: ='BAU breakdown'!C38 -> 0.1982039 | D22: ='BAU breakdown'!D38 -> 0 | E22: ='BAU breakdown'!E38 -> 0 | F22: ='BAU breakdown'!F38 -> 157.02402 | G22: ='BAU breakdown'!G38 -> 68.146261 | H22: ='BAU breakdown'!H38 -> 179.04847 | I22: ='BAU breakdown'!I38 -> 91.775063 | J22: ='BAU breakdown'!J38 -> 1161.2884
A23: Jan '22 | B23: ='Wind breakdown'!B38 -> 0 | C23: ='Wind breakdown'!C38 -> 0 | D23: ='Wind breakdown'!D38 -> 99.915392 | E23: ='Wind breakdown'!E38 -> 1094.3941 | F23: ='Wind breakdown'!F38 -> 78.881098 | G23: ='Wind breakdown'!G38 -> 1.8092004 | H23: ='Wind breakdown'!H38 -> 107.5576 | I23: ='Wind breakdown'!I38 -> 66.118809 | ... L23: ='Wind breakdown'!L38 -> 190.23918
A24: Jan '22 | B24: ='Solar breakdown'!B38 -> 0 | C24: ='Solar breakdown'!C38 -> 0 | D24: ='Solar breakdown'!D38 -> 99.915392 | E24: ='Solar breakdown'!E38 -> 1670.8697 | F24: ='Solar breakdown'!F38 -> 78.881098 | G24: ='Solar breakdown'!G38 -> 1.8092004 | H24: ='Solar breakdown'!H38 -> 107.5576 | I24: ='Solar breakdown'!I38 -> 66.118809 | ... L24: ='Solar breakdown'!L38 -> 805.7189
A25: Jan '22 | B25: ='SMR CCS breakdown'!B38 -> 0 | C25: ='SMR CCS breakdown'!C38 -> 0 | D25: ='SMR CCS breakdown'!D38 -> 99.915392 | E25: ='SMR CCS breakdown'!E38 -> 1125.0444 | F25: ='SMR CCS breakdown'!F38 -> 78.881098 | G25: ='SMR CCS breakdown'!G38 -> 1.8092004 | H25: ='SMR CCS breakdown'!H38 -> 107.5576 | I25: ='SMR CCS breakdown'!I38 -> 66.118809 | J25: ='SMR CCS breakdown'!J38 -> 1479.3265
A26: Jan '22 | B26: 0 | C26: 0 | D26: 0 | E26: 0 | F26: 0 | G26: 0 | H26: 0 | I26: 0 | J26: 0
A27: Apr '22 | B27: ='BAU breakdown'!B41 -> 757.82387 | C27: ='BAU breakdown'!C41 -> 0.1982039 | D27: ='BAU breakdown'!D41 -> 0 | E27: ='BAU breakdown'!E41 -> 0 | F27: ='BAU breakdown'!F41 -> 155.27484 | G27: ='BAU breakdown'!G41 -> 68.146261 | H27: ='BAU breakdown'!H41 -> 179.04847 | I27: ='BAU breakdown'!I41 -> 91.775063 | J27: ='BAU breakdown'!J41 -> 1252.2667
A28: Apr '22 | B28: ='Wind breakdown'!B41 -> 0 | C28: ='Wind breakdown'!C41 -> 0 | D28: ='Wind breakdown'!D41 -> 99.915392 | E28: ='Wind breakdown'!E41 -> 1094.3941 | F28: ='Wind breakdown'!F41 -> 78.002396 | G28: ='Wind breakdown'!G41 -> 1.8092004 | H28: ='Wind breakdown'!H41 -> 107.5576 | I28: ='Wind breakdown'!I41 -> 66.118809 | ... L28: ='Wind breakdown'!L41 -> 190.23918
A29: Apr '22 | B29: ='Solar breakdown'!B41 -> 0 | C29: ='Solar breakdown'!C41 -> 0 | D29: ='Solar breakdown'!D41 -> 99.915392 | E29: ='Solar breakdown'!E41 -> 1670.8697 | F29: ='Solar breakdown'!F41 -> 78.002396 | G29: ='Solar breakdown'!G41 -> 1.8092004 | H29: ='Solar breakdown'!H41 -> 107.5576 | I29: ='Solar breakdown'!I41 -> 66.118809 | ... L29: ='Solar breakdown'!L41 -> 805.7189
A30: Apr '22 | B30: ='SMR CCS breakdown'!B41 -> 0 | C30: ='SMR CCS breakdown'!C41 -> 0 | D30: ='SMR CCS breakdown'!D41 -> 99.915392 | E30: ='SMR CCS breakdown'!E41 -> 1247.8332 | F30: ='SMR CCS breakdown'!F41 -> 78.002396 | G30: ='SMR CCS breakdown'!G41 -> 1.8092004 | H30: ='SMR CCS breakdown'!H41 -> 107.5576 | I30: ='SMR CCS breakdown'!I41 -> 66.118809 | J30: ='SMR CCS breakdown'!J41 -> 1601.2366
A31: Apr '22 | B31: 0 | C31: 0 | D31: 0 | E31: 0 | F31: 0 | G31: 0 | H31: 0 | I31: 0 | J31: 0
A32: Jul '22 | B32: ='BAU breakdown'!B44 -> 1208.0466 | C32: ='BAU breakdown'!C44 -> 0.1982039 | D32: ='BAU breakdown'!D44 -> 0 | E32: ='BAU breakdown'!E44 -> 0 | F32: ='BAU breakdown'!F44 -> 294.89123 | G32: ='BAU breakdown'!G44 -> 68.146261 | H32: ='BAU breakdown'!H44 -> 179.04847 | I32: ='BAU breakdown'!I44 -> 91.775063 | J32: ='BAU breakdown'!J44 -> 1842.1058
A33: Jul '22 | B33: ='Wind breakdown'!B44 -> 0 | C33: ='Wind breakdown'!C44 -> 0 | D33: ='Wind breakdown'!D44 -> 99.915392 | E33: ='Wind breakdown'!E44 -> 1094.3941 | F33: ='Wind breakdown'!F44 -> 148.13877 | G33: ='Wind breakdown'!G44 -> 1.8092004 | H33: ='Wind breakdown'!H44 -> 107.5576 | I33: ='Wind breakdown'!I44 -> 66.118809 | ... L33: ='Wind breakdown'!L44 -> 190.23918
A34: Jul '22 | B34: ='Solar breakdown'!B44 -> 0 | C34: ='Solar breakdown'!C44 -> 0 | D34: ='Solar breakdown'!D44 -> 99.915392 | E34: ='Solar breakdown'!E44 -> 1670.8697 | F34: ='Solar breakdown'!F44 -> 148.13877 | G34: ='Solar breakdown'!G44 -> 1.8092004 | H34: ='Solar breakdown'!H44 -> 107.5576 | I34: ='Solar breakdown'!I44 -> 66.118809 | ... L34: ='Solar breakdown'!L44 -> 805.7189
A35: Jul '22 | B35: ='SMR CCS breakdown'!B44 -> 0 | C35: ='SMR CCS breakdown'!C44 -> 0 | D35: ='SMR CCS breakdown'!D44 -> 99.915392 | E35: ='SMR CCS breakdown'!E44 -> 1844.013 | F35: ='SMR CCS breakdown'!F44 -> 148.13877 | G35: ='SMR CCS breakdown'!G44 -> 1.8092004 | H35: ='SMR CCS breakdown'!H44 -> 107.5576 | I35: ='SMR CCS breakdown'!I44 -> 66.118809 | J35: ='SMR CCS breakdown'!J44 -> 2267.5528
A36: Jul '22 | B36: 0 | C36: 0 | D36: 0 | E36: 0 | F36: 0 | G36: 0 | H36: 0 | I36: 0 | J36: 0
A37: Aug '22 | B37: ='BAU breakdown'!B45 -> 1648.3846 | C37: ='BAU breakdown'!C45 -> 0.1982039 | D37: ='BAU breakdown'!D45 -> 0 | E37: ='BAU breakdown'!E45 -> 0 | F37: ='BAU breakdown'!F45 -> 439.02557 | G37: ='BAU breakdown'!G45 -> 68.146261 | H37: ='BAU breakdown'!H45 -> 179.04847 | I37: ='BAU breakdown'!I45 -> 91.775063 | J37: ='BAU breakdown'!J45 -> 2426.5782
A38: Aug '22 | B38: ='Wind breakdown'!B45 -> 0 | C38: ='Wind breakdown'!C45 -> 0 | D38: ='Wind breakdown'!D45 -> 99.915392 | E38: ='Wind breakdown'!E45 -> 1094.3941 | F38: ='Wind breakdown'!F45 -> 220.54473 | G38: ='Wind breakdown'!G45 -> 1.8092004 | H38: ='Wind breakdown'!H45 -> 107.5576 | I38: ='Wind breakdown'!I45 -> 66.118809 | ... L38: ='Wind breakdown'!L45 -> 190.23918
A39: Aug '22 | B39: ='Solar breakdown'!B45 -> 0 | C39: ='Solar breakdown'!C45 -> 0 | D39: ='Solar breakdown'!D45 -> 99.915392 | E39: ='Solar breakdown'!E45 -> 1670.8697 | F39: ='Solar breakdown'!F45 -> 220.54473 | G39: ='Solar breakdown'!G45 -> 1.8092004 | H39: ='Solar breakdown'!H45 -> 107.5576 | I39: ='Solar breakdown'!I45 -> 66.118809 | ... L39: ='Solar breakdown'!L45 -> 805.7189
A40: Aug '22 | B40: ='SMR CCS breakdown'!B45 -> 0 | C40: ='SMR CCS breakdown'!C45 -> 0 | D40: ='SMR CCS breakdown'!D45 -> 99.915392 | E40: ='SMR CCS breakdown'!E45 -> 2427.1036 | F40: ='SMR CCS breakdown'!F45 -> 220.54473 | G40: ='SMR CCS breakdown'!G45 -> 1.8092004 | H40: ='SMR CCS breakdown'!H45 -> 107.5576 | I40: ='SMR CCS breakdown'!I45 -> 66.118809 | J40: ='SMR CCS breakdown'!J45 -> 2923.0494
...
