Workbook

Sheet Ammonia
A1: Index | B1: Time | C1: NG price | D1: Market | E1: BAU | F1: Biomass | G1: Wind | H1: Solar | I1: Nuclear | J1: CO2 Biomass | K1: CO2 Wind | L1: CO2 Solar | M1: CO2 Nuclear | N1: Grid | P1: Process | Q1: GWP | S1: Electricity | T1: H2 SMR CCS | U1: SMR CCS | V1: CO2 SMR CCS | W1: LCOH Grid
A2: 1 | B2: Jan '19 | C2: 326.17727 | E2: 470.06471 | F2: 627.873 | G2: 1440.5245 | H2: 1851.9251 | I2: 1446.3571 | J2: =(E2-F2)/($Q$3-$Q$2) -> 47.389876 | K2: =(E2-G2)/($Q$4-$Q$2) -> 647.83696 | L2: =(E2-H2)/($Q$5-$Q$2) -> 1316.0575 | M2: =(E2-I2)/($Q$6-$Q$2) -> 473.00986 | N2: 1076.8365 | P2: BAU | Q2: 2.19 | S2: 49.41 | T2: 2321.4698 | U2: 636.94256 | V2: =(E2-U2)/($Q$8-$Q$2) -> 101.81687 | W2: 4817.8697
A3: =A2+1 -> 2 | B3: Feb '19 | C3: 268.53773 | E3: 433.53111 | F3: 624.7717 | G3: 1437.4232 | H3: 1848.8238 | I3: 1443.2558 | J3: =(E3-F3)/($Q$3-$Q$2) -> 57.429607 | K3: =(E3-G3)/($Q$4-$Q$2) -> 670.15491 | L3: =(E3-H3)/($Q$5-$Q$2) -> 1347.8978 | M3: =(E3-I3)/($Q$6-$Q$2) -> 489.20768 | N3: 1009.7705 | P3: Biomass | Q3: -1.14 | S3: 42.81 | T3: 2093.321 | U3: 593.63885 | V3: =(E3-U3)/($Q$8-$Q$2) -> 97.686238 | W3: 4454.8697
A4: =A3+1 -> 3 | B4: Mar '19 | C4: 231.45182 | E4: 402.58538 | F4: 619.03899 | G4: 1431.6905 | H4: 1843.0911 | I4: 1437.5231 | J4: =(E4-F4)/($Q$3-$Q$2) -> 65.001087 | K4: =(E4-G4)/($Q$4-$Q$2) -> 686.98604 | L4: =(E4-H4)/($Q$5-$Q$2) -> 1371.9102 | M4: =(E4-I4)/($Q$6-$Q$2) -> 501.4233 | N4: 885.80001 | P4: Wind | Q4: 0.692 | S4: 30.61 | T4: 1946.5276 | U4: 562.03949 | V4: =(E4-U4)/($Q$8-$Q$2) -> 97.287438 | W4: 3783.8697
A5: =A4+1 -> 4 | B5: Apr '19 | C5: 219.83455 | E5: 402.41539 | F5: 622.02752 | G5: 1434.679 | H5: 1846.0796 | I5: 1440.5116 | J5: =(E5-F5)/($Q$3-$Q$2) -> 65.94959 | K5: =(E5-G5)/($Q$4-$Q$2) -> 689.09453 | L5: =(E5-H5)/($Q$5-$Q$2) -> 1374.9183 | M5: =(E5-I5)/($Q$6-$Q$2) -> 502.95359 | N5: 950.42726 | P5: Solar | Q5: 1.14 | S5: 36.97 | T5: 1900.5441 | U5: 556.9252 | V5: =(E5-U5)/($Q$8-$Q$2) -> 94.270785 | W5: 4133.6697
A6: =A5+1 -> 5 | B6: May '19 | C6: 193.91909 | E6: 389.56958 | F6: 622.43163 | G6: 1435.0831 | H6: 1846.4837 | I6: 1440.9157 | J6: =(E6-F6)/($Q$3-$Q$2) -> 69.928544 | K6: =(E6-G6)/($Q$4-$Q$2) -> 697.9396 | L6: =(E6-H6)/($Q$5-$Q$2) -> 1387.5373 | M6: =(E6-I6)/($Q$6-$Q$2) -> 509.37312 | N6: 959.16616 | P6: Nuclear | Q6: 0.126 | S6: 37.83 | T6: 1797.9656 | U6: 539.25381 | V6: =(E6-U6)/($Q$8-$Q$2) -> 91.326562 | W6: 4180.9697
A7: =A6+1 -> 6 | B7: Jun '19 | C7: 160.40773 | E7: 366.93277 | F7: 619.92709 | G7: 1432.5786 | H7: 1843.9792 | I7: 1438.4112 | J7: =(E7-F7)/($Q$3-$Q$2) -> 75.974272 | K7: =(E7-G7)/($Q$4-$Q$2) -> 711.37904 | L7: =(E7-H7)/($Q$5-$Q$2) -> 1406.7109 | M7: =(E7-I7)/($Q$6-$Q$2) -> 519.12713 | N7: 905.00527 | P7: Coal | S7: 32.5 | T7: 1665.321 | U7: 513.37579 | V7: =(E7-U7)/($Q$8-$Q$2) -> 89.349005 | W7: 3887.8197
A8: =A7+1 -> 7 | B8: Jul '19 | C8: 161.74818 | E8: 374.38298 | F8: 623.31503 | G8: 1435.9665 | H8: 1847.3671 | I8: 1441.7991 | J8: =(E8-F8)/($Q$3-$Q$2) -> 74.754369 | K8: =(E8-G8)/($Q$4-$Q$2) -> 708.66724 | L8: =(E8-H8)/($Q$5-$Q$2) -> 1402.842 | M8: =(E8-I8)/($Q$6-$Q$2) -> 517.15897 | N8: 978.26982 | P8: SMR CCS | Q8: 0.551 | S8: 39.71 | T8: 1670.6267 | U8: 517.69866 | V8: =(E8-U8)/($Q$8-$Q$2) -> 87.440928 | W8: 4284.3697
A9: =A8+1 -> 8 | B9: Aug '19 | C9: 164.42909 | E9: 373.0918 | F9: 621.95704 | G9: 1434.6085 | H9: 1846.0091 | I9: 1440.4411 | J9: =(E9-F9)/($Q$3-$Q$2) -> 74.734306 | K9: =(E9-G9)/($Q$4-$Q$2) -> 708.62264 | L9: =(E9-H9)/($Q$5-$Q$2) -> 1402.7784 | M9: =(E9-I9)/($Q$6-$Q$2) -> 517.1266 | N9: 948.90303 | S9: 36.82 | T9: 1681.2383 | U9: 518.21055 | V9: =(E9-U9)/($Q$8-$Q$2) -> 88.541032 | W9: 4125.4197
A10: =A9+1 -> 9 | B10: Sep '19 | C10: 188.11045 | E10: 384.58314 | F10: 621.46365 | G10: 1434.1151 | H10: 1845.5157 | I10: 1439.9477 | J10: =(E10-F10)/($Q$3-$Q$2) -> 71.135289 | K10: =(E10-G10)/($Q$4-$Q$2) -> 700.62215 | L10: =(E10-H10)/($Q$5-$Q$2) -> 1391.3644 | M10: =(E10-I10)/($Q$6-$Q$2) -> 511.32005 | N10: 938.23344 | S10: 35.77 | T10: 1774.9739 | U10: 534.23443 | V10: =(E10-U10)/($Q$8-$Q$2) -> 91.306461 | W10: 4067.6697
A11: =A10+1 -> 10 | B11: Oct '19 | C11: 226.09 | E11: 405.69156 | F11: 622.01812 | G11: 1434.6696 | H11: 1846.0702 | I11: 1440.5022 | J11: =(E11-F11)/($Q$3-$Q$2) -> 64.96293 | K11: =(E11-G11)/($Q$4-$Q$2) -> 686.90122 | L11: =(E11-H11)/($Q$5-$Q$2) -> 1371.7892 | M11: =(E11-I11)/($Q$6-$Q$2) -> 501.36174 | N11: 950.22403 | S11: 36.95 | T11: 1925.3044 | U11: 561.27886 | V11: =(E11-U11)/($Q$8-$Q$2) -> 94.928183 | W11: 4132.5697
A12: =A11+1 -> 11 | B12: Nov '19 | C12: 230.11136 | E12: 411.59804 | F12: 623.92119 | G12: 1436.5727 | H12: 1847.9733 | I12: 1442.4053 | J12: =(E12-F12)/($Q$3-$Q$2) -> 63.760707 | K12: =(E12-G12)/($Q$4-$Q$2) -> 684.22872 | L12: =(E12-H12)/($Q$5-$Q$2) -> 1367.9764 | M12: =(E12-I12)/($Q$6-$Q$2) -> 499.4221 | N12: 991.37818 | S12: 41 | T12: 1941.2218 | U12: 565.98675 | V12: =(E12-U12)/($Q$8-$Q$2) -> 94.196893 | W12: 4355.3197
A13: =A12+1 -> 12 | B13: Dec '19 | C13: 206.43 | E13: 390.67796 | F13: 619.67805 | G13: 1432.3295 | H13: 1843.7301 | I13: 1438.1621 | J13: =(E13-F13)/($Q$3-$Q$2) -> 68.768795 | K13: =(E13-G13)/($Q$4-$Q$2) -> 695.36152 | L13: =(E13-H13)/($Q$5-$Q$2) -> 1383.8592 | M13: =(E13-I13)/($Q$6-$Q$2) -> 507.50201 | N13: 899.61967 | S13: 31.97 | T13: 1847.4863 | U13: 545.22634 | V13: =(E13-U13)/($Q$8-$Q$2) -> 94.294311 | W13: 3858.6697
A14: =A13+1 -> 13 | B14: Jan '20 | C14: 162.195 | D14: 494.38202 | E14: 365.50574 | F14: 609.84534 | G14: 1210.4483 | H14: 1811.5404 | I14: 1256.6333 | J14: =(E14-F14)/($Q$3-$Q$2) -> 73.375255 | K14: =(E14-G14)/($Q$4-$Q$2) -> 564.04709 | L14: =(E14-H14)/($Q$5-$Q$2) -> 1377.1759 | M14: =(E14-I14)/($Q$6-$Q$2) -> 431.74784 | N14: 926.39907 | S14: 34.98 | T14: 1653.2291 | U14: 508.60364 | V14: =(E14-U14)/($Q$8-$Q$2) -> 87.308056 | W14: 4024.2197
A15: =A14+1 -> 14 | B15: Feb '20 | C15: 130.02409 | D15: 487.64045 | E15: 336.33505 | F15: 603.70383 | G15: 1204.3068 | H15: 1805.3989 | I15: 1250.4918 | J15: =(E15-F15)/($Q$3-$Q$2) -> 80.290922 | K15: =(E15-G15)/($Q$4-$Q$2) -> 579.42037 | L15: =(E15-H15)/($Q$5-$Q$2) -> 1399.1084 | M15: =(E15-I15)/($Q$6-$Q$2) -> 442.90538 | N15: 793.58803 | S15: 21.91 | T15: 1525.8903 | U15: 480.02358 | V15: =(E15-U15)/($Q$8-$Q$2) -> 87.66841 | W15: 3305.3697
A16: =A15+1 -> 15 | B16: Mar '20 | C16: 121.53455 | D16: 487.64045 | E16: 332.43401 | F16: 603.99046 | G16: 1204.5934 | H16: 1805.6855 | I16: 1250.7784 | J16: =(E16-F16)/($Q$3-$Q$2) -> 81.548484 | K16: =(E16-G16)/($Q$4-$Q$2) -> 582.21589 | L16: =(E16-H16)/($Q$5-$Q$2) -> 1403.0967 | M16: =(E16-I16)/($Q$6-$Q$2) -> 444.9343 | N16: 799.78656 | S16: 22.52 | T16: 1492.287 | U16: 474.38893 | V16: =(E16-U16)/($Q$8-$Q$2) -> 86.610689 | W16: 3338.9197
A17: =A16+1 -> 16 | B17: Apr '20 | C17: 94.725455 | D17: 492.13483 | E17: 313.19648 | F17: 601.42014 | G17: 1202.0231 | H17: 1803.1152 | I17: 1248.2081 | J17: =(E17-F17)/($Q$3-$Q$2) -> 86.553651 | K17: =(E17-G17)/($Q$4-$Q$2) -> 593.34219 | L17: =(E17-H17)/($Q$5-$Q$2) -> 1418.9702 | M17: =(E17-I17)/($Q$6-$Q$2) -> 453.0095 | N17: 744.20306 | S17: 17.05 | T17: 1386.1713 | U17: 453.11982 | V17: =(E17-U17)/($Q$8-$Q$2) -> 85.371163 | W17: 3038.0697
A18: =A17+1 -> 17 | B18: May '20 | C18: 70.597273 | D18: 471.91011 | E18: 301.0021 | F18: 601.67858 | G18: 1202.2815 | H18: 1803.3737 | I18: 1248.4665 | J18: =(E18-F18)/($Q$3-$Q$2) -> 90.293238 | K18: =(E18-G18)/($Q$4-$Q$2) -> 601.65516 | L18: =(E18-H18)/($Q$5-$Q$2) -> 1430.8301 | M18: =(E18-I18)/($Q$6-$Q$2) -> 459.04284 | N18: 749.79189 | S18: 17.6 | T18: 1290.6671 | U18: 436.54935 | V18: =(E18-U18)/($Q$8-$Q$2) -> 82.701188 | W18: 3068.3197
A19: =A18+1 -> 18 | B19: Jun '20 | C19: 78.193182 | D19: 462.92135 | E19: 313.07545 | F19: 605.73377 | G19: 1206.3367 | H19: 1807.4288 | I19: 1252.5217 | J19: =(E19-F19)/($Q$3-$Q$2) -> 87.885379 | K19: =(E19-G19)/($Q$4-$Q$2) -> 596.30258 | L19: =(E19-H19)/($Q$5-$Q$2) -> 1423.1937 | M19: =(E19-I19)/($Q$6-$Q$2) -> 455.15807 | N19: 837.48579 | S19: 26.23 | T19: 1320.7333 | U19: 445.90252 | V19: =(E19-U19)/($Q$8-$Q$2) -> 81.041531 | W19: 3542.9697
A20: =A19+1 -> 19 | B20: Jul '20 | C20: 80.427273 | D20: 453.93258 | E20: 317.8441 | F20: 607.53816 | G20: 1208.1411 | H20: 1809.2332 | I20: 1254.3261 | J20: =(E20-F20)/($Q$3-$Q$2) -> 86.995214 | K20: =(E20-G20)/($Q$4-$Q$2) -> 594.32377 | L20: =(E20-H20)/($Q$5-$Q$2) -> 1420.3706 | M20: =(E20-I20)/($Q$6-$Q$2) -> 453.7219 | N20: 876.50602 | S20: 30.07 | T20: 1329.5762 | U20: 449.26515 | V20: =(E20-U20)/($Q$8-$Q$2) -> 80.183679 | W20: 3754.1697
A21: =A20+1 -> 20 | B21: Aug '20 | C21: 127.79 | D21: 435.95506 | E21: 347.29968 | F21: 609.80305 | G21: 1210.406 | H21: 1811.4981 | I21: 1256.591 | J21: =(E21-F21)/($Q$3-$Q$2) -> 78.829841 | K21: =(E21-G21)/($Q$4-$Q$2) -> 576.17244 | L21: =(E21-H21)/($Q$5-$Q$2) -> 1394.4747 | M21: =(E21-I21)/($Q$6-$Q$2) -> 440.54812 | N21: 925.48454 | S21: 34.89 | T21: 1517.0473 | U21: 484.56457 | V21: =(E21-U21)/($Q$8-$Q$2) -> 83.749171 | W21: 4019.2697
A22: =A21+1 -> 21 | B22: Sep '20 | C22: 176.49318 | D22: 431.46067 | E22: 381.17481 | F22: 613.93342 | G22: 1214.5364 | H22: 1815.6285 | I22: 1260.7214 | J22: =(E22-F22)/($Q$3-$Q$2) -> 69.897481 | K22: =(E22-G22)/($Q$4-$Q$2) -> 556.31613 | L22: =(E22-H22)/($Q$5-$Q$2) -> 1366.1464 | M22: =(E22-I22)/($Q$6-$Q$2) -> 426.1369 | N22: 1014.8043 | S22: 43.68 | T22: 1709.8242 | U22: 522.66441 | V22: =(E22-U22)/($Q$8-$Q$2) -> 86.326786 | W22: 4502.7197
A23: =A22+1 -> 22 | B23: Oct '20 | C23: 218.49409 | D23: 422.47191 | E23: 394.20562 | F23: 609.36605 | G23: 1209.969 | H23: 1811.0611 | I23: 1256.154 | J23: =(E23-F23)/($Q$3-$Q$2) -> 64.612742 | K23: =(E23-G23)/($Q$4-$Q$2) -> 544.56834 | L23: =(E23-H23)/($Q$5-$Q$2) -> 1349.3862 | M23: =(E23-I23)/($Q$6-$Q$2) -> 417.61064 | N23: 916.03432 | S23: 33.96 | T23: 1876.0721 | U23: 547.39181 | V23: =(E23-U23)/($Q$8-$Q$2) -> 93.463206 | W23: 3968.1197
A24: =A23+1 -> 23 | B24: Nov '20 | C24: 216.26 | D24: 426.96629 | E24: 397.55616 | F24: 611.64034 | G24: 1212.2433 | H24: 1813.3354 | I24: 1258.4283 | J24: =(E24-F24)/($Q$3-$Q$2) -> 64.289541 | K24: =(E24-G24)/($Q$4-$Q$2) -> 543.84988 | L24: =(E24-H24)/($Q$5-$Q$2) -> 1348.3612 | M24: =(E24-I24)/($Q$6-$Q$2) -> 417.0892 | N24: 965.21607 | S24: 38.8 | T24: 1867.2292 | U24: 548.10787 | V24: =(E24-U24)/($Q$8-$Q$2) -> 91.855829 | W24: 4234.3197
A25: =A24+1 -> 24 | B25: Dec '20 | C25: 261.83545 | D25: 471.91011 | E25: 426.00487 | F25: 613.87233 | G25: 1214.4753 | H25: 1815.5674 | I25: 1260.6603 | J25: =(E25-F25)/($Q$3-$Q$2) -> 56.416655 | K25: =(E25-G25)/($Q$4-$Q$2) -> 526.34874 | L25: =(E25-H25)/($Q$5-$Q$2) -> 1323.3929 | M25: =(E25-I25)/($Q$6-$Q$2) -> 404.38731 | N25: 1013.4833 | S25: 43.55 | T25: 2047.6259 | U25: 582.12781 | V25: =(E25-U25)/($Q$8-$Q$2) -> 95.254997 | W25: 4495.5697
... A38: =A37+1 -> 37 | B38: Jan '22 | C38: 1262.7082 | D38: 1471.9101 | E38: 1161.2884 | F38: 892.55337 | G38: 1448.6762 | H38: 2025.1518 | I38: 1699.1612 | J38: =(E38-F38)/($Q$3-$Q$2) -> -80.701202 | K38: =(E38-G38)/($Q$4-$Q$2) -> 191.84771 | L38: =(E38-H38)/($Q$5-$Q$2) -> 822.72712 | M38: =(E38-I38)/($Q$6-$Q$2) -> 260.59732 | N38: 2351.3152 | S38: 167.87 | T38: 6384.6312 | U38: 1479.3265 | V38: =(E38-U38)/($Q$8-$Q$2) -> 194.04404 | W38: 11333.17
A39: =A38+1 -> 38 | B39: Feb '22 | C39: 1216.6859 | E39: 1100.483 | F39: 874.18521 | G39: 1430.3081 | H39: 2006.7837 | I39: 1680.7931 | J39: =(E39-F39)/($Q$3-$Q$2) -> -67.957294 | K39: =(E39-G39)/($Q$4-$Q$2) -> 220.17696 | L39: =(E39-H39)/($Q$5-$Q$2) -> 863.14351 | M39: =(E39-I39)/($Q$6-$Q$2) -> 281.15798 | N39: 1954.1014 | S39: 128.78 | T39: 6202.4659 | U39: 1428.8588 | V39: =(E39-U39)/($Q$8-$Q$2) -> 200.35131 | W39: 9183.2197
A40: =A39+1 -> 39 | B40: Mar '22 | C40: 1894.0623 | E40: 1572.3065 | F40: 931.97277 | G40: 1488.0957 | H40: 2064.5712 | I40: 1738.5806 | J40: =(E40-F40)/($Q$3-$Q$2) -> -192.2924 | K40: =(E40-G40)/($Q$4-$Q$2) -> -56.215496 | L40: =(E40-H40)/($Q$5-$Q$2) -> 468.8236 | M40: =(E40-I40)/($Q$6-$Q$2) -> 80.559191 | N40: 3203.7649 | S40: 251.76 | T40: 8883.6562 | U40: 1959.1025 | V40: =(E40-U40)/($Q$8-$Q$2) -> 235.99514 | W40: 15947.12
A41: =A40+1 -> 40 | B41: Apr '22 | C41: 1438.7545 | E41: 1252.2667 | F41: 891.67467 | G41: 1447.7975 | H41: 2024.2731 | I41: 1698.2825 | J41: =(E41-F41)/($Q$3-$Q$2) -> -108.2859 | K41: =(E41-G41)/($Q$4-$Q$2) -> 130.52793 | L41: =(E41-H41)/($Q$5-$Q$2) -> 735.24422 | M41: =(E41-I41)/($Q$6-$Q$2) -> 216.09294 | N41: 2332.3131 | S41: 166 | T41: 7081.4577 | U41: 1601.2366 | V41: =(E41-U41)/($Q$8-$Q$2) -> 212.91633 | W41: 11230.32
A42: =A41+1 -> 41 | B42: May '22 | C42: 1303.3686 | E42: 1191.7223 | F42: 897.08315 | G42: 1453.206 | H42: 2029.6816 | I42: 1703.691 | J42: =(E42-F42)/($Q$3-$Q$2) -> -88.480226 | K42: =(E42-G42)/($Q$4-$Q$2) -> 174.55523 | L42: =(E42-H42)/($Q$5-$Q$2) -> 798.0565 | M42: =(E42-I42)/($Q$6-$Q$2) -> 248.04686 | N42: 2449.2722 | S42: 177.51 | T42: 6545.5734 | U42: 1512.2162 | V42: =(E42-U42)/($Q$8-$Q$2) -> 195.54232 | W42: 11863.37
A43: =A42+1 -> 42 | B43: Jun '22 | C43: 1499.5218 | E43: 1333.0829 | F43: 916.19373 | G43: 1472.3166 | H43: 2048.7922 | I43: 1722.8016 | J43: =(E43-F43)/($Q$3-$Q$2) -> -125.19193 | K43: =(E43-G43)/($Q$4-$Q$2) -> 92.946433 | L43: =(E43-H43)/($Q$5-$Q$2) -> 681.62795 | M43: =(E43-I43)/($Q$6-$Q$2) -> 188.81722 | N43: 2862.5411 | S43: 218.18 | T43: 7321.9867 | U43: 1668.1396 | V43: =(E43-U43)/($Q$8-$Q$2) -> 204.42753 | W43: 14100.22
A44: =A43+1 -> 43 | B44: Jul '22 | C44: 2293.5177 | E44: 1842.1058 | F44: 961.81104 | G44: 1517.9339 | H44: 2094.4095 | I44: 1768.4189 | J44: =(E44-F44)/($Q$3-$Q$2) -> -264.35278 | K44: =(E44-G44)/($Q$4-$Q$2) -> -216.40312 | L44: =(E44-H44)/($Q$5-$Q$2) -> 240.28925 | M44: =(E44-I44)/($Q$6-$Q$2) -> -35.701016 | N44: 3849.0213 | S44: 315.26 | T44: 10464.78 | U44: 2267.5528 | V44: =(E44-U44)/($Q$8-$Q$2) -> 259.57716 | W44: 19439.62
A45: =A44+1 -> 44 | B45: Aug '22 | C45: 3129.5145 | E45: 2426.5782 | F45: 1034.217 | G45: 1590.3399 | H45: 2166.8155 | I45: 1840.8249 | J45: =(E45-F45)/($Q$3-$Q$2) -> -418.12648 | K45: =(E45-G45)/($Q$4-$Q$2) -> -558.23651 | L45: =(E45-H45)/($Q$5-$Q$2) -> -247.39304 | M45: =(E45-I45)/($Q$6-$Q$2) -> -283.79521 | N45: 5414.8095 | S45: 469.35 | T45: 13773.822 | U45: 2923.0494 | V45: =(E45-U45)/($Q$8-$Q$2) -> 302.91105 | W45: 27914.57
A46: =A45+1 -> 45 | B46: Sep '22 | C46: 2640.6955 | E46: 2066.9897 | F46: 982.91867 | G46: 1539.0416 | H46: 2115.5171 | I46: 1789.5265 | J46: =(E46-F46)/($Q$3-$Q$2) -> -325.54687 | K46: =(E46-G46)/($Q$4-$Q$2) -> -352.43537 | L46: =(E46-H46)/($Q$5-$Q$2) -> 46.216581 | M46: =(E46-I46)/($Q$6-$Q$2) -> -134.42985 | N46: 4305.4766 | S46: 360.18 | T46: 11838.979 | U46: 2530.8097 | V46: =(E46-U46)/($Q$8-$Q$2) -> 282.98963 | W46: 21910.22
A47: =A46+1 -> 46 | B47: Oct '22 | C47: 1743.4845 | E47: 1405.0858 | F47: 887.81214 | G47: 1443.935 | H47: 2020.4106 | I47: 1694.42 | J47: =(E47-F47)/($Q$3-$Q$2) -> -155.33745 | K47: =(E47-G47)/($Q$4-$Q$2) -> 25.934034 | L47: =(E47-H47)/($Q$5-$Q$2) -> 586.0236 | M47: =(E47-I47)/($Q$6-$Q$2) -> 140.18128 | N47: 2248.7854 | S47: 157.78 | T47: 8287.6396 | U47: 1809.917 | V47: =(E47-U47)/($Q$8-$Q$2) -> 246.99887 | W47: 10778.22
A48: =A47+1 -> 47 | B48: Nov '22 | C48: 1596.0345 | E48: 1343.949 | F48: 896.11516 | G48: 1452.238 | H48: 2028.7136 | I48: 1702.723 | J48: =(E48-F48)/($Q$3-$Q$2) -> -134.48464 | K48: =(E48-G48)/($Q$4-$Q$2) -> 72.289077 | L48: =(E48-H48)/($Q$5-$Q$2) -> 652.15679 | M48: =(E48-I48)/($Q$6-$Q$2) -> 173.82462 | N48: 2428.3395 | S48: 175.45 | T48: 7704.0032 | U48: 1715.3767 | V48: =(E48-U48)/($Q$8-$Q$2) -> 226.61846 | W48: 11750.07

Sheet Ammonia summary
B1: Natural gas | C1: BAU | D1: Wind | E1: Solar | F1: Nuclear | G1: Biomass | H1: SMR + CCS
A2: =Ammonia!B2 -> Jan '19 | B2: =Ammonia!C2 -> 326.17727 | C2: =Ammonia!E2 -> 470.06471 | D2: =Ammonia!G2 -> 1440.5245 | E2: =Ammonia!H2 -> 1851.9251 | F2: =Ammonia!I2 -> 1446.3571 | G2: =Ammonia!F2 -> 627.873 | H2: =Ammonia!U2 -> 636.94256
A3: =Ammonia!B3 -> Feb '19 | B3: =Ammonia!C3 -> 268.53773 | C3: =Ammonia!E3 -> 433.53111 | D3: =Ammonia!G3 -> 1437.4232 | E3: =Ammonia!H3 -> 1848.8238 | F3: =Ammonia!I3 -> 1443.2558 | G3: =Ammonia!F3 -> 624.7717 | H3: =Ammonia!U3 -> 593.63885
A4: =Ammonia!B4 -> Mar '19 | B4: =Ammonia!C4 -> 231.45182 | C4: =Ammonia!E4 -> 402.58538 | D4: =Ammonia!G4 -> 1431.6905 | E4: =Ammonia!H4 -> 1843.0911 | F4: =Ammonia!I4 -> 1437.5231 | G4: =Ammonia!F4 -> 619.03899 | H4: =Ammonia!U4 -> 562.03949
A5: =Ammonia!B5 -> Apr '19 | B5: =Ammonia!C5 -> 219.83455 | C5: =Ammonia!E5 -> 402.41539 | D5: =Ammonia!G5 -> 1434.679 | E5: =Ammonia!H5 -> 1846.0796 | F5: =Ammonia!I5 -> 1440.5116 | G5: =Ammonia!F5 -> 622.02752 | H5: =Ammonia!U5 -> 556.9252
A6: =Ammonia!B6 -> May '19 | B6: =Ammonia!C6 -> 193.91909 | C6: =Ammonia!E6 -> 389.56958 | D6: =Ammonia!G6 -> 1435.0831 | E6: =Ammonia!H6 -> 1846.4837 | F6: =Ammonia!I6 -> 1440.9157 | G6: =Ammonia!F6 -> 622.43163 | H6: =Ammonia!U6 -> 539.25381
A7: =Ammonia!B7 -> Jun '19 | B7: =Ammonia!C7 -> 160.40773 | C7: =Ammonia!E7 -> 366.93277 | D7: =Ammonia!G7 -> 1432.5786 | E7: =Ammonia!H7 -> 1843.9792 | F7: =Ammonia!I7 -> 1438.4112 | G7: =Ammonia!F7 -> 619.92709 | H7: =Ammonia!U7 -> 513.37579
A8: =Ammonia!B8 -> Jul '19 | B8: =Ammonia!C8 -> 161.74818 | C8: =Ammonia!E8 -> 374.38298 | D8: =Ammonia!G8 -> 1435.9665 | E8: =Ammonia!H8 -> 1847.3671 | F8: =Ammonia!I8 -> 1441.7991 | G8: =Ammonia!F8 -> 623.31503 | H8: =Ammonia!U8 -> 517.69866
A9: =Ammonia!B9 -> Aug '19 | B9: =Ammonia!C9 -> 164.42909 | C9: =Ammonia!E9 -> 373.0918 | D9: =Ammonia!G9 -> 1434.6085 | E9: =Ammonia!H9 -> 1846.0091 | F9: =Ammonia!I9 -> 1440.4411 | G9: =Ammonia!F9 -> 621.95704 | H9: =Ammonia!U9 -> 518.21055
A10: =Ammonia!B10 -> Sep '19 | B10: =Ammonia!C10 -> 188.11045 | C10: =Ammonia!E10 -> 384.58314 | D10: =Ammonia!G10 -> 1434.1151 | E10: =Ammonia!H10 -> 1845.5157 | F10: =Ammonia!I10 -> 1439.9477 | G10: =Ammonia!F10 -> 621.46365 | H10: =Ammonia!U10 -> 534.23443
A11: =Ammonia!B11 -> Oct '19 | B11: =Ammonia!C11 -> 226.09 | C11: =Ammonia!E11 -> 405.69156 | D11: =Ammonia!G11 -> 1434.6696 | E11: =Ammonia!H11 -> 1846.0702 | F11: =Ammonia!I11 -> 1440.5022 | G11: =Ammonia!F11 -> 622.01812 | H11: =Ammonia!U11 -> 561.27886
A12: =Ammonia!B12 -> Nov '19 | B12: =Ammonia!C12 -> 230.11136 | C12: =Ammonia!E12 -> 411.59804 | D12: =Ammonia!G12 -> 1436.5727 | E12: =Ammonia!H12 -> 1847.9733 | F12: =Ammonia!I12 -> 1442.4053 | G12: =Ammonia!F12 -> 623.92119 | H12: =Ammonia!U12 -> 565.98675
A13: =Ammonia!B13 -> Dec '19 | B13: =Ammonia!C13 -> 206.43 | C13: =Ammonia!E13 -> 390.67796 | D13: =Ammonia!G13 -> 1432.3295 | E13: =Ammonia!H13 -> 1843.7301 | F13: =Ammonia!I13 -> 1438.1621 | G13: =Ammonia!F13 -> 619.67805 | H13: =Ammonia!U13 -> 545.22634
... A48: =Ammonia!B48 -> Nov '22 | B48: =Ammonia!C48 -> 1596.0345 | C48: =Ammonia!E48 -> 1343.949 | D48: =Ammonia!G48 -> 1452.238 | E48: =Ammonia!H48 -> 2028.7136 | F48: =Ammonia!I48 -> 1702.723 | G48: =Ammonia!F48 -> 896.11516 | H48: =Ammonia!U48 -> 1715.3767

Sheet Ammonia high low
A1: Index | B1: Time | C1: NG price | D1: BAU price | E1: Wind low | F1: Wind high | G1: Solar low | H1: Solar high | I1: Nuclear low | J1: Nuclear high | K1: CO2 Wind low | L1: CO2 Wind high | M1: CO2 Solar low | N1: CO2 Solar high | O1: CO2 Nuclear low | P1: CO2 Nuclear high | R1: Process | S1: GWP
A2: 1 | B2: Jan '19 | C2: =Ammonia!C2 -> 326.17727 | D2: =Ammonia!E2 -> 470.06471 | E2: 1149.7758 | F2: 1721.5816 | G2: 1696.8591 | H2: 3034.3032 | I2: 1207.2207 | J2: 1685.4935 | K2: =(D2-E2)/($S$4-$S$2) -> 453.74569 | L2: =(D2-F2)/($S$4-$S$2) -> 835.45851 | M2: =(D2-G2)/($S$5-$S$2) -> 1168.3756 | N2: =(D2-H2)/($S$5-$S$2) -> 2442.1319 | O2: =(D2-I2)/($S$6-$S$2) -> 357.1492 | P2: =(D2-J2)/($S$6-$S$2) -> 588.87053 | R2: BAU | S2: 2.19
A3: =A2+1 -> 2 | B3: Feb '19 | C3: =Ammonia!C3 -> 268.53773 | D3: =Ammonia!E3 -> 433.53111 | E3: 1146.6745 | F3: 1718.4803 | G3: 1693.7578 | H3: 3031.2019 | I3: 1204.1194 | J3: 1682.3922 | K3: =(D3-E3)/($S$4-$S$2) -> 476.06365 | L3: =(D3-F3)/($S$4-$S$2) -> 857.77647 | M3: =(D3-G3)/($S$5-$S$2) -> 1200.2159 | N3: =(D3-H3)/($S$5-$S$2) -> 2473.9722 | O3: =(D3-I3)/($S$6-$S$2) -> 373.34702 | P3: =(D3-J3)/($S$6-$S$2) -> 605.06835 | R3: Biomass | S3: -1.14
A4: =A3+1 -> 3 | B4: Mar '19 | C4: =Ammonia!C4 -> 231.45182 | D4: =Ammonia!E4 -> 402.58538 | E4: 1140.9418 | F4: 1712.7476 | G4: 1688.0251 | H4: 3025.4692 | I4: 1198.3866 | J4: 1676.6595 | K4: =(D4-E4)/($S$4-$S$2) -> 492.89478 | L4: =(D4-F4)/($S$4-$S$2) -> 874.6076 | M4: =(D4-G4)/($S$5-$S$2) -> 1224.2283 | N4: =(D4-H4)/($S$5-$S$2) -> 2497.9846 | O4: =(D4-I4)/($S$6-$S$2) -> 385.56263 | P4: =(D4-J4)/($S$6-$S$2) -> 617.28396 | R4: Wind | S4: 0.692
A5: =A4+1 -> 4 | B5: Apr '19 | C5: =Ammonia!C5 -> 219.83455 | D5: =Ammonia!E5 -> 402.41539 | E5: 1143.9303 | F5: 1715.7361 | G5: 1691.0136 | H5: 3028.4577 | I5: 1201.3752 | J5: 1679.648 | K5: =(D5-E5)/($S$4-$S$2) -> 495.00326 | L5: =(D5-F5)/($S$4-$S$2) -> 876.71609 | M5: =(D5-G5)/($S$5-$S$2) -> 1227.2364 | N5: =(D5-H5)/($S$5-$S$2) -> 2500.9927 | O5: =(D5-I5)/($S$6-$S$2) -> 387.09292 | P5: =(D5-J5)/($S$6-$S$2) -> 618.81425 | R5: Solar | S5: 1.14
A6: =A5+1 -> 5 | B6: May '19 | C6: =Ammonia!C6 -> 193.91909 | D6: =Ammonia!E6 -> 389.56958 | E6: 1144.3344 | F6: 1716.1402 | G6: 1691.4177 | H6: 3028.8618 | I6: 1201.7793 | J6: 1680.0521 | K6: =(D6-E6)/($S$4-$S$2) -> 503.84834 | L6: =(D6-F6)/($S$4-$S$2) -> 885.56116 | M6: =(D6-G6)/($S$5-$S$2) -> 1239.8554 | N6: =(D6-H6)/($S$5-$S$2) -> 2513.6117 | O6: =(D6-I6)/($S$6-$S$2) -> 393.51245 | P6: =(D6-J6)/($S$6-$S$2) -> 625.23379 | R6: Nuclear | S6: 0.126
A7: =A6+1 -> 6 | B7: Jun '19 | C7: =Ammonia!C7 -> 160.40773 | D7: =Ammonia!E7 -> 366.93277 | E7: 1141.8299 | F7: 1713.6357 | G7: 1688.9132 | H7: 3026.3573 | I7: 1199.2747 | J7: 1677.5476 | K7: =(D7-E7)/($S$4-$S$2) -> 517.28777 | L7: =(D7-F7)/($S$4-$S$2) -> 899.00059 | M7: =(D7-G7)/($S$5-$S$2) -> 1259.029 | N7: =(D7-H7)/($S$5-$S$2) -> 2532.7853 | O7: =(D7-I7)/($S$6-$S$2) -> 403.26646 | P7: =(D7-J7)/($S$6-$S$2) -> 634.98779 | R7: Coal
A8: =A7+1 -> 7 | B8: Jul '19 | C8: =Ammonia!C8 -> 161.74818 | D8: =Ammonia!E8 -> 374.38298 | E8: 1145.2178 | F8: 1717.0236 | G8: 1692.3011 | H8: 3029.7452 | I8: 1202.6627 | J8: 1680.9355 | K8: =(D8-E8)/($S$4-$S$2) -> 514.57597 | L8: =(D8-F8)/($S$4-$S$2) -> 896.28879 | M8: =(D8-G8)/($S$5-$S$2) -> 1255.1602 | N8: =(D8-H8)/($S$5-$S$2) -> 2528.9164 | O8: =(D8-I8)/($S$6-$S$2) -> 401.2983 | P8: =(D8-J8)/($S$6-$S$2) -> 633.01964 | R8: SMR CCS | S8: 0.551
A9: =A8+1 -> 8 | B9: Aug '19 | C9: =Ammonia!C9 -> 164.42909 | D9: =Ammonia!E9 -> 373.0918 | E9: 1143.8598 | F9: 1715.6656 | G9: 1690.9431 | H9: 3028.3872 | I9: 1201.3047 | J9: 1679.5775 | K9: =(D9-E9)/($S$4-$S$2) -> 514.53137 | L9: =(D9-F9)/($S$4-$S$2) -> 896.24419 | M9: =(D9-G9)/($S$5-$S$2) -> 1255.0965 | N9: =(D9-H9)/($S$5-$S$2) -> 2528.8528 | O9: =(D9-I9)/($S$6-$S$2) -> 401.26594 | P9: =(D9-J9)/($S$6-$S$2) -> 632.98727
A10: =A9+1 -> 9 | B10: Sep '19 | C10: =Ammonia!C10 -> 188.11045 | D10: =Ammonia!E10 -> 384.58314 | E10: 1143.3664 | F10: 1715.1722 | G10: 1690.4498 | H10: 3027.8939 | I10: 1200.8113 | J10: 1679.0841 | K10: =(D10-E10)/($S$4-$S$2) -> 506.53089 | L10: =(D10-F10)/($S$4-$S$2) -> 888.24371 | M10: =(D10-G10)/($S$5-$S$2) -> 1243.6825 | N10: =(D10-H10)/($S$5-$S$2) -> 2517.4388 | O10: =(D10-I10)/($S$6-$S$2) -> 395.45938 | P10: =(D10-J10)/($S$6-$S$2) -> 627.18071
A11: =A10+1 -> 10 | B11: Oct '19 | C11: =Ammonia!C11 -> 226.09 | D11: =Ammonia!E11 -> 405.69156 | E11: 1143.9209 | F11: 1715.7267 | G11: 1691.0042 | H11: 3028.4483 | I11: 1201.3658 | J11: 1679.6386 | K11: =(D11-E11)/($S$4-$S$2) -> 492.80996 | L11: =(D11-F11)/($S$4-$S$2) -> 874.52278 | M11: =(D11-G11)/($S$5-$S$2) -> 1224.1073 | N11: =(D11-H11)/($S$5-$S$2) -> 2497.8636 | O11: =(D11-I11)/($S$6-$S$2) -> 385.50107 | P11: =(D11-J11)/($S$6-$S$2) -> 617.2224
A12: =A11+1 -> 11 | B12: Nov '19 | C12: =Ammonia!C12 -> 230.11136 | D12: =Ammonia!E12 -> 411.59804 | E12: 1145.8239 | F12: 1717.6298 | G12: 1692.9073 | H12: 3030.3514 | I12: 1203.2688 | J12: 1681.5417 | K12: =(D12-E12)/($S$4-$S$2) -> 490.13746 | L12: =(D12-F12)/($S$4-$S$2) -> 871.85028 | M12: =(D12-G12)/($S$5-$S$2) -> 1220.2945 | N12: =(D12-H12)/($S$5-$S$2) -> 2494.0508 | O12: =(D12-I12)/($S$6-$S$2) -> 383.56144 | P12: =(D12-J12)/($S$6-$S$2) -> 615.28277
A13: =A12+1 -> 12 | B13: Dec '19 | C13: =Ammonia!C13 -> 206.43 | D13: =Ammonia!E13 -> 390.67796 | E13: 1141.5808 | F13: 1713.3866 | G13: 1688.6642 | H13: 3026.1083 | I13: 1199.0257 | J13: 1677.2985 | K13: =(D13-E13)/($S$4-$S$2) -> 501.27026 | L13: =(D13-F13)/($S$4-$S$2) -> 882.98308 | M13: =(D13-G13)/($S$5-$S$2) -> 1236.1773 | N13: =(D13-H13)/($S$5-$S$2) -> 2509.9336 | O13: =(D13-I13)/($S$6-$S$2) -> 391.64135 | P13: =(D13-J13)/($S$6-$S$2) -> 623.36268
A14: =A13+1 -> 13 | B14: Jan '20 | C14: =Ammonia!C14 -> 162.195 | D14: =Ammonia!E14 -> 365.50574 | E14: 1113.532 | F14: 1404.2808 | G14: 1637.0912 | H14: 2838.8526 | I14: 994.95944 | J14: 1576.4569 | K14: =(D14-E14)/($S$4-$S$2) -> 499.35001 | L14: =(D14-F14)/($S$4-$S$2) -> 693.44127 | M14: =(D14-G14)/($S$5-$S$2) -> 1211.0338 | N14: =(D14-H14)/($S$5-$S$2) -> 2355.5684 | O14: =(D14-I14)/($S$6-$S$2) -> 304.96788 | P14: =(D14-J14)/($S$6-$S$2) -> 586.70113
A15: =A14+1 -> 14 | B15: Feb '20 | C15: =Ammonia!C15 -> 130.02409 | D15: =Ammonia!E15 -> 336.33505 | E15: 1107.3905 | F15: 1398.1393 | G15: 1630.9497 | H15: 2832.711 | I15: 988.81792 | J15: 1570.3154 | K15: =(D15-E15)/($S$4-$S$2) -> 514.72328 | L15: =(D15-F15)/($S$4-$S$2) -> 708.81455 | M15: =(D15-G15)/($S$5-$S$2) -> 1232.9663 | N15: =(D15-H15)/($S$5-$S$2) -> 2377.5009 | O15: =(D15-I15)/($S$6-$S$2) -> 316.12542 | P15: =(D15-J15)/($S$6-$S$2) -> 597.85867
A16: =A15+1 -> 15 | B16: Mar '20 | C16: =Ammonia!C16 -> 121.53455 | D16: =Ammonia!E16 -> 332.43401 | E16: 1107.6772 | F16: 1398.4259 | G16: 1631.2363 | H16: 2832.9977 | I16: 989.10456 | J16: 1570.602 | K16: =(D16-E16)/($S$4-$S$2) -> 517.5188 | L16: =(D16-F16)/($S$4-$S$2) -> 711.61006 | M16: =(D16-G16)/($S$5-$S$2) -> 1236.9546 | N16: =(D16-H16)/($S$5-$S$2) -> 2381.4892 | O16: =(D16-I16)/($S$6-$S$2) -> 318.15433 | P16: =(D16-J16)/($S$6-$S$2) -> 599.88759
A17: =A16+1 -> 16 | B17: Apr '20 | C17: =Ammonia!C17 -> 94.725455 | D17: =Ammonia!E17 -> 313.19648 | E17: 1105.1069 | F17: 1395.8556 | G17: 1628.666 | H17: 2830.4274 | I17: 986.53424 | J17: 1568.0317 | K17: =(D17-E17)/($S$4-$S$2) -> 528.64511 | L17: =(D17-F17)/($S$4-$S$2) -> 722.73637 | M17: =(D17-G17)/($S$5-$S$2) -> 1252.8281 | N17: =(D17-H17)/($S$5-$S$2) -> 2397.3627 | O17: =(D17-I17)/($S$6-$S$2) -> 326.22953 | P17: =(D17-J17)/($S$6-$S$2) -> 607.96278
A18: =A17+1 -> 17 | B18: May '20 | C18: =Ammonia!C18 -> 70.597273 | D18: =Ammonia!E18 -> 301.0021 | E18: 1105.3653 | F18: 1396.114 | G18: 1628.9244 | H18: 2830.6858 | I18: 986.79268 | J18: 1568.2901 | K18: =(D18-E18)/($S$4-$S$2) -> 536.95807 | L18: =(D18-F18)/($S$4-$S$2) -> 731.04934 | M18: =(D18-G18)/($S$5-$S$2) -> 1264.6879 | N18: =(D18-H18)/($S$5-$S$2) -> 2409.2226 | O18: =(D18-I18)/($S$6-$S$2) -> 332.26288 | P18: =(D18-J18)/($S$6-$S$2) -> 613.99613
A19: =A18+1 -> 18 | B19: Jun '20 | C19: =Ammonia!C19 -> 78.193182 | D19: =Ammonia!E19 -> 313.07545 | E19: 1109.4205 | F19: 1400.1692 | G19: 1632.9796 | H19: 2834.741 | I19: 990.84786 | J19: 1572.3453 | K19: =(D19-E19)/($S$4-$S$2) -> 531.60549 | L19: =(D19-F19)/($S$4-$S$2) -> 725.69675 | M19: =(D19-G19)/($S$5-$S$2) -> 1257.0516 | N19: =(D19-H19)/($S$5-$S$2) -> 2401.5862 | O19: =(D19-I19)/($S$6-$S$2) -> 328.37811 | P19: =(D19-J19)/($S$6-$S$2) -> 610.11136
A20: =A19+1 -> 19 | B20: Jul '20 | C20: =Ammonia!C20 -> 80.427273 | D20: =Ammonia!E20 -> 317.8441 | E20: 1111.2249 | F20: 1401.9736 | G20: 1634.784 | H20: 2836.5454 | I20: 992.65226 | J20: 1574.1497 | K20: =(D20-E20)/($S$4-$S$2) -> 529.62668 | L20: =(D20-F20)/($S$4-$S$2) -> 723.71795 | M20: =(D20-G20)/($S$5-$S$2) -> 1254.2285 | N20: =(D20-H20)/($S$5-$S$2) -> 2398.7631 | O20: =(D20-I20)/($S$6-$S$2) -> 326.94194 | P20: =(D20-J20)/($S$6-$S$2) -> 608.67519
... A48: =A47+1 -> 47 | B48: Nov '22 | C48: =Ammonia!C48 -> 1596.0345 | D48: =Ammonia!E48 -> 1343.949 | E48: 1273.1894 | F48: 1642.4772 | G48: 1816.0934 | H48: 2834.4325 | I48: 1343.9136 | J48: 2141.2701 | K48: =(D48-E48)/($S$4-$S$2) -> -47.236053 | L48: =(D48-F48)/($S$4-$S$2) -> 199.28453 | M48: =(D48-G48)/($S$5-$S$2) -> 449.6613 | N48: =(D48-H48)/($S$5-$S$2) -> 1419.5081 | O48: =(D48-I48)/($S$6-$S$2) -> -0.017147761 | P48: =(D48-J48)/($S$6-$S$2) -> 386.29899

Sheet Ammonia avoidance
B1: Average | C1: Low | D1: High
A2: Avg 19 | B2: =AVERAGE(Ammonia!K2:K13) -> 690.64955 | C2: =B2-AVERAGE('Ammonia high low'!K2:K13) -> 194.09127 | D2: =AVERAGE('Ammonia high low'!L2:L13)-B2 -> 187.62156 | E2: Wind
A3: Avg 19 | B3: =AVERAGE(Ammonia!L2:L13) -> 1377.1368 | C3: =B3-AVERAGE('Ammonia high low'!M2:M13) -> 147.68189 | D3: =AVERAGE('Ammonia high low'!N2:N13)-B3 -> 1126.0744 | E3: Solar
A4: Avg 19 | B4: =AVERAGE(Ammonia!V2:V13) -> 93.537059 | C4: 0 | D4: 0 | E4: SMR CCS
A5: Avg 19 | B5: 0
A6: Avg 20 | B6: =AVERAGE(Ammonia!K14:K25) -> 571.54688 | C6: =B6-AVERAGE('Ammonia high low'!K14:K25) -> 64.697089 | D6: =AVERAGE('Ammonia high low'!L14:L25)-B6 -> 129.39418 | E6: Wind
A7: Avg 20 | B7: =AVERAGE(Ammonia!L14:L25) -> 1387.8756 | C7: =B7-AVERAGE('Ammonia high low'!M14:M25) -> 166.14212 | D7: =AVERAGE('Ammonia high low'!N14:N25)-B7 -> 978.39251 | E7: Solar
A8: Avg 20 | B8: =AVERAGE(Ammonia!V14:V25) -> 86.794559 | C8: 0 | D8: 0 | E8: SMR CCS
A9: Avg 20 | B9: 0
A10: Jul '21 | B10: =Ammonia!K32 -> 374.04405 | C10: =B10-'Ammonia high low'!K32 -> 103.51534 | D10: =-(B10-'Ammonia high low'!L32) -> 109.98505 | E10: Wind
A11: Jul '21 | B11: =Ammonia!L32 -> 1009.1215 | C11: =B11-'Ammonia high low'!M32 -> 175.37224 | D11: =-B11+'Ammonia high low'!N32 -> 664.56849 | E11: Solar
A12: Jul '21 | B12: =Ammonia!V32 -> 130.55926 | C12: 0 | D12: 0 | E12: SMR CCS
A13: Jul '21 | B13: 0
A14: Oct '21 | B14: =Ammonia!K35 -> 64.663358 | C14: =B14-'Ammonia high low'!K35 -> 103.51534 | D14: =-(B14-'Ammonia high low'!L35) -> 109.98505 | E14: Wind
A15: Oct '21 | B15: =Ammonia!L35 -> 567.73839 | C15: =B15-'Ammonia high low'!M35 -> 175.37224 | D15: =-B15+'Ammonia high low'!N35 -> 664.56849 | E15: Solar
A16: Oct '21 | B16: =Ammonia!V35 -> 200.32155 | C16: 0 | D16: 0 | E16: SMR CCS
A17: Oct '21 | B17: 0
A18: Jan '22 | B18: =Ammonia!K38 -> 191.84771 | C18: =B18-'Ammonia high low'!K38 -> 119.52513 | D18: =-(B18-'Ammonia high low'!L38) -> 126.99545 | E18: Wind
A19: Jan '22 | B19: =Ammonia!L38 -> 822.72712 | C19: =B19-'Ammonia high low'!M38 -> 202.49549 | D19: =-B19+'Ammonia high low'!N38 -> 767.35133 | E19: Solar
A20: Jan '22 | B20: =Ammonia!V38 -> 194.04404 | C20: 0 | D20: 0 | E20: SMR CCS
A21: Jan '22 | B21: 0
A22: Apr '22 | B22: =Ammonia!K41 -> 130.52793 | C22: =B22-'Ammonia high low'!K41 -> 119.52513 | D22: =-(B22-'Ammonia high low'!L41) -> 126.99545 | E22: Wind
A23: Apr '22 | B23: =Ammonia!L41 -> 735.24422 | C23: =B23-'Ammonia high low'!M41 -> 202.49549 | D23: =-B23+'Ammonia high low'!N41 -> 767.35133 | E23: Solar
A24: Apr '22 | B24: =Ammonia!V41 -> 212.91633 | C24: 0 | D24: 0 | E24: SMR CCS
A25: Apr '22 | B25: 0
A26: Jul '22 | B26: =Ammonia!K44 -> -216.40312 | C26: =B26-'Ammonia high low'!K44 -> 119.52513 | D26: =-(B26-'Ammonia high low'!L44) -> 126.99545 | E26: Wind
A27: Jul '22 | B27: =Ammonia!L44 -> 240.28925 | C27: =B27-'Ammonia high low'!M44 -> 202.49549 | D27: =-B27+'Ammonia high low'!N44 -> 767.35133 | E27: Solar
A28: Jul '22 | B28: =Ammonia!V44 -> 259.57716 | C28: 0 | D28: 0 | E28: SMR CCS
A29: Jul '22 | B29: 0
A30: Aug '22 | B30: =Ammonia!K45 -> -558.23651 | C30: =B30-'Ammonia high low'!K45 -> 119.52513 | D30: =-(B30-'Ammonia high low'!L45) -> 126.99545 | E30: Wind
A31: Aug '22 | B31: =Ammonia!L45 -> -247.39304 | C31: =B31-'Ammonia high low'!M45 -> 202.49549 | D31: =-B31+'Ammonia high low'!N45 -> 767.35133 | E31: Solar
A32: Aug '22 | B32: =Ammonia!V45 -> 302.91105 | C32: 0 | D32: 0 | E32: SMR CCS
A33: Aug '22 | B33: 0
A34: Sep '22 | B34: =Ammonia!K46 -> -352.43537 | C34: =B34-'Ammonia high low'!K46 -> 119.52513 | D34: =-(B34-'Ammonia high low'!L46) -> 126.99545 | E34: Wind
A35: Sep '22 | B35: =Ammonia!L46 -> 46.216581 | C35: =B35-'Ammonia high low'!M46 -> 202.49549 | D35: =-B35+'Ammonia high low'!N46 -> 767.35133 | E35: Solar
A36: Sep '22 | B36: =Ammonia!V46 -> 282.98963 | C36: 0 | D36: 0 | E36: SMR CCS
A37: Sep '22 | B37: 0
A38: Nov '22 | B38: =Ammonia!K48 -> 72.289077 | C38: =B38-'Ammonia high low'!K48 -> 119.52513 | D38: =-(B38-'Ammonia high low'!L48) -> 126.99545 | E38: Wind
A39: Nov '22 | B39: =Ammonia!L48 -> 652.15679 | C39: =B39-'Ammonia high low'!M48 -> 202.49549 | D39: =-(B39-'Ammonia high low'!N48) -> 767.35133 | E39: Solar
A40: Nov '22 | B40: =Ammonia!V48 -> 226.61846 | C40: 0 | D40: 0 | E40: SMR CCS
...

Sheet Methanol
A1: Index | B1: Time | C1: NG price | D1: Market | E1: BAU | F1: DAC + biomass | G1: DAC + wind | H1: DAC + solar | I1: DAC + nuclear | J1: CO2 DAC + biomass | K1: CO2 DAC + wind | L1: CO2 DAC + solar | M1: CO2 DAC + nuclear | N1: Grid | P1: Process | Q1: GWP | S1: SMR CCS | T1: CO2 SMR CCS
A2: 1 | B2: Jan '19 | C2: 326.17727 | D2: 419.11765 | E2: 309.3765 | F2: 332.25223 | G2: 1717.5181 | H2: 2161.1111 | I2: 1723.8071 | J2: =(E2-F2)/($Q$3-$Q$2) -> 9.2839815 | K2: =(E2-G2)/($Q$4-$Q$2) -> 1612.9915 | L2: =(E2-H2)/($Q$5-$Q$2) -> 7496.9011 | M2: =(E2-I2)/($Q$6-$Q$2) -> 1040.0225 | N2: 1325.3713 | P2: BAU | Q2: 0.674 | R2: =(S2-E2)/E2*100 -> 175.08726 | S2: 851.05532 | T2: =(E2-S2)/($Q$7-$Q$2) -> 3043.1395
A3: =A2+1 -> 2 | B3: Feb '19 | C3: 268.53773 | D3: 400 | E3: 271.21328 | F3: 331.58899 | G3: 1706.5293 | H3: 2150.1223 | I3: 1712.8183 | J3: =(E3-F3)/($Q$3-$Q$2) -> 24.503133 | K3: =(E3-G3)/($Q$4-$Q$2) -> 1644.1191 | L3: =(E3-H3)/($Q$5-$Q$2) -> 7606.919 | M3: =(E3-I3)/($Q$6-$Q$2) -> 1060.0037 | N3: 1245.4125 | P3: DAC + biomass | Q3: -1.79 | R3: =(S3-E3)/E3*100 -> 193.76079 | S3: 796.71826 | T3: =(E3-S3)/($Q$7-$Q$2) -> 2952.2752
A4: =A3+1 -> 3 | B4: Mar '19 | C4: 231.45182 | D4: 400 | E4: 246.07009 | F4: 330.36302 | G4: 1697.0729 | H4: 2140.6659 | I4: 1703.3619 | J4: =(E4-F4)/($Q$3-$Q$2) -> 34.209793 | K4: =(E4-G4)/($Q$4-$Q$2) -> 1662.088 | L4: =(E4-H4)/($Q$5-$Q$2) -> 7670.4284 | M4: =(E4-I4)/($Q$6-$Q$2) -> 1071.5381 | N4: 1108.4662 | P4: DAC + wind | Q4: -0.199 | R4: =(S4-E4)/E4*100 -> 208.59954 | S4: 759.37116 | T4: =(E4-S4)/($Q$7-$Q$2) -> 2883.7139
A5: =A4+1 -> 4 | B5: Apr '19 | C5: 219.83455 | D5: 397.05882 | E5: 238.94735 | F5: 331.00213 | G5: 1697.1652 | H5: 2140.7582 | I5: 1703.4542 | J5: =(E5-F5)/($Q$3-$Q$2) -> 37.359895 | K5: =(E5-G5)/($Q$4-$Q$2) -> 1670.3526 | L5: =(E5-H5)/($Q$5-$Q$2) -> 7699.639 | M5: =(E5-I5)/($Q$6-$Q$2) -> 1076.8433 | N5: 1175.0204 | P5: DAC + solar | Q5: 0.427 | R5: =(S5-E5)/E5*100 -> 214.18074 | S5: 750.72657 | T5: =(E5-S5)/($Q$7-$Q$2) -> 2875.1641
A6: =A5+1 -> 5 | B6: May '19 | C6: 193.91909 | D6: 394.11765 | E6: 222.07192 | F6: 331.08855 | G6: 1693.3727 | H6: 2136.9657 | I6: 1699.6617 | J6: =(E6-F6)/($Q$3-$Q$2) -> 44.243762 | K6: =(E6-G6)/($Q$4-$Q$2) -> 1685.3388 | L6: =(E6-H6)/($Q$5-$Q$2) -> 7752.6065 | M6: =(E6-I6)/($Q$6-$Q$2) -> 1086.4631 | N6: 1180.215 | P6: DAC + nuclear | Q6: -0.686 | R6: =(S6-E6)/E6*100 -> 227.57143 | S6: 727.44418 | T6: =(E6-S6)/($Q$7-$Q$2) -> 2839.17
A7: =A6+1 -> 6 | B7: Jun '19 | C7: 160.40773 | D7: 398.52941 | E7: 199.77354 | F7: 330.55294 | G7: 1686.536 | H7: 2130.129 | I7: 1692.825 | J7: =(E7-F7)/($Q$3-$Q$2) -> 53.076057 | K7: =(E7-G7)/($Q$4-$Q$2) -> 1703.0498 | L7: =(E7-H7)/($Q$5-$Q$2) -> 7815.2045 | M7: =(E7-I7)/($Q$6-$Q$2) -> 1097.832 | N7: 1117.6798 | P7: SMR CCS | Q7: 0.496 | R7: =(S7-E7)/E7*100 -> 248.09667 | S7: 695.40503 | T7: =(E7-S7)/($Q$7-$Q$2) -> 2784.4466
A8: =A7+1 -> 7 | B8: Jul '19 | C8: 161.74818 | D8: 344.11765 | E8: 201.18324 | F8: 331.27748 | G8: 1688.9086 | H8: 2132.5016 | I8: 1695.1976 | J8: =(E8-F8)/($Q$3-$Q$2) -> 52.797987 | K8: =(E8-G8)/($Q$4-$Q$2) -> 1704.1527 | L8: =(E8-H8)/($Q$5-$Q$2) -> 7819.1025 | M8: =(E8-I8)/($Q$6-$Q$2) -> 1098.5399 | N8: 1195.3968 | R8: =(S8-E8)/E8*100 -> 247.3379 | S8: 698.78564 | T8: =(E8-S8)/($Q$7-$Q$2) -> 2795.5191
A9: =A8+1 -> 8 | B9: Aug '19 | C9: 164.42909 | D9: 341.17647 | E9: 202.72169 | F9: 330.98706 | G9: 1688.4606 | H9: 2132.0536 | I9: 1694.7496 | J9: =(E9-F9)/($Q$3-$Q$2) -> 52.055749 | K9: =(E9-G9)/($Q$4-$Q$2) -> 1701.8773 | L9: =(E9-H9)/($Q$5-$Q$2) -> 7811.0602 | M9: =(E9-I9)/($Q$6-$Q$2) -> 1097.0793 | N9: 1164.7483 | R9: =(S9-E9)/E9*100 -> 245.47553 | S9: 700.35385 | T9: =(E9-S9)/($Q$7-$Q$2) -> 2795.6863
A10: =A9+1 -> 9 | B10: Sep '19 | C10: 188.11045 | D10: 336.76471 | E10: 218.1228 | F10: 330.88155 | G10: 1691.8469 | H10: 2135.4399 | I10: 1698.1359 | J10: =(E10-F10)/($Q$3-$Q$2) -> 45.762479 | K10: =(E10-G10)/($Q$4-$Q$2) -> 1688.1146 | L10: =(E10-H10)/($Q$5-$Q$2) -> 7762.4172 | M10: =(E10-I10)/($Q$6-$Q$2) -> 1088.2449 | N10: 1157.1621 | R10: =(S10-E10)/E10*100 -> 230.79985 | S10: 721.54989 | T10: =(E10-S10)/($Q$7-$Q$2) -> 2828.2421
A11: =A10+1 -> 10 | B11: Oct '19 | C11: 226.09 | D11: 322.05882 | E11: 243.03461 | F11: 331.00012 | G11: 1698.1369 | H11: 2141.7299 | I11: 1704.4259 | J11: =(E11-F11)/($Q$3-$Q$2) -> 35.700289 | K11: =(E11-G11)/($Q$4-$Q$2) -> 1666.7838 | L11: =(E11-H11)/($Q$5-$Q$2) -> 7687.0254 | M11: =(E11-I11)/($Q$6-$Q$2) -> 1074.5524 | N11: 1175.7831 | R11: =(S11-E11)/E11*100 -> 211.23251 | S11: 756.40273 | T11: =(E11-S11)/($Q$7-$Q$2) -> 2884.0906
A12: =A11+1 -> 11 | B12: Nov '19 | C12: 230.11136 | D12: 305.88235 | E12: 245.96279 | F12: 331.40711 | G12: 1699.9804 | H12: 2143.5734 | I12: 1706.2694 | J12: =(E12-F12)/($Q$3-$Q$2) -> 34.677078 | K12: =(E12-G12)/($Q$4-$Q$2) -> 1665.5414 | L12: =(E12-H12)/($Q$5-$Q$2) -> 7682.6341 | M12: =(E12-I12)/($Q$6-$Q$2) -> 1073.7549 | N12: 1219.9491 | R12: =(S12-E12)/E12*100 -> 209.50639 | S12: 761.27055 | T12: =(E12-S12)/($Q$7-$Q$2) -> 2894.9874
A13: =A12+1 -> 12 | B13: Dec '19 | C13: 206.43 | D13: 308.82353 | E13: 229.81577 | F13: 330.49968 | G13: 1693.5701 | H13: 2137.1631 | I13: 1699.8591 | J13: =(E13-F13)/($Q$3-$Q$2) -> 40.86198 | K13: =(E13-G13)/($Q$4-$Q$2) -> 1676.6946 | L13: =(E13-H13)/($Q$5-$Q$2) -> 7722.0541 | M13: =(E13-I13)/($Q$6-$Q$2) -> 1080.9142 | N13: 1119.1754 | R13: =(S13-E13)/E13*100 -> 220.71364 | S13: 737.05051 | T13: =(E13-S13)/($Q$7-$Q$2) -> 2849.6334
A14: =A13+1 -> 13 | B14: Jan '20 | C14: 162.195 | D14: 302.94118 | E14: 199.40429 | F14: 324.71435 | G14: 1444.4935 | H14: 2092.6215 | I14: 1494.2925 | J14: =(E14-F14)/($Q$3-$Q$2) -> 50.856355 | K14: =(E14-G14)/($Q$4-$Q$2) -> 1426.219 | L14: =(E14-H14)/($Q$5-$Q$2) -> 7664.8469 | M14: =(E14-I14)/($Q$6-$Q$2) -> 952.12367 | N14: 1138.2172 | R14: =(S14-E14)/E14*100 -> 244.89179 | S14: 687.72902 | T14: =(E14-S14)/($Q$7-$Q$2) -> 2743.3974
A15: =A14+1 -> 14 | B15: Feb '20 | C15: 130.02409 | D15: 298.52941 | E15: 177.4093 | F15: 323.40095 | G15: 1435.5443 | H15: 2083.6723 | I15: 1485.3433 | J15: =(E15-F15)/($Q$3-$Q$2) -> 59.249854 | K15: =(E15-G15)/($Q$4-$Q$2) -> 1441.1627 | L15: =(E15-H15)/($Q$5-$Q$2) -> 7717.664 | M15: =(E15-I15)/($Q$6-$Q$2) -> 961.71619 | N15: 992.68656 | R15: =(S15-E15)/E15*100 -> 268.96908 | S15: 654.58548 | T15: =(E15-S15)/($Q$7-$Q$2) -> 2680.765
A16: =A15+1 -> 15 | B16: Mar '20 | C16: 121.53455 | D16: 300 | E16: 171.90544 | F16: 323.46224 | G16: 1434.4004 | H16: 2082.5284 | I16: 1484.1994 | J16: =(E16-F16)/($Q$3-$Q$2) -> 61.508444 | K16: =(E16-G16)/($Q$4-$Q$2) -> 1446.1569 | L16: =(E16-H16)/($Q$5-$Q$2) -> 7735.3158 | M16: =(E16-I16)/($Q$6-$Q$2) -> 964.92206 | N16: 997.91718 | R16: =(S16-E16)/E16*100 -> 276.40285 | S16: 647.05697 | T16: =(E16-S16)/($Q$7-$Q$2) -> 2669.3906
A17: =A16+1 -> 16 | B17: Apr '20 | C17: 94.725455 | E17: 153.97749 | F17: 322.91256 | G17: 1428.5693 | H17: 2076.6973 | I17: 1478.3683 | J17: =(E17-F17)/($Q$3-$Q$2) -> 68.561314 | K17: =(E17-G17)/($Q$4-$Q$2) -> 1460.0135 | L17: =(E17-H17)/($Q$5-$Q$2) -> 7784.2908 | M17: =(E17-I17)/($Q$6-$Q$2) -> 973.81678 | N17: 934.92455 | R17: =(S17-E17)/E17*100 -> 303.34718 | S17: 621.06385 | T17: =(E17-S17)/($Q$7-$Q$2) -> 2624.0807
A18: =A17+1 -> 17 | B18: May '20 | C18: 70.597273 | E18: 138.24733 | F18: 322.96783 | G18: 1424.9632 | H18: 2073.0912 | I18: 1474.7622 | J18: =(E18-F18)/($Q$3-$Q$2) -> 74.967737 | K18: =(E18-G18)/($Q$4-$Q$2) -> 1473.9013 | L18: =(E18-H18)/($Q$5-$Q$2) -> 7833.3759 | M18: =(E18-I18)/($Q$6-$Q$2) -> 982.73151 | N18: 937.06592 | R18: =(S18-E18)/E18*100 -> 333.50706 | S18: 599.31194 | T18: =(E18-S18)/($Q$7-$Q$2) -> 2590.2506
A19: =A18+1 -> 18 | B19: Jun '20 | C19: 78.193182 | E19: 143.85085 | F19: 323.83506 | G19: 1428.7394 | H19: 2076.8674 | I19: 1478.5384 | J19: =(E19-F19)/($Q$3-$Q$2) -> 73.045541 | K19: =(E19-G19)/($Q$4-$Q$2) -> 1471.8082 | L19: =(E19-H19)/($Q$5-$Q$2) -> 7825.9779 | M19: =(E19-I19)/($Q$6-$Q$2) -> 981.3879 | N19: 1031.0256 | R19: =(S19-E19)/E19*100 -> 323.21662 | S19: 608.8007 | T19: =(E19-S19)/($Q$7-$Q$2) -> 2612.0778
A20: =A19+1 -> 19 | B20: Jul '20 | C20: 80.427273 | E20: 145.59527 | F20: 324.22094 | G20: 1430.2406 | H20: 2078.3686 | I20: 1480.0396 | J20: =(E20-F20)/($Q$3-$Q$2) -> 72.494184 | K20: =(E20-G20)/($Q$4-$Q$2) -> 1471.5295 | L20: =(E20-H20)/($Q$5-$Q$2) -> 7824.9931 | M20: =(E20-I20)/($Q$6-$Q$2) -> 981.20904 | N20: 1072.6548 | R20: =(S20-E20)/E20*100 -> 320.33098 | S20: 611.98205 | T20: =(E20-S20)/($Q$7-$Q$2) -> 2620.1504
A21: =A20+1 -> 20 | B21: Aug '20 | C21: 127.79 | E21: 176.90956 | F21: 324.70531 | G21: 1439.0891 | H21: 2087.2171 | I21: 1488.8881 | J21: =(E21-F21)/($Q$3-$Q$2) -> 59.98204 | K21: =(E21-G21)/($Q$4-$Q$2) -> 1445.7956 | L21: =(E21-H21)/($Q$5-$Q$2) -> 7734.0388 | M21: =(E21-I21)/($Q$6-$Q$2) -> 964.69013 | N21: 1131.8724 | R21: =(S21-E21)/E21*100 -> 271.06538 | S21: 656.45013 | T21: =(E21-S21)/($Q$7-$Q$2) -> 2694.0482
A22: =A21+1 -> 21 | B22: Sep '20 | C22: 176.49318 | E22: 209.39378 | F22: 325.58861 | G22: 1449.3382 | H22: 2097.4662 | I22: 1499.1372 | J22: =(E22-F22)/($Q$3-$Q$2) -> 47.156992 | K22: =(E22-G22)/($Q$4-$Q$2) -> 1420.3258 | L22: =(E22-H22)/($Q$5-$Q$2) -> 7644.018 | M22: =(E22-I22)/($Q$6-$Q$2) -> 948.34077 | N22: 1233.977 | R22: =(S22-E22)/E22*100 -> 235.88715 | S22: 703.32682 | T22: =(E22-S22)/($Q$7-$Q$2) -> 2774.9047
A23: =A22+1 -> 22 | B23: Oct '20 | C23: 218.49409 | E23: 236.12748 | F23: 324.61185 | G23: 1452.9868 | H23: 2101.1148 | I23: 1502.7858 | J23: =(E23-F23)/($Q$3-$Q$2) -> 35.910866 | K23: =(E23-G23)/($Q$4-$Q$2) -> 1393.8824 | L23: =(E23-H23)/($Q$5-$Q$2) -> 7550.5559 | M23: =(E23-I23)/($Q$6-$Q$2) -> 931.3664 | N23: 1136.0515 | R23: =(S23-E23)/E23*100 -> 212.78125 | S23: 738.56248 | T23: =(E23-S23)/($Q$7-$Q$2) -> 2822.6686
A24: =A23+1 -> 23 | B24: Nov '20 | C24: 216.26 | E24: 235.02537 | F24: 325.09822 | G24: 1454.0896 | H24: 2102.2176 | I24: 1503.8886 | J24: =(E24-F24)/($Q$3-$Q$2) -> 36.55554 | K24: =(E24-G24)/($Q$4-$Q$2) -> 1396.4081 | L24: =(E24-H24)/($Q$5-$Q$2) -> 7559.4827 | M24: =(E24-I24)/($Q$6-$Q$2) -> 932.98767 | N24: 1187.7323 | R24: =(S24-E24)/E24*100 -> 214.00233 | S24: 737.98514 | T24: =(E24-S24)/($Q$7-$Q$2) -> 2825.6167
A25: =A24+1 -> 24 | B25: Dec '20 | C25: 261.83545 | E25: 265.16627 | F25: 325.57555 | G25: 1462.6378 | H25: 2110.7658 | I25: 1512.4368 | J25: =(E25-F25)/($Q$3-$Q$2) -> 24.516755 | K25: =(E25-G25)/($Q$4-$Q$2) -> 1371.6742 | L25: =(E25-H25)/($Q$5-$Q$2) -> 7472.063 | M25: =(E25-I25)/($Q$6-$Q$2) -> 917.11071 | N25: 1245.9181 | R25: =(S25-E25)/E25*100 -> 194.46006 | S25: 780.80875 | T25: =(E25-S25)/($Q$7-$Q$2) -> 2896.8679
A26: =A25+1 -> 25 | B26: Jan '21 | C26: 324.83682 | E26: 324.05649 | F26: 386.73566 | G26: 1489.6898 | H26: 2028.0168 | I26: 1723.5988 | J26: =(E26-F26)/($Q$3-$Q$2) -> 25.437974 | K26: =(E26-G26)/($Q$4-$Q$2) -> 1335.2043 | L26: =(E26-H26)/($Q$5-$Q$2) -> 6898.6248 | M26: =(E26-I26)/($Q$6-$Q$2) -> 1029.0752 | N26: 1418.4341 | R26: =(S26-E26)/E26*100 -> 190.12734 | S26: 940.17647 | T26: =(E26-S26)/($Q$7-$Q$2) -> 3461.3482
A27: =A26+1 -> 26 | B27: Feb '21 | C27: 275.24 | E27: 291.3367 | F27: 386.32566 | G27: 1480.7141 | H27: 2019.0411 | I27: 1714.6231 | J27: =(E27-F27)/($Q$3-$Q$2) -> 38.550714 | K27: =(E27-G27)/($Q$4-$Q$2) -> 1362.4025 | L27: =(E27-H27)/($Q$5-$Q$2) -> 6994.7545 | M27: =(E27-I27)/($Q$6-$Q$2) -> 1046.5341 | N27: 1366.8223 | R27: =(S27-E27)/E27*100 -> 206.82747 | S27: 893.90105 | T27: =(E27-S27)/($Q$7-$Q$2) -> 3385.1929
A28: =A27+1 -> 27 | B28: Mar '21 | C28: 273.89955 | E28: 290.34733 | F28: 386.17191 | G28: 1480.0456 | H28: 2018.3726 | I28: 1713.9546 | J28: =(E28-F28)/($Q$3-$Q$2) -> 38.88985 | K28: =(E28-G28)/($Q$4-$Q$2) -> 1362.77 | L28: =(E28-H28)/($Q$5-$Q$2) -> 6996.0536 | M28: =(E28-I28)/($Q$6-$Q$2) -> 1046.77 | N28: 1350.1653 | R28: =(S28-E28)/E28*100 -> 207.29556 | S28: 892.22444 | T28: =(E28-S28)/($Q$7-$Q$2) -> 3381.3321
... A48: =A47+1 -> 47 | B48: Nov '22 | C48: 1596.0345 | E48: 1180.7005 | F48: 458.05424 | G48: 1945.2656 | H48: 2566.8508 | I48: 2215.3512 | J48: =(E48-F48)/($Q$3-$Q$2) -> -293.28177 | K48: =(E48-G48)/($Q$4-$Q$2) -> 875.79045 | L48: =(E48-H48)/($Q$5-$Q$2) -> 5611.9444 | M48: =(E48-I48)/($Q$6-$Q$2) -> 760.77255 | N48: 2997.7476 | R48: =(S48-E48)/E48*100 -> 88.785804 | S48: 2228.995 | T48: =(E48-S48)/($Q$7-$Q$2) -> 5889.2947

Sheet Methanol summary
B1: Natural gas | C1: BAU | D1: Wind | E1: Solar | F1: Nuclear | G1: Biomass | H1: SMR + CCS
A2: =Ammonia!B2 -> Jan '19 | B2: =Methanol!C2 -> 326.17727 | C2: =Methanol!E2 -> 309.3765 | D2: =Methanol!G2 -> 1717.5181 | E2: =Methanol!H2 -> 2161.1111 | F2: =Methanol!I2 -> 1723.8071 | G2: =Methanol!F2 -> 332.25223 | H2: =Methanol!S2 -> 851.05532
A3: =Ammonia!B3 -> Feb '19 | B3: =Methanol!C3 -> 268.53773 | C3: =Methanol!E3 -> 271.21328 | D3: =Methanol!G3 -> 1706.5293 | E3: =Methanol!H3 -> 2150.1223 | F3: =Methanol!I3 -> 1712.8183 | G3: =Methanol!F3 -> 331.58899 | H3: =Methanol!S3 -> 796.71826
A4: =Ammonia!B4 -> Mar '19 | B4: =Methanol!C4 -> 231.45182 | C4: =Methanol!E4 -> 246.07009 | D4: =Methanol!G4 -> 1697.0729 | E4: =Methanol!H4 -> 2140.6659 | F4: =Methanol!I4 -> 1703.3619 | G4: =Methanol!F4 -> 330.36302 | H4: =Methanol!S4 -> 759.37116
A5: =Ammonia!B5 -> Apr '19 | B5: =Methanol!C5 -> 219.83455 | C5: =Methanol!E5 -> 238.94735 | D5: =Methanol!G5 -> 1697.1652 | E5: =Methanol!H5 -> 2140.7582 | F5: =Methanol!I5 -> 1703.4542 | G5: =Methanol!F5 -> 331.00213 | H5: =Methanol!S5 -> 750.72657
A6: =Ammonia!B6 -> May '19 | B6: =Methanol!C6 -> 193.91909 | C6: =Methanol!E6 -> 222.07192 | D6: =Methanol!G6 -> 1693.3727 | E6: =Methanol!H6 -> 2136.9657 | F6: =Methanol!I6 -> 1699.6617 | G6: =Methanol!F6 -> 331.08855 | H6: =Methanol!S6 -> 727.44418
A7: =Ammonia!B7 -> Jun '19 | B7: =Methanol!C7 -> 160.40773 | C7: =Methanol!E7 -> 199.77354 | D7: =Methanol!G7 -> 1686.536 | E7: =Methanol!H7 -> 2130.129 | F7: =Methanol!I7 -> 1692.825 | G7: =Methanol!F7 -> 330.55294 | H7: =Methanol!S7 -> 695.40503
A8: =Ammonia!B8 -> Jul '19 | B8: =Methanol!C8 -> 161.74818 | C8: =Methanol!E8 -> 201.18324 | D8: =Methanol!G8 -> 1688.9086 | E8: =Methanol!H8 -> 2132.5016 | F8: =Methanol!I8 -> 1695.1976 | G8: =Methanol!F8 -> 331.27748 | H8: =Methanol!S8 -> 698.78564
A9: =Ammonia!B9 -> Aug '19 | B9: =Methanol!C9 -> 164.42909 | C9: =Methanol!E9 -> 202.72169 | D9: =Methanol!G9 -> 1688.4606 | E9: =Methanol!H9 -> 2132.0536 | F9: =Methanol!I9 -> 1694.7496 | G9: =Methanol!F9 -> 330.98706 | H9: =Methanol!S9 -> 700.35385
A10: =Ammonia!B10 -> Sep '19 | B10: =Methanol!C10 -> 188.11045 | C10: =Methanol!E10 -> 218.1228 | D10: =Methanol!G10 -> 1691.8469 | E10: =Methanol!H10 -> 2135.4399 | F10: =Methanol!I10 -> 1698.1359 | G10: =Methanol!F10 -> 330.88155 | H10: =Methanol!S10 -> 721.54989
A11: =Ammonia!B11 -> Oct '19 | B11: =Methanol!C11 -> 226.09 | C11: =Methanol!E11 -> 243.03461 | D11: =Methanol!G11 -> 1698.1369 | E11: =Methanol!H11 -> 2141.7299 | F11: =Methanol!I11 -> 1704.4259 | G11: =Methanol!F11 -> 331.00012 | H11: =Methanol!S11 -> 756.40273
A12: =Ammonia!B12 -> Nov '19 | B12: =Methanol!C12 -> 230.11136 | C12: =Methanol!E12 -> 245.96279 | D12: =Methanol!G12 -> 1699.9804 | E12: =Methanol!H12 -> 2143.5734 | F12: =Methanol!I12 -> 1706.2694 | G12: =Methanol!F12 -> 331.40711 | H12: =Methanol!S12 -> 761.27055
A13: =Ammonia!B13 -> Dec '19 | B13: =Methanol!C13 -> 206.43 | C13: =Methanol!E13 -> 229.81577 | D13: =Methanol!G13 -> 1693.5701 | E13: =Methanol!H13 -> 2137.1631 | F13: =Methanol!I13 -> 1699.8591 | G13: =Methanol!F13 -> 330.49968 | H13: =Methanol!S13 -> 737.05051
... A44: =Ammonia!B44 -> Jul '22 | B44: =Methanol!C44 -> 2293.5177 | C44: =Methanol!E44 -> 1646.941 | D44: =Methanol!G44 -> 2096.222 | E44: =Methanol!H44 -> 2717.8072 | F44: =Methanol!I44 -> 2366.3076 | G44: =Methanol!F44 -> 472.10375 | H44: =Methanol!S44 -> 2904.499
A45: =Ammonia!B45 -> Aug '22 | B45: =Methanol!C45 -> 3129.5145 | C45: =Methanol!E45 -> 2204.7746 | D45: =Methanol!G45 -> 2273.1115 | E45: =Methanol!H45 -> 2894.6967 | F45: =Methanol!I45 -> 2543.1971 | G45: =Methanol!F45 -> 487.58825 | H45: =Methanol!S45 -> 3710.1064 | J45: =(C45-D45)/C45*100 -> -3.0994945
A46: =Ammonia!B46 -> Sep '22 | B46: =Methanol!C46 -> 2640.6955 | C46: =Methanol!E46 -> 1877.1902 | D46: =Methanol!G46 -> 2163.9603 | E46: =Methanol!H46 -> 2785.5455 | F46: =Methanol!I46 -> 2434.0459 | G46: =Methanol!F46 -> 476.61776 | H46: =Methanol!S46 -> 3233.335
A47: =Ammonia!B47 -> Oct '22 | B47: =Methanol!C47 -> 1743.4845 | C47: =Methanol!E47 -> 1275.7704 | D47: =Methanol!G47 -> 1963.0103 | E47: =Methanol!H47 -> 2584.5955 | F47: =Methanol!I47 -> 2233.0959 | G47: =Methanol!F47 -> 456.27858 | H47: =Methanol!S47 -> 2357.6306
A48: =Ammonia!B48 -> Nov '22 | B48: =Methanol!C48 -> 1596.0345 | C48: =Methanol!E48 -> 1180.7005 | D48: =Methanol!G48 -> 1945.2656 | E48: =Methanol!H48 -> 2566.8508 | F48: =Methanol!I48 -> 2215.3512 | G48: =Methanol!F48 -> 458.05424 | H48: =Methanol!S48 -> 2228.995

Sheet Methanol high low
A1: Index | B1: Time | C1: NG price | D1: BAU | E1: DAC + wind low | F1: DAC + wind high | G1: DAC + solar low | H1: DAC + solar high | I1: DAC + nuclear low | J1: DAC + nuclear high | K1: CO2 DAC + wind low | L1: CO2 DAC + wind high | M1: CO2 DAC + solar low | N1: CO2 DAC + solar high | O1: CO2 DAC + nuclear low | P1: CO2 DAC + nuclear high | R1: Process | S1: GWP
A2: 1 | B2: Jan '19 | C2: 326.17727 | D2: =Methanol!E2 -> 309.3765 | E2: 1303.2431 | F2: 2121.3431 | G2: 1893.1361 | H2: 3536.7861 | I2: 1365.1831 | J2: 2082.4311 | K2: =(D2-E2)/($S$3-$S$2) -> 1138.4497 | L2: =(D2-F2)/($S$3-$S$2) -> 2075.5631 | M2: =(D2-G2)/($S$4-$S$2) -> 6411.9821 | N2: =(D2-H2)/($S$4-$S$2) -> 13066.436 | O2: =(D2-I2)/($S$5-$S$2) -> 776.32836 | P2: =(D2-J2)/($S$5-$S$2) -> 1303.7166 | R2: BAU | S2: 0.674
A3: =A2+1 -> 2 | B3: Feb '19 | C3: 268.53773 | D3: =Methanol!E3 -> 271.21328 | E3: 1292.2543 | F3: 2110.3543 | G3: 1882.1473 | H3: 3525.7973 | I3: 1354.1943 | J3: 2071.4423 | K3: =(D3-E3)/($S$3-$S$2) -> 1169.5773 | L3: =(D3-F3)/($S$3-$S$2) -> 2106.6907 | M3: =(D3-G3)/($S$4-$S$2) -> 6522 | N3: =(D3-H3)/($S$4-$S$2) -> 13176.453 | O3: =(D3-I3)/($S$5-$S$2) -> 796.30956 | P3: =(D3-J3)/($S$5-$S$2) -> 1323.6978 | R3: DAC + wind | S3: -0.199
A4: =A3+1 -> 3 | B4: Mar '19 | C4: 231.45182 | D4: =Methanol!E4 -> 246.07009 | E4: 1282.7979 | F4: 2100.8979 | G4: 1872.6909 | H4: 3516.3409 | I4: 1344.7379 | J4: 2061.9859 | K4: =(D4-E4)/($S$3-$S$2) -> 1187.5462 | L4: =(D4-F4)/($S$3-$S$2) -> 2124.6596 | M4: =(D4-G4)/($S$4-$S$2) -> 6585.5094 | N4: =(D4-H4)/($S$4-$S$2) -> 13239.963 | O4: =(D4-I4)/($S$5-$S$2) -> 807.84399 | P4: =(D4-J4)/($S$5-$S$2) -> 1335.2322 | R4: DAC + solar | S4: 0.427
A5: =A4+1 -> 4 | B5: Apr '19 | C5: 219.83455 | D5: =Methanol!E5 -> 238.94735 | E5: 1282.8902 | F5: 2100.9902 | G5: 1872.7832 | H5: 3516.4332 | I5: 1344.8302 | J5: 2062.0782 | K5: =(D5-E5)/($S$3-$S$2) -> 1195.8108 | L5: =(D5-F5)/($S$3-$S$2) -> 2132.9242 | M5: =(D5-G5)/($S$4-$S$2) -> 6614.72 | N5: =(D5-H5)/($S$4-$S$2) -> 13269.173 | O5: =(D5-I5)/($S$5-$S$2) -> 813.14914 | P5: =(D5-J5)/($S$5-$S$2) -> 1340.5374 | R5: DAC + nuclear | S5: -0.686
A6: =A5+1 -> 5 | B6: May '19 | C6: 193.91909 | D6: =Methanol!E6 -> 222.07192 | E6: 1279.0977 | F6: 2097.1977 | G6: 1868.9907 | H6: 3512.6407 | I6: 1341.0377 | J6: 2058.2857 | K6: =(D6-E6)/($S$3-$S$2) -> 1210.797 | L6: =(D6-F6)/($S$3-$S$2) -> 2147.9104 | M6: =(D6-G6)/($S$4-$S$2) -> 6667.6874 | N6: =(D6-H6)/($S$4-$S$2) -> 13322.141 | O6: =(D6-I6)/($S$5-$S$2) -> 822.76897 | P6: =(D6-J6)/($S$5-$S$2) -> 1350.1572 | R6: SMR CCS | S6: 0.496
A7: =A6+1 -> 6 | B7: Jun '19 | C7: 160.40773 | D7: =Methanol!E7 -> 199.77354 | E7: 1272.261 | F7: 2090.361 | G7: 1862.154 | H7: 3505.804 | I7: 1334.201 | J7: 2051.449 | K7: =(D7-E7)/($S$3-$S$2) -> 1228.508 | L7: =(D7-F7)/($S$3-$S$2) -> 2165.6214 | M7: =(D7-G7)/($S$4-$S$2) -> 6730.2855 | N7: =(D7-H7)/($S$4-$S$2) -> 13384.739 | O7: =(D7-I7)/($S$5-$S$2) -> 834.13787 | P7: =(D7-J7)/($S$5-$S$2) -> 1361.5261
A8: =A7+1 -> 7 | B8: Jul '19 | C8: 161.74818 | D8: =Methanol!E8 -> 201.18324 | E8: 1274.6336 | F8: 2092.7336 | G8: 1864.5266 | H8: 3508.1766 | I8: 1336.5736 | J8: 2053.8216 | K8: =(D8-E8)/($S$3-$S$2) -> 1229.6109 | L8: =(D8-F8)/($S$3-$S$2) -> 2166.7243 | M8: =(D8-G8)/($S$4-$S$2) -> 6734.1835 | N8: =(D8-H8)/($S$4-$S$2) -> 13388.637 | O8: =(D8-I8)/($S$5-$S$2) -> 834.84582 | P8: =(D8-J8)/($S$5-$S$2) -> 1362.2341
A9: =A8+1 -> 8 | B9: Aug '19 | C9: 164.42909 | D9: =Methanol!E9 -> 202.72169 | E9: 1274.1856 | F9: 2092.2856 | G9: 1864.0786 | H9: 3507.7286 | I9: 1336.1256 | J9: 2053.3736 | K9: =(D9-E9)/($S$3-$S$2) -> 1227.3355 | L9: =(D9-F9)/($S$3-$S$2) -> 2164.4489 | M9: =(D9-G9)/($S$4-$S$2) -> 6726.1412 | N9: =(D9-H9)/($S$4-$S$2) -> 13380.595 | O9: =(D9-I9)/($S$5-$S$2) -> 833.3852 | P9: =(D9-J9)/($S$5-$S$2) -> 1360.7734
A10: =A9+1 -> 9 | B10: Sep '19 | C10: 188.11045 | D10: =Methanol!E10 -> 218.1228 | E10: 1277.5719 | F10: 2095.6719 | G10: 1867.4649 | H10: 3511.1149 | I10: 1339.5119 | J10: 2056.7599 | K10: =(D10-E10)/($S$3-$S$2) -> 1213.5728 | L10: =(D10-F10)/($S$3-$S$2) -> 2150.6862 | M10: =(D10-G10)/($S$4-$S$2) -> 6677.4982 | N10: =(D10-H10)/($S$4-$S$2) -> 13331.952 | O10: =(D10-I10)/($S$5-$S$2) -> 824.55078 | P10: =(D10-J10)/($S$5-$S$2) -> 1351.939
A11: =A10+1 -> 10 | B11: Oct '19 | C11: 226.09 | D11: =Methanol!E11 -> 243.03461 | E11: 1283.8619 | F11: 2101.9619 | G11: 1873.7549 | H11: 3517.4049 | I11: 1345.8019 | J11: 2063.0499 | K11: =(D11-E11)/($S$3-$S$2) -> 1192.242 | L11: =(D11-F11)/($S$3-$S$2) -> 2129.3554 | M11: =(D11-G11)/($S$4-$S$2) -> 6602.1064 | N11: =(D11-H11)/($S$4-$S$2) -> 13256.56 | O11: =(D11-I11)/($S$5-$S$2) -> 810.85829 | P11: =(D11-J11)/($S$5-$S$2) -> 1338.2465
A12: =A11+1 -> 11 | B12: Nov '19 | C12: 230.11136 | D12: =Methanol!E12 -> 245.96279 | E12: 1285.7054 | F12: 2103.8054 | G12: 1875.5984 | H12: 3519.2484 | I12: 1347.6454 | J12: 2064.8934 | K12: =(D12-E12)/($S$3-$S$2) -> 1190.9996 | L12: =(D12-F12)/($S$3-$S$2) -> 2128.113 | M12: =(D12-G12)/($S$4-$S$2) -> 6597.7151 | N12: =(D12-H12)/($S$4-$S$2) -> 13252.168 | O12: =(D12-I12)/($S$5-$S$2) -> 810.06075 | P12: =(D12-J12)/($S$5-$S$2) -> 1337.449
A13: =A12+1 -> 12 | B13: Dec '19 | C13: 206.43 | D13: =Methanol!E13 -> 229.81577 | E13: 1279.2951 | F13: 2097.3951 | G13: 1869.1881 | H13: 3512.8381 | I13: 1341.2351 | J13: 2058.4831 | K13: =(D13-E13)/($S$3-$S$2) -> 1202.1528 | L13: =(D13-F13)/($S$3-$S$2) -> 2139.2662 | M13: =(D13-G13)/($S$4-$S$2) -> 6637.135 | N13: =(D13-H13)/($S$4-$S$2) -> 13291.588 | O13: =(D13-I13)/($S$5-$S$2) -> 817.22011 | P13: =(D13-J13)/($S$5-$S$2) -> 1344.6083
A14: =A13+1 -> 13 | B14: Jan '20 | C14: 162.195 | D14: =Methanol!E14 -> 199.40429 | E14: 1241.093 | F14: 1752.394 | G14: 1805.621 | H14: 3299.222 | I14: 1113.242 | J14: 1938.043 | K14: =(D14-E14)/($S$3-$S$2) -> 1193.2287 | L14: =(D14-F14)/($S$3-$S$2) -> 1778.9115 | M14: =(D14-G14)/($S$4-$S$2) -> 6502.9016 | N14: =(D14-H14)/($S$4-$S$2) -> 12549.869 | O14: =(D14-I14)/($S$5-$S$2) -> 671.93948 | P14: =(D14-J14)/($S$5-$S$2) -> 1278.4108
A15: =A14+1 -> 14 | B15: Feb '20 | C15: 130.02409 | D15: =Methanol!E15 -> 177.4093 | E15: 1232.1438 | F15: 1743.4448 | G15: 1796.6718 | H15: 3290.2728 | I15: 1104.2928 | J15: 1929.0938 | K15: =(D15-E15)/($S$3-$S$2) -> 1208.1724 | L15: =(D15-F15)/($S$3-$S$2) -> 1793.8551 | M15: =(D15-G15)/($S$4-$S$2) -> 6555.7187 | N15: =(D15-H15)/($S$4-$S$2) -> 12602.686 | O15: =(D15-I15)/($S$5-$S$2) -> 681.532 | P15: =(D15-J15)/($S$5-$S$2) -> 1288.0033
A16: =A15+1 -> 15 | B16: Mar '20 | C16: 121.53455 | D16: =Methanol!E16 -> 171.90544 | E16: 1230.9999 | F16: 1742.3009 | G16: 1795.5279 | H16: 3289.1289 | I16: 1103.1489 | J16: 1927.9499 | K16: =(D16-E16)/($S$3-$S$2) -> 1213.1667 | L16: =(D16-F16)/($S$3-$S$2) -> 1798.8494 | M16: =(D16-G16)/($S$4-$S$2) -> 6573.3705 | N16: =(D16-H16)/($S$4-$S$2) -> 12620.338 | O16: =(D16-I16)/($S$5-$S$2) -> 684.73787 | P16: =(D16-J16)/($S$5-$S$2) -> 1291.2092
A17: =A16+1 -> 16 | B17: Apr '20 | C17: 94.725455 | D17: =Methanol!E17 -> 153.97749 | E17: 1225.1688 | F17: 1736.4698 | G17: 1789.6968 | H17: 3283.2978 | I17: 1097.3178 | J17: 1922.1188 | K17: =(D17-E17)/($S$3-$S$2) -> 1227.0233 | L17: =(D17-F17)/($S$3-$S$2) -> 1812.706 | M17: =(D17-G17)/($S$4-$S$2) -> 6622.3454 | N17: =(D17-H17)/($S$4-$S$2) -> 12669.313 | O17: =(D17-I17)/($S$5-$S$2) -> 693.63259 | P17: =(D17-J17)/($S$5-$S$2) -> 1300.1039
A18: =A17+1 -> 17 | B18: May '20 | C18: 70.597273 | D18: =Methanol!E18 -> 138.24733 | E18: 1221.5627 | F18: 1732.8637 | G18: 1786.0907 | H18: 3279.6917 | I18: 1093.7117 | J18: 1918.5127 | K18: =(D18-E18)/($S$3-$S$2) -> 1240.9111 | L18: =(D18-F18)/($S$3-$S$2) -> 1826.5938 | M18: =(D18-G18)/($S$4-$S$2) -> 6671.4306 | N18: =(D18-H18)/($S$4-$S$2) -> 12718.398 | O18: =(D18-I18)/($S$5-$S$2) -> 702.54732 | P18: =(D18-J18)/($S$5-$S$2) -> 1309.0186
... A48: =A47+1 -> 47 | B48: Nov '22 | C48: 1596.0345 | D48: =Methanol!E48 -> 1180.7005 | E48: 1616.5955 | F48: 2286.0019 | G48: 2201.982 | H48: 3571.2285 | I48: 1692.8539 | J48: 2823.8257 | K48: =(D48-E48)/($S$3-$S$2) -> 499.30692 | L48: =(D48-F48)/($S$3-$S$2) -> 1266.0955 | M48: =(D48-G48)/($S$4-$S$2) -> 4134.743 | N48: =(D48-H48)/($S$4-$S$2) -> 9678.2511 | O48: =(D48-I48)/($S$5-$S$2) -> 376.58336 | P48: =(D48-J48)/($S$5-$S$2) -> 1208.1803

Sheet Methanol avoidance
B1: Average | C1: Low | D1: High
A2: Avg 19 | B2: =AVERAGE(Methanol!K2:K13) -> 1673.4254 | C2: =B2-AVERAGE('Methanol high low'!K2:K13) -> 474.54181 | D2: =AVERAGE('Methanol high low'!L2:L13)-B2 -> 462.57159 | E2: Wind
A3: Avg 19 | B3: =AVERAGE(Methanol!L2:L13) -> 7710.4993 | C3: =B3-AVERAGE('Methanol high low'!M2:M13) -> 1084.919 | D3: =AVERAGE('Methanol high low'!N2:N13)-B3 -> 5569.5344 | E3: Solar
A4: Avg 19 | B4: =AVERAGE(Methanol!T2:T13) -> 2868.839 | C4: 0 | D4: 0 | E4: SMR CCS
A5: Avg 19 | B5: 0
A6: Avg 20 | B6: =AVERAGE(Methanol!K14:K25) -> 1434.9064 | C6: =B6-AVERAGE('Methanol high low'!K14:K25) -> 232.99027 | D6: =AVERAGE('Methanol high low'!L14:L25)-B6 -> 352.69244 | E6: Wind
A7: Avg 20 | B7: =AVERAGE(Methanol!L14:L25) -> 7695.5519 | C7: =B7-AVERAGE('Methanol high low'!M14:M25) -> 1161.9454 | D7: =AVERAGE('Methanol high low'!N14:N25)-B7 -> 4885.0223 | E7: Solar
A8: Avg 20 | B8: =AVERAGE(Methanol!T14:T25) -> 2712.8515 | C8: 0 | D8: 0 | E8: SMR CCS
A9: Avg 20 | B9: 0
A10: Jul '21 | B10: =Methanol!K32 -> 1209.201 | C10: =B10-'Methanol high low'!K32 -> 326.05546 | D10: =-(B10-'Methanol high low'!L32) -> 338.02568 | E10: Wind
A11: Jul '21 | B11: =Methanol!L32 -> 6453.2773 | C11: =B11-'Methanol high low'!M32 -> 1279.3377 | D11: =-B11+'Methanol high low'!N32 -> 3521.6454 | E11: Solar
A12: Jul '21 | B12: =Methanol!T32 -> 3832.5869 | C12: 0 | D12: 0 | E12: SMR CCS
A13: Jul '21 | B13: 0
A14: Oct '21 | B14: =Methanol!K35 -> 752.35535 | C14: =B14-'Methanol high low'!K35 -> 326.05546 | D14: =-(B14-'Methanol high low'!L35) -> 338.02568 | E14: Wind
A15: Oct '21 | B15: =Methanol!L35 -> 4838.596 | C15: =B15-'Methanol high low'!M35 -> 1279.3377 | D15: =-B15+'Methanol high low'!N35 -> 3521.6454 | E15: Solar
A16: Oct '21 | B16: =Methanol!T35 -> 5092.0198 | C16: 0 | D16: 0 | E16: SMR CCS
A17: Oct '21 | B17: 0
A18: Jan '22 | B18: =Methanol!K38 -> 1063.7183 | C18: =B18-'Methanol high low'!K38 -> 376.48353 | D18: =-(B18-'Methanol high low'!L38) -> 390.30508 | E18: Wind
A19: Jan '22 | B19: =Methanol!L38 -> 6276.1589 | C19: =B19-'Methanol high low'!M38 -> 1477.2014 | D19: =-B19+'Methanol high low'!N38 -> 4066.3067 | E19: Solar
A20: Jan '22 | B20: =Methanol!T38 -> 5402.6672 | C20: 0 | D20: 0 | E20: SMR CCS
A21: Jan '22 | B21: 0
A22: Apr '22 | B22: =Methanol!K41 -> 962.94368 | C22: =B22-'Methanol high low'!K41 -> 376.48353 | D22: =-(B22-'Methanol high low'!L41) -> 390.30508 | E22: Wind
