Workbook

Sheet CAPEX
A1: Cost factors
A2: Equipment erection | B2: fer | C2: 0.3
A3: Piping | B3: fp | C3: 0.8
A4: Instrumentation and control | B4: fi | C4: 0.3
A5: Electrical | B5: fel | C5: 0.2
A6: Civil | B6: fc | C6: 0.3
A7: Structures and buildings | B7: fs | C7: 0.2
A8: Lagging and paint | B8: fl | C8: 0.1
A9: Material factor for 304 SS | B9: fm | C9: 1.3
A12: Equipment | B12: Equipment approximated as | C12: Dimension needed | D12: Value | E12: a | F12: b | G12: n | H12: Purchased Cost (Ce,i,a) | J12: Equipment | K12: Internal diameter (m) | L12: h (m) | M12: External diameter (m) | N12: Area for shell (m2) | O12: Volume | P12: Density (kg/m3) | Q12: Shell mass (kg)
A13: Compressors | J13: V-100 | K13: 6.096 | L13: 21.336 | M13: =K13+0.0254 -> 6.1214 | N13: =PI()*(M13*M13-K13*K13)/4 -> 0.2437263 | O13: =N13*L13 -> 5.2001443 | P13: 8000 | Q13: =P13*O13 -> 41601.154
A14: K-100 | B14: Centrifugal compressor | C14: Power, kW | D14: 3968.315 | E14: 580000 | F14: 20000 | G14: 0.6 | H14: =(E14+(F14*(D14^G14)))/1000000 -> 3.465318 | J14: V-101 | K14: 5.334 | L14: 18.669 | M14: =K14+0.0254 -> 5.3594 | N14: =PI()*(M14*M14-K14*K14)/4 -> 0.21332385 | O14: =N14*L14 -> 3.9825429 | P14: 8000 | Q14: =P14*O14 -> 31860.343
A15: K-101 | B15: Centrifugal compressor | C15: Power, kW | D15: 3897.1179 | E15: 580000 | F15: 20000 | G15: 0.6 | H15: =(E15+(F15*(D15^G15)))/1000000 -> 3.4341456 | J15: V-102 | K15: 5.334 | L15: 18.669 | M15: =K15+0.0254 -> 5.3594 | N15: =PI()*(M15*M15-K15*K15)/4 -> 0.21332385 | O15: =N15*L15 -> 3.9825429 | P15: 8000 | Q15: =P15*O15 -> 31860.343
A16: K-102 | B16: Centrifugal compressor | C16: Power, kW | D16: 3874.3885 | E16: 580000 | F16: 20000 | G16: 0.6 | H16: =(E16+(F16*(D16^G16)))/1000000 -> 3.4241461 | J16: V-103 | K16: 6.5532 | L16: 22.9362 | M16: =K16+0.0254 -> 6.5786 | N16: =PI()*(M16*M16-K16*K16)/4 -> 0.26196777 | O16: =N16*L16 -> 6.0085451 | P16: 8000 | Q16: =P16*O16 -> 48068.361
A17: K-103 | B17: Centrifugal compressor | C17: Power, kW | D17: 2652.1762 | E17: 580000 | F17: 20000 | G17: 0.6 | H17: =(E17+(F17*(D17^G17)))/1000000 -> 2.8456427 | J17: V-104 | K17: 0.6096 | L17: 3.3528 | M17: =K17+0.0254 -> 0.635 | N17: =PI()*(M17*M17-K17*K17)/4 -> 0.024828666 | O17: =N17*L17 -> 0.083245553 | P17: 8000 | Q17: =P17*O17 -> 665.96442
A18: K-104 | B18: Centrifugal compressor | C18: Power, kW | D18: 1.8756644 | E18: 580000 | F18: 20000 | G18: 0.6 | H18: =(E18+(F18*(D18^G18)))/1000000 -> 0.6091691 | J18: V-105 | K18: 3.3528 | L18: 11.7348 | M18: =K18+0.0254 -> 3.3782 | N18: =PI()*(M18*M18-K18*K18)/4 -> 0.13427748 | O18: =N18*L18 -> 1.5757194 | P18: 8000 | Q18: =P18*O18 -> 12605.755
A19: K-105 | B19: Centrifugal compressor | C19: Power, kW | D19: 2.0314086 | E19: 580000 | F19: 20000 | G19: 0.6 | H19: =(E19+(F19*(D19^G19)))/1000000 -> 0.61059908 | J19: V-106 | K19: 1.0668 | L19: 5.8674 | M19: =K19+0.0254 -> 1.0922 | N19: =PI()*(M19*M19-K19*K19)/4 -> 0.043070136 | O19: =N19*L19 -> 0.25270971 | P19: 8000 | Q19: =P19*O19 -> 2021.6777
A20: K-106 | B20: Centrifugal compressor | C20: Power, kW | D20: 2.0942139 | E20: 580000 | F20: 20000 | G20: 0.6 | H20: =(E20+(F20*(D20^G20)))/1000000 -> 0.61116324 | J20: V-107 | K20: 0.3048 | L20: 1.6764 | M20: =K20+0.0254 -> 0.3302 | N20: =PI()*(M20*M20-K20*K20)/4 -> 0.012667687 | O20: =N20*L20 -> 0.02123611 | P20: 8000 | Q20: =P20*O20 -> 169.88888
A21: K-107 | B21: Centrifugal compressor | C21: Power, kW | D21: 1.4371651 | E21: 580000 | F21: 20000 | G21: 0.6 | H21: =(E21+(F21*(D21^G21)))/1000000 -> 0.60486188 | J21: V-108 | K21: 1.3716 | L21: 7.5438 | M21: =K21+0.0254 -> 1.397 | N21: =PI()*(M21*M21-K21*K21)/4 -> 0.055231115 | O21: =N21*L21 -> 0.41665249 | P21: 8001 | Q21: =P21*O21 -> 3333.6365
A22: K-108 | B22: Centrifugal compressor | C22: Power, kW | D22: 902.01095 | E22: 580000 | F22: 20000 | G22: 0.6 | H22: =(E22+(F22*(D22^G22)))/1000000 -> 1.7661977 | J22: V-109 | K22: 1.3716 | L22: 7.5438 | M22: =K22+0.0254 -> 1.397 | N22: =PI()*(M22*M22-K22*K22)/4 -> 0.055231115 | O22: =N22*L22 -> 0.41665249 | P22: 8002 | Q22: =P22*O22 -> 3334.0532
A23: K-109 | B23: Centrifugal compressor | C23: Power, kW | D23: 966.97096 | E23: 580000 | F23: 20000 | G23: 0.6 | H23: =(E23+(F23*(D23^G23)))/1000000 -> 1.816739 | J23: T-100 | K23: 1.5415 | L23: =0.6096*10 -> 6.096 | M23: =K23+0.0254 -> 1.5669 | N23: =PI()*(M23*M23-K23*K23)/4 -> 0.062009824 | O23: =N23*L23 -> 0.37801189 | P23: 8000 | Q23: =P23*O23 -> 3024.0951
A24: K-110 | B24: Centrifugal compressor | C24: Power, kW | D24: 945.80368 | E24: 580000 | F24: 20000 | G24: 0.6 | H24: =(E24+(F24*(D24^G24)))/1000000 -> 1.8004236 | J24: T-101 | K24: 2.1346667 | L24: =0.6096*3 -> 1.8288 | M24: =K24+0.0254 -> 2.1600667 | N24: =PI()*(M24*M24-K24*K24)/4 -> 0.085676122 | O24: =N24*L24 -> 0.15668449 | P24: 8000 | Q24: =P24*O24 -> 1253.4759
A25: K-111 | B25: Centrifugal compressor | C25: Power, kW | D25: 554.29395 | E25: 580000 | F25: 20000 | G25: 0.6 | H25: =(E25+(F25*(D25^G25)))/1000000 -> 1.4656744 | J25: T-102 | K25: 1.224 | L25: 0.6096 | M25: =K25+0.0254 -> 1.2494 | N25: =PI()*(M25*M25-K25*K25)/4 -> 0.049342137 | O25: =N25*L25 -> 0.030078967 | P25: 8000 | Q25: =P25*O25 -> 240.63173
A26: K-112 | B26: Centrifugal compressor | C26: Power, kW | D26: 567.5542 | E26: 580000 | F26: 20000 | G26: 0.6 | H26: =(E26+(F26*(D26^G26)))/1000000 -> 1.4783269 | J26: T-103 | K26: 1.6795 | L26: =0.6096*2 -> 1.2192 | M26: =K26+0.0254 -> 1.7049 | N26: =PI()*(M26*M26-K26*K26)/4 -> 0.067515779 | O26: =N26*L26 -> 0.082315238 | P26: 8000 | Q26: =P26*O26 -> 658.5219
A27: K-113 | B27: Centrifugal compressor | C27: Power, kW | D27: 930.9868 | E27: 580000 | F27: 20000 | G27: 0.6 | H27: =(E27+(F27*(D27^G27)))/1000000 -> 1.788916
A28: K-114 | B28: Centrifugal compressor | C28: Power, kW | D28: 2559.6749 | E28: 580000 | F28: 20000 | G28: 0.6 | H28: =(E28+(F28*(D28^G28)))/1000000 -> 2.7978945
A29: K-115 | B29: Centrifugal compressor | C29: Power, kW | D29: 2937.9039 | E29: 580000 | F29: 20000 | G29: 0.6 | H29: =(E29+(F29*(D29^G29)))/1000000 -> 2.9890874
A30: K-116 | B30: Centrifugal compressor | C30: Power, kW | D30: 3007.8458 | E30: 580000 | F30: 20000 | G30: 0.6 | H30: =(E30+(F30*(D30^G30)))/1000000 -> 3.0233368
B31: Total | H31: =SUM(H14:H30) -> 34.531642
A32: Pumps
A33: P-100 | B33: Centrifugal pump | C33: Flow, litres/s | D33: 1.5359808 | E33: 8000 | F33: 240 | G33: 0.9 | H33: =(E33+(F33*(D33^G33)))/1000000 -> 0.0083531494
A34: P-101 | B34: Centrifugal pump | C34: Flow, litres/s | D34: 10.61499 | E34: 8000 | F34: 240 | G34: 0.9 | H34: =(E34+(F34*(D34^G34)))/1000000 -> 0.010011587
A35: P-102 | B35: Centrifugal pump | C35: Flow, litres/s | D35: 11.086554 | E35: 8000 | F35: 240 | G35: 0.9 | H35: =(E35+(F35*(D35^G35)))/1000000 -> 0.010091839
B36: Total | H36: =SUM(H33:H35) -> 0.028456575
A37: Heat exchangers
A38: E-191 | B38: U tube HEX | C38: Area | D38: 876.29109 | E38: 28000 | F38: 54 | G38: 1.2 | H38: =(E38+(F38*(D38^G38)))/1000000 -> 0.21147286
A39: E-191 | B39: U tube HEX | C39: Area | D39: 876.29109 | E39: 28000 | F39: 54 | G39: 1.2 | H39: =(E39+(F39*(D39^G39)))/1000000 -> 0.21147286
A40: E-191 | B40: U tube HEX | C40: Area | D40: 876.29109 | E40: 28000 | F40: 54 | G40: 1.2 | H40: =(E40+(F40*(D40^G40)))/1000000 -> 0.21147286
A41: E-189 | B41: U tube HEX | C41: Area | D41: 63.273519 | E41: 28000 | F41: 54 | G41: 1.2 | H41: =(E41+(F41*(D41^G41)))/1000000 -> 0.035831774
A42: E-182 | B42: U tube HEX | C42: Area | D42: 224.38567 | E42: 28000 | F42: 54 | G42: 1.2 | H42: =(E42+(F42*(D42^G42)))/1000000 -> 0.06377568
...

Sheet Production costs
A4: Description | B4: Assumption | C4: M$/year
A5: Labor Costs
A6: Operating labor | B6: 9 shift positions, 9 operators/shift | C6: =50000*9*9/1000000 -> 4.05
A7: Supervision | B7: 25% of operating Labor | C7: =0.25*C6 -> 1.0125
A8: Direct overhead | B8: 45% of labor and supervision | C8: =0.45*(C6+C7) -> 2.278125
C9: =SUM(C6:C8) -> 7.340625
A10: Maintanance Costs
A11: Maintanance | B11: 3% of the installed capital cost | C11: =0.03*CAPEX!B199 -> 10.363573
C12: =C11 -> 10.363573
A13: Overhead Expenses
A14: Plant overhead | B14: 65% of labor and maintanace | C14: =0.65*(C6+C7+C8+C11) -> 11.507728
A15: Tax & Insurance | B15: 2% of installed cost and offsites | C15: =0.02*(CAPEX!B199+CAPEX!B200) -> 8.981763
C16: =SUM(C14:C15) -> 20.489491
A17: Interest
A18: Interest on debit | B18: 6% of working capital | C18: =0.06*CAPEX!B204 -> 5.6585107
C19: =C18 -> 5.6585107
A20: Total fixed production costs | C20: =C9+C12+C16+C19 -> 43.8522

Sheet Catalyst costs
A1: Propanol produced | D1: 58559.194 | E1: kg/hr
A4: Unit operation | B4: Catalyst used | C4: kg/hr | D4: $/kg | E4: $/hr | F4: M$/year
A5: Hydroformylation | B5: Rh/PPh3 | C5: 0.0081 | D5: 286000 | E5: =C5*D5 -> 2316.6 | F5: =E5/10^6*8000 -> 18.5328 | G5: Sigma Aldrich: https://www.sigmaaldrich.com/US/en/product/aldrich/225665

Sheet OPEX
B3: Material | C3: Unit | D3: Quantity | E3: Price ($/unit) | F3: Total cost | G3: 2022 costs | H3: Reference
B4: Raw material costs | K4: $/cu. ft | L4: $/MJ | M4: $/kg
B5: Carbon dioxide - DAC | C5: ton/hr | D5: =42148.0904323578/1000 -> 42.14809 | E5: 164.2 | F5: =E5*D5 -> 6920.7164 | G5: =F5*C29/C27 -> 9154.7123 | H5: Iasonas 2020 | J5: Natural gas | K5: =13.4/1000 -> 0.0134 | L5: =K5/1.06 -> 0.012641509 | M5: =L5*55 -> 0.69528302
B6: Hydrogen - Wind | C6: ton/hr | D6: =5829.71870176398/1000 -> 5.8297187 | E6: 3560 | F6: =E6*D6 -> 20753.799 | G6: =F6*C29/C27 -> 27453.091 | H6: Parkinson 2019
B7: gEthylene - DAC | C7: ton/hr | D7: =27826.8289304375/1000 -> 27.826829 | E7: 1293 | F7: =E7*D7 -> 35980.09 | G7: =F7*C29/C27 -> 47594.404 | H7: Iasonas 2020
B8: Total | G8: =SUM(G5:G7) -> 84202.206
B9: Utility costs
B10: Cooling water | C10: m3/hr | D10: =16421602.7279223/1000 -> 16421.603 | E10: =3.6/100 -> 0.036 | F10: =E10*D10 -> 591.1777 | G10: =F10*C29/C27 -> 782.00889 | H10: Iasonas 2020
B11: Electricity | C11: MWh | D11: =27835.0537109595/1000 -> 27.835054 | E11: 69.6 | F11: =E11*D11 -> 1937.3197 | G11: =F11*C29/C27 -> 2562.6834 | H11: Iasonas 2020
B12: Fired heat - natural gas | C12: ton/hr | D12: =2018.00390320268/1000 -> 2.0180039 | E12: 524 | F12: =E12*D12 -> 1057.434 | G12: =F12*C29/C28 -> 1094.6206 | H12: Europa 2021
B13: Total | G13: =SUM(G10:G12) -> 4439.3129
B14: Additional costs (purge,etc)
B15: Wastewater treatment | C15: m3/hr | D15: =17008.5900537084/1000 -> 17.00859 | E15: 1.6 | F15: =E15*D15 -> 27.213744 | G15: =F15*C29/C27 -> 35.998296 | H15: Iasonas 2020
B16: Flue gas emissions | C16: ton/hr | D16: =359.543844527518/1000 -> 0.35954384 | E16: 200 | F16: =E16*D16 -> 71.908769 | G16: =F16*C29/C26 -> 95.814768 | H16: Turton 2018
B17: Total | G17: =SUM(G15:G16) -> 131.81306
B18: Products sold
B19: Steam | C19: ton/hr | D19: =-22639.240068494/1000 -> -22.63924 | E19: 15.6 | F19: =E19*D19 -> -353.17215 | G19: =F19*C29/C27 -> -467.17553 | H19: Iasonas 2020
B20: Total | G20: =SUM(G19) -> -467.17553
B21: Catalyst costs | C21: M$/year | G21: =SUM('Catalyst costs'!F5) -> 18.5328 | H21: Refer catalyst costs sheet
B22: Total OPEX | C22: M$/year | G22: =(G8+G13+G17+G20)*8000/1000000+G$21 -> 724.98206
B24: Reference Data
B25: CEPCI 2008 | C25: 575.4
B26: CEPCI 2018 | C26: 603.1
B27: CEPCI 2019 | C27: 607.5
B28: CEPCI 2021 | C28: 776.3
B29: CEPCI 2022 | C29: 803.6

Sheet Summary
B3: Purchased equipment cost 2022 (M$/year) | C3: =SUM(CAPEX!B198) -> 92.366958 | E3: CAPEX summary | J3: CAPEX short summary
B4: Installed capital cost | C4: =SUM(CAPEX!B199) -> 345.45242 | E4: Unit operation | F4: Contribution 2010 | G4: Contribution 2022 | H4: CAPEX [M$/year] | J4: Unit operation | K4: CAPEX [M$/year]
B5: Offsites (OS) | C5: =SUM(CAPEX!B200) -> 103.63573 | E5: Compressors | F5: =CAPEX!H31 -> 34.531642 | G5: =F5*CAPEX!$B$197/CAPEX!$B$196 -> 52.072861 | H5: =(G5*CAPEX!$C$203+Summary!G5*CAPEX!$C$203*0.15)*CAPEX!$B$208 -> 51.971153 | J5: Compressors | K5: =H5 -> 51.971153
B6: Design and engineering (D&E) | C6: =SUM(CAPEX!B201) -> 134.72644 | E6: Pumps | F6: =CAPEX!H36 -> 0.028456575 | G6: =F6*CAPEX!$B$197/CAPEX!$B$196 -> 0.042911811 | H6: =(G6*CAPEX!$C$203+Summary!G6*CAPEX!$C$203*0.15)*CAPEX!$B$208 -> 0.042827996 | J6: Pumps | K6: =H6 -> 0.042827996
B7: Contingency (X) | C7: =SUM(CAPEX!B202) -> 44.908815 | E7: Heat exchangers | F7: =CAPEX!H160 -> 19.156225 | G7: =F7*CAPEX!$B$197/CAPEX!$B$196 -> 28.887112 | H7: =(G7*CAPEX!$C$203+Summary!G7*CAPEX!$C$203*0.15)*CAPEX!$B$208 -> 28.83069 | J7: Heat exchangers | K7: =H7 -> 28.83069
B8: Fixed capital investment | C8: =SUM(CAPEX!B203) -> 628.72341 | E8: Reactors | F8: =CAPEX!H165 -> 4.1811995 | G8: =F8*CAPEX!$B$197/CAPEX!$B$196 -> 6.3051452 | H8: =(G8*CAPEX!$C$203+Summary!G8*CAPEX!$C$203*0.15)*CAPEX!$B$208 -> 6.2928301 | J8: Reactors | K8: =H8 -> 6.2928301
B9: Working capital | C9: =SUM(CAPEX!B204) -> 94.308511 | E9: Flash separators | F9: =CAPEX!H177 -> 3.131704 | G9: =F9*CAPEX!$B$197/CAPEX!$B$196 -> 4.7225321 | H9: =(G9*CAPEX!$C$203+Summary!G9*CAPEX!$C$203*0.15)*CAPEX!$B$208 -> 4.7133081 | J9: Flash separators | K9: =H9 -> 4.7133081
B10: Total investment | C10: =SUM(CAPEX!B205) -> 723.03192 | E10: Columns | F10: =CAPEX!H181+CAPEX!H185+CAPEX!H189+CAPEX!H193 -> 0.22307781 | G10: =F10*CAPEX!$B$197/CAPEX!$B$196 -> 0.33639581 | H10: =(G10*CAPEX!$C$203+Summary!G10*CAPEX!$C$203*0.15)*CAPEX!$B$208 -> 0.33573877 | J10: Columns | K10: =H10 -> 0.33573877
B11: Labor costs | C11: =SUM('Production costs'!C9) -> 7.340625 | E11: Total | F11: =SUM(F5:F10) -> 61.252304 | G11: =SUM(G5:G10) -> 92.366958 | H11: =SUM(H5:H10) -> 92.186548 | J11: Total | K11: =SUM(K5:K10) -> 92.186548
B12: Maintanance costs | C12: =SUM('Production costs'!C12) -> 10.363573
B13: Overhead expenses | C13: =SUM('Production costs'!C16) -> 20.489491 | E13: Production costs summary | J13: Production costs short summary
B14: Interest | C14: =SUM('Production costs'!C19) -> 5.6585107 | E14: Category | F14: M$/year | J14: Category | K14: M$/year
B15: Project lifetime | C15: =SUM(CAPEX!B206) -> 25 | E15: Operating labor | F15: ='Production costs'!C6 -> 4.05 | J15: Labor | K15: =F15+F16+F17 -> 7.340625
B16: Interest rate | C16: =SUM(CAPEX!B207) -> 0.12 | E16: Supervision | F16: ='Production costs'!C7 -> 1.0125 | J16: Maintanance | K16: =F18 -> 10.363573
B17: ACCR | C17: =SUM(CAPEX!B208) -> 0.12749997 | E17: Direct overhead | F17: ='Production costs'!C8 -> 2.278125 | J17: Overhead | K17: =F19+F20 -> 20.489491
B18: CAPEX (M$/year) | C18: =SUM(CAPEX!B210) -> 92.186548 | E18: Maintanance | F18: ='Production costs'!C11 -> 10.363573 | J18: Interest | K18: =F21 -> 5.6585107
B19: Fixed production costs (M$/year) | C19: ='Production costs'!C20 -> 43.8522 | E19: Plant overhead | F19: ='Production costs'!C14 -> 11.507728 | J19: Total | K19: =SUM(K15:K18) -> 43.8522
B20: OPEX (M$/year) | C20: =OPEX!G22 -> 724.98206 | E20: Tax & Insurance | F20: ='Production costs'!C15 -> 8.981763
B21: Total expenses (M$/year) | C21: =($C$18+$C$19+C20) -> 861.0208 | E21: Interest on debit | F21: ='Production costs'!C18 -> 5.6585107
B22: Total expenses ($/hr) | C22: =(C21)*1000000/8000 -> 107627.6 | E22: Total | F22: =SUM(F15:F21) -> 43.8522
B23: Total propanol produced (kg/hr) | C23: 58559.194
B24: Cost of propanol per kg | C24: =C22/C23 -> 1.8379283 | E24: OPEX short summary
B25: Cost of propanol per ton | C25: =C24*1000 -> 1837.9283 | E25: Category | F25: M$/year
E26: Carbon dioxide | F26: =OPEX!G5*8000/10^6 -> 73.237699
E27: Hydrogen | F27: =OPEX!G6*8000/10^6 -> 219.62472
E28: Ethylene | F28: =OPEX!G7*8000/10^6 -> 380.75523
E29: Cooling water | F29: =OPEX!G10*8000/10^6 -> 6.2560711
E30: Electricity | F30: =OPEX!G11*8000/10^6 -> 20.501467
E31: Fired heat - natural gas | F31: =OPEX!G12*8000/10^6 -> 8.7569651
E32: Wastewater treatment | F32: =OPEX!G15*8000/10^6 -> 0.28798637
E33: Flue gas emissions | F33: =OPEX!G16*8000/10^6 -> 0.76651815
E34: Steam | F34: =OPEX!G19*8000/10^6 -> -3.7374043
E35: Catalyst | F35: =OPEX!G21 -> 18.5328
E36: Total | F36: =SUM(F26:F35) -> 724.98206
E38: Overall
E39: Category | F39: Value $/t | G39: Required (unit/hr) | H39: Unit
E40: Natural gas | F40: 0 | G40: 0 | H40: ton/hr
E41: Carbon dioxide | F41: =F26*10^9/8000/$C$23 -> 156.33262 | G41: =SUM(OPEX!D5) -> 42.14809 | H41: ton/hr
E42: Biogas | F42: 0 | G42: 0 | H42: ton/hr
E43: Oxygen | F43: 0 | G43: 0 | H43: ton/hr
...
